Workbook
Name AllJobIDs: _xlfn.ANCHORARRAY(Lookup!$A$2)
Name FilteredJobIDs: _xlfn.ANCHORARRAY(Lookup!$C$2)

Sheet Production Schedule
A1: Unique Tag | B1: ID | C1: Duplicate Entry | D1: Job Name | E1: Job Address | F1: PM | G1: PM Phone | H1: System | I1: Crating Plan | J1: Release Notes | K1: Description | L1: Included with this issue | M1: Misc Materials | N1: Production Folder | O1: Percent Panels Released | P1: Total Panels Released | Q1: Total Quoted Panels | R1: Panel Qty | S1: Part Qty | T1: Sketch Qty | U1: Extrusion Qty | V1: Reveal LF | W1: Program Material Qty | X1: Prog Run Time | Y1: Material | Z1: Material Type | AA1: Material Desc | AB1: Material Grain | AC1: Outsource Eng | AD1: Outsource Eng Group | AE1: Ranked Priority | AF1: Days to Release | AG1: Responsible | AH1: Eng Manager | AI1: Evaluation By | AJ1: LO By | AK1: LO Check By | AL1: Sketch By | AM1: Sketch Check By | AN1: Correction By | AO1: Eng Returned | AP1: AXYZ Prog By | AQ1: Laser Prog By | AR1: Punch Prog By | AS1: Prog Complete | AT1: Prog Returned | AU1: Release By | AV1: Date Submitted | AW1: Short Engineering Lead | AX1: Release To Shop Target | AY1: Released to Shop Actual | AZ1: Short Fab Lead | BA1: Shop Complete By Date | BB1: Ship To Coating Target | BC1: Ship Target | BD1: Adjusted Ship Date | BE1: Requested Ship Date | BF1: Ship Actual | BG1: Ship To Coating Actual | BH1: Material In Stock | BI1: Sheet Qty | BJ1: Material Date | BK1: Post Prod Coating | BL1: Coating Process | BM1: Vendor Coating Info | BN1: Post Coating Shipping Instructions | BO1: Screw Color | BP1: Screws Ordered | BQ1: Shop Drawings | BR1: Scan | BS1: Scan Location | BT1: FD | BU1: FD Location | BV1: Calcs | BW1: Calcs Location | BX1: Remake Piecemarks | BY1: Original Release | BZ1: RP Reason | CA1: RM Reason | CB1: Remake Request By | CC1: Station | CD1: LO | CE1: Sketch | CF1: CNC | CG1: Prog CNC | CH1: Vendor Cut | CI1: Flat Laser | CJ1: Tube Laser | CK1: Prog Laser | CL1: Punch | CM1: Prog Punch | CN1: Roll | CO1: Shear | CP1: Cidan | CQ1: Mill | CR1: Prog Mill | CS1: Extrusion Saw | CT1: 1st Manual | CU1: Brake | CV1: Prog Brake | CW1: 2nd Manual | CX1: Weld | CY1: Robot Weld | CZ1: Prog Robot Weld | DA1: Metal Finish | DB1: CNB | DC1: Fab | DD1: Assembly | DE1: Processing Customer No | DF1: Short Job No | DG1: Release Type | DH1: Rework Release Type | DI1: Release No | DJ1: Nonconformance # | DK1: Release No H1 | DL1: Highest Release | DM1: Process Required Start Date | DN1: Eng Hold | DO1: Eng Hold Start | DP1: Eng Hold End | DQ1: Eng Days On Hold | DR1: Prog Hold | DS1: Prog Hold Start | DT1: Prog Hold End | DU1: Prog Days On Hold | DV1: Process Hold | DW1: Process Hold Start | DX1: Process Hold End | DY1: Process Days On Hold | DZ1: QC Hold | EA1: QC Hold Start | EB1: QC Hold End | EC1: QC Days On Hold | ED1: Total Days On Hold | EE1: Drafting Hours | EF1: Shop Hours | EG1: Laser Hours | EH1: Punch Hours | EI1: Mill Hours | EJ1: Roll Hours | EK1: 1st Manual Hours | EL1: Brake Hours | EM1: 2nd Manual Hours | EN1: Weld Hours | EO1: Assembly Hours | EP1: Partial Shipment | EQ1: Shipping Method | ER1: Total # Crates | ES1: Total # Skids | ET1: Programs Required | EU1: Required Processes | EV1: Date Programming Received | EW1: Date Programming Complete | EX1: Days In Programming | EY1: Date QC Received | EZ1: Days In QC | FA1: Date Crating Received | FB1: Days In Crating | FC1: Program Lead | FD1: Shipping Department | FE1: Date Ready to Ship | FF1: Ship Late | FG1: Ship v Target | FH1: Latest Comment | FI1: Department | FJ1: Discard Issue | FK1: Inhouse PM | FL1: Inhouse Drafter | FM1: Inhouse Checker | FN1: Inhouse Name | FO1: Generate Inhouse (Manual) | FP1: Week to Ship | FQ1: Tube Bender | FR1: Band Saw | FS1: 5030 | FT1: Tube Bender Hours | FU1: Band Saw Hours
A2: 1 | B2: 24060-BM01 | D2: Loves Blacksburg | E2: 116 Preister Road Blacksburg, SC 29702 | F2: Cole Norona | G2: 931.591.9340 | K2: 102: 6 pieces at 10ft 103: 8 pieces at 10ft | M2: 102: 6 pieces at 10ft 103: 8 pieces at 10ft | N2: Q:\Jobs\24060 - Loves Blacksburg\04_Production\24060BM01 | O2: N/A | P2: N/A | Q2: N/A | S2: 14 | T2: 2 | U2: - | V2: - | W2: 3 | Y2: 18 Ga. X 48" X 120" Steel Sheet, No Grain | Z2: Steel Sheet | AA2: 18 Ga. X 48" X 120" | AB2: No | AE2: 1 | AF2: -302 | AG2: Ramon Estrada, Shane Watson | AH2: Denis Usatenko | AL2: Hennadii Stakhurskyi | AM2: Denis Usatenko | AN2: Hennadii Stakhurskyi | AU2: Hennadii Stakhurskyi | AV2: 45665.701 | AX2: 45700 | AY2: 45670 | BA2: 45707 | BC2: 45709 | BE2: 45709 | BH2: YES | BI2: 2 | CC2: Ready to Ship | CE2: TRUE | CO2: TRUE | CP2: TRUE | DF2: 24060 | DG2: BM | DI2: 01 | DK2: 1 | DL2: 24060-BM01 | DQ2: No Hold | DU2: No Hold | DY2: No Hold | EC2: No Hold | ED2: No Hold | EE2: 12 | EF2: 28 | EQ2: Hot Shot | EU2: Cidan Shear | EX2: No Program Requested | EZ2: QC Not Requested | FA2: 45694 | FB2: 3 | FC2: David Hasty | FD2: Ramon Estrada, Shane Watson | FE2: 45698 | FG2: Issue Still in Process | FI2: 1010 | FK2: Cole Norona | FL2: Hennadii Stakhurskyi | FM2: Denis Usatenko | FN2: 24060-BM01 In-House | FP2: 2025, Week 08
A3: 2 | B3: 24071-FS10.R | D3: RS Gass State Lab | E3: 975 RS Gass Blvd Nashville, TN 37216 | F3: Cole Norona | G3: 931.591.9340 | H3: 400 | K3: (25) of 1 5/8" reveals at 8' long | M3: (25) of 1 5/8" reveals at 8' long | N3: Q:\Jobs\24071 - RS Gass State Lab\04_Production\24071FS10R | O3: N/A | P3: N/A | Q3: N/A | R3: 0 | S3: 0 | T3: 0 | U3: 0 | V3: 200 | W3: Drop | X3: na | Y3: 4mm X 62" X 196", Bright Silver Metallic FR ACM, Grain | Z3: FR ACM | AA3: 4mm X 62" X 196", Bright Silver Metallic | AB3: Yes | AE3: 29 | AF3: -50 | AG3: Ramon Estrada, Shane Watson | AH3: Denis Usatenko | AU3: Denis Usatenko | AV3: 46043.353 | AW3: TRUE | AX3: 46064 | AY3: 46043 | AZ3: TRUE | BA3: 46059 | BC3: 46048 | BE3: 46048 | BH3: YES | BI3: 45 | BO3: N/A | BP3: N/A | BQ3: Approved | BR3: YES | BS3: Q:\Jobs\24071 - RS Gass State Lab\03_Engineering\02_FD Docs\24071_FS10 | BT3: YES | BU3: Q:\Jobs\24071 - RS Gass State Lab\03_Engineering\02_FD Docs\24071_FS10 | BV3: NO | CC3: Ready to Ship | CO3: TRUE | DF3: 24071 | DG3: FS | DI3: 10.R | DK3: 0 | DL3: 24071-FS11 | DQ3: No Hold | DU3: No Hold | DY3: No Hold | EC3: No Hold | ED3: No Hold | EE3: 1 | EF3: 1 | EQ3: Customer Pick Up | EU3: Shear | EX3: No Program Requested | EZ3: QC Not Requested | FA3: 46045 | FB3: 1 | FC3: David Hasty | FD3: Ramon Estrada, Shane Watson | FE3: 46045 | FG3: Issue Still in Process | FI3: 1010 | FK3: Cole Norona | FN3: 24071-FS10.R In-House | FP3: 2026, Week 05
A4: 3 | B4: 24051-FS200 | D4: TN Titans Stadium | E4: 1 Titans Way Nashville, TN 37213 | F4: Marc Ribar | G4: 360.798.3603 | H4: 400 | K4: MOONSTONE BAND ON LEVEL 7 | N4: Q:\Jobs\24051 - TN Titans Stadium\04_Production\24051FS200 | O4: 0.34476853 | P4: 6643 | Q4: 19268 | R4: 131 | S4: 131 | T4: 2 | U4: 917 | V4: 700 | W4: 196 X 62 - 44 | X4: 18:17:07 | Y4: 4MM FR CORE MOONSTONE METALLIC FR ACM, Grain | Z4: FR ACM | AA4: 4MM FR CORE MOONSTONE METALLIC | AB4: Yes | AE4: 19 | AF4: -218 | AG4: Unassigned | AH4: Denis Usatenko | AI4: Hennadii Stakhurskyi | AJ4: Hennadii Stakhurskyi | AL4: Hennadii Stakhurskyi | AM4: Denis Usatenko | AN4: Hennadii Stakhurskyi | AP4: Issiah Havens | AS4: TRUE | AU4: Hennadii Stakhurskyi | AV4: 45723.68 | AX4: 45806 | AY4: 45762 | BA4: 45825 | BC4: 45827 | BE4: 45827 | BH4: YES | BI4: 250 | BJ4: 45757 | BO4: MATCH COLOR | BP4: YES | BQ4: Approved | BR4: NO | BT4: NO | BV4: NO | CC4: RTS Titans | CD4: TRUE | CE4: TRUE | CF4: TRUE | CG4: AXYZ Titans Line | DB4: TRUE | DC4: TRUE | DF4: 24051 | DG4: FS | DI4: 200 | DK4: 200 | DL4: 24051-FS231 | DO4: 45737 | DP4: 45741 | DQ4: 3 | DU4: No Hold | DY4: No Hold | EC4: No Hold | ED4: 3 | EE4: 4 | EF4: 300 | EQ4: In House | ET4: AXYZ | EU4: AXYZ Titans Line Clean and Brake Fab | EV4: 45761 | EW4: 45761 | EX4: 1 | EZ4: Issue Still In Process | FB4: Crating Start Date Not Recorded | FC4: David Hasty | FD4: Ramon Estrada, Shane Watson | FE4: 45827 | FG4: Issue Still in Process | FH4: Issiah Havens - @hstakhurskyi@jwmcd.com @jdavis@jwmcd.com @tgraves@jwmcd.com Programmed | FI4: 1010 | FK4: Marc Ribar | FL4: Hennadii Stakhurskyi | FM4: Denis Usatenko | FN4: 24051-FS200 In-House | FP4: 2025, Week 25
A5: 4 | B5: 24051-FS201 | D5: TN Titans Stadium | E5: 1 Titans Way Nashville, TN 37213 | F5: Marc Ribar | G5: 360.798.3603 | H5: 400 | K5: level 400 moonstone | N5: Q:\Jobs\24051 - TN Titans Stadium\04_Production\24051FS201 | O5: 0.50088229 | P5: 9651 | Q5: 19268 | R5: 109 | S5: 109 | T5: 2 | U5: 1090 | V5: 700 | W5: Sheet Size Quantity 196 x 62 in 55 | X5: 00d20h30m49s | Y5: 4MM MOONSTONE METALLIC 62 X 196 FR ACM, Grain | Z5: FR ACM | AA5: 4MM MOONSTONE METALLIC 62 X 196 | AB5: Yes | AE5: 43 | AF5: -107 | AG5: Unassigned | AH5: Denis Usatenko | AI5: Hennadii Stakhurskyi | AJ5: Hennadii Stakhurskyi | AL5: Hennadii Stakhurskyi | AM5: Denis Usatenko | AN5: Hennadii Stakhurskyi | AP5: Arnold Jurado, Issiah Havens | AS5: TRUE | AU5: Hennadii Stakhurskyi | AV5: 45726.378 | AX5: 45961 | AY5: 45951 | BA5: 45980 | BC5: 45982 | BE5: 45982 | BH5: YES | BI5: 1000 | BO5: MATCH COLOR | BP5: YES | BQ5: Approved | BR5: NO | BT5: NO | BV5: NO | CC5: RTS Titans | CD5: TRUE | CE5: TRUE | CF5: TRUE | CG5: AXYZ Titans Line | DB5: TRUE | DC5: TRUE | DF5: 24051 | DG5: FS | DI5: 201 | DK5: 201 | DL5: 24051-FS231 | DO5: 45737 | DP5: 45944 | DQ5: 148 | DU5: No Hold | DY5: No Hold | EC5: No Hold | ED5: 148 | EE5: 4 | EF5: 200 | EQ5: In House | ET5: AXYZ | EU5: AXYZ Titans Line Clean and Brake Fab | EV5: 45951 | EW5: 45951 | EX5: 1 | EZ5: QC Not Requested | FA5: 45960 | FB5: 2 | FC5: David Hasty | FD5: Ramon Estrada, Shane Watson | FE5: 45961 | FG5: Issue Still in Process | FH5: Arnold Jurado - @hstakhurskyi@jwmcd.com @jdavis@jwmcd.com PROGRAMMED | FI5: 1010 | FK5: Marc Ribar | FL5: Hennadii Stakhurskyi | FM5: Denis Usatenko | FN5: 24051-FS201 In-House | FP5: 2025, Week 47
A6: 5 | B6: 24051-FS205 | D6: TN Titans Stadium | E6: 1 Titans Way Nashville, TN 37213 | F6: Marc Ribar | G6: 360.798.3603 | H6: 400 | K6: South Elevation 700 level. Install Direction Left to Right | L6: * SKETCHES * CUT LIST * EXTRUSION TIGER SAW LIST * COLOR LABELS | M6: 2 SETS - INSTALL DRAWINGS 750 LF - 1 5/8" REVEALS TO MATCH 725 pcs - Corner Clips 1450 pcs﻿ - Color Matched Screws | N6: Q:\Jobs\24051 - TN Titans Stadium\04_Production\24051FS205 | O6: 0.50700644 | P6: 9769 | Q6: 19268 | R6: 118 | S6: 118 | T6: 2 | U6: 1180 | V6: 750 | W6: 59 sheets | X6: 00d22h08m40s | Y6: Alpolic - 4mm - 880 pcs - [62 X 196] - MOONSTONE METALLIC FR ACM, Grain | Z6: FR ACM | AA6: Alpolic - 4mm - 880 pcs - [62 X 196] - MOONSTONE METALLIC | AB6: Yes | AE6: 43 | AF6: -107 | AG6: Unassigned | AH6: Denis Usatenko | AI6: Hennadii Stakhurskyi | AJ6: Hennadii Stakhurskyi | AL6: Hennadii Stakhurskyi | AM6: Denis Usatenko | AN6: Hennadii Stakhurskyi | AP6: Arnold Jurado, Issiah Havens | AS6: TRUE | AU6: Hennadii Stakhurskyi | AV6: 45737.236 | AX6: 45961 | AY6: 45953 | BA6: 45980 | BC6: 45982 | BE6: 45982 | BH6: YES | BI6: 500 | BJ6: 45757 | BO6: MATCH COLOR | BP6: YES | BQ6: Approved | BR6: NO | BT6: NO | BV6: NO | CC6: RTS Titans | CD6: TRUE | CE6: TRUE | CF6: TRUE | CG6: AXYZ Titans Line | DB6: TRUE | DC6: TRUE | DF6: 24051 | DG6: FS | DI6: 205 | DK6: 205 | DL6: 24051-FS231 | DO6: 45737 | DP6: 45946 | DQ6: 150 | DU6: No Hold | DY6: No Hold | EC6: No Hold | ED6: 150 | EE6: 8 | EF6: 300 | EQ6: In House | ET6: AXYZ | EU6: AXYZ Titans Line Clean and Brake Fab | EV6: 45952 | EW6: 45953 | EX6: 2 | EZ6: QC Not Requested | FA6: 45968 | FB6: 1 | FC6: David Hasty | FD6: Ramon Estrada, Shane Watson | FE6: 45968 | FG6: Issue Still in Process | FH6: Arnold Jurado - @hstakhurskyi@jwmcd.com @jdavis@jwmcd.com PROGRAMMED | FI6: 1010 | FK6: Marc Ribar | FL6: Hennadii Stakhurskyi | FM6: Denis Usatenko | FN6: 24051-FS205 In-House | FP6: 2025, Week 47
A7: 6 | B7: 24051-FS206 | D7: TN Titans Stadium | E7: 1 Titans Way Nashville, TN 37213 | F7: Marc Ribar | G7: 360.798.3603 | H7: 400 | K7: LEVEL 400 INSTALL LEFT TO RIGHT | N7: Q:\Jobs\24051 - TN Titans Stadium\04_Production\24051FS206 | O7: 0.34850529 | P7: 6715 | Q7: 19268 | R7: 72 | S7: 72 | T7: 2 | U7: 504 | V7: 600 | W7: 196 X 62 - 24 | X7: 10:02:09 | Y7: 4MM FR CORE MOONSTONE METALLIC 62 X 196 FR ACM, Grain | Z7: FR ACM | AA7: 4MM FR CORE MOONSTONE METALLIC 62 X 196 | AB7: Yes | AE7: 22 | AF7: -214 | AG7: Unassigned | AH7: Denis Usatenko | AI7: Hennadii Stakhurskyi | AJ7: Hennadii Stakhurskyi | AL7: Hennadii Stakhurskyi | AM7: Denis Usatenko | AN7: Hennadii Stakhurskyi | AP7: Issiah Havens | AS7: TRUE | AU7: Hennadii Stakhurskyi | AV7: 45737.619 | AX7: 45812 | AY7: 45762 | BA7: 45831 | BC7: 45833 | BE7: 45833 | BH7: NO | BI7: 500 | BJ7: 45757 | BO7: MATCH COLOR | BP7: YES | BQ7: Approved | BR7: NO | BT7: NO | BV7: NO | CC7: RTS Titans | CE7: TRUE | CF7: TRUE | CG7: AXYZ Titans Line | DB7: TRUE | DC7: TRUE | DF7: 24051 | DG7: FS | DI7: 206 | DK7: 206 | DL7: 24051-FS231 | DQ7: No Hold | DU7: No Hold | DY7: No Hold | EC7: No Hold | ED7: No Hold | EE7: 4 | EF7: 200 | EQ7: In House | ET7: AXYZ | EU7: AXYZ Titans Line Clean and Brake Fab | EV7: 45762 | EW7: 45762 | EX7: 1 | EZ7: QC Not Requested | FA7: 45826 | FB7: 6 | FC7: David Hasty | FD7: Ramon Estrada, Shane Watson | FE7: 45833 | FG7: Issue Still in Process | FH7: Issiah Havens - @hstakhurskyi@jwmcd.com @jdavis@jwmcd.com @tgraves@jwmcd.com Programmed | FI7: 1010 | FK7: Marc Ribar | FL7: Hennadii Stakhurskyi | FM7: Denis Usatenko | FN7: 24051-FS206 In-House | FP7: 2025, Week 26
A8: 7 | B8: 24051-FS209.1 | D8: TN Titans Stadium | E8: 1 Titans Way Nashville, TN 37213 | F8: Marc Ribar | G8: 360.798.3603 | H8: 400 | K8: SOUTH LEVEL 50 WING WALL | L8: * SKETCHES * CUT LIST * EXTRUSION TIGER SAW LIST * COLOR LABELS | M8: * 2 SETS - INSTALL DRAWINGS * ( 350 LF) 1-5/8" Reveals * ( 16 LF) JR2 | N8: Q:\Jobs\24051 - TN Titans Stadium\04_Production\24051FS209.1 | O8: 0.70038406 | P8: 13495 | Q8: 19268 | R8: 36 | S8: 76 | T8: 50 | U8: 292 | V8: 350 | W8: 13 SHEETS | X8: 00d05h30m19s | Y8: 4mm X 62" X 196", MOONSTONE METALLIC FR ACM, Grain | Z8: FR ACM | AA8: 4mm X 62" X 196", MOONSTONE METALLIC | AB8: Yes | AE8: 87 | AF8: -25 | AG8: Unassigned | AH8: Denis Usatenko | AI8: Hennadii Stakhurskyi | AJ8: Hennadii Stakhurskyi | AL8: Hennadii Stakhurskyi | AM8: Denis Usatenko | AN8: Hennadii Stakhurskyi | AP8: Arnold Jurado, Issiah Havens | AS8: TRUE | AU8: Denis Usatenko | AV8: 46031.657 | AX8: 46062 | AY8: 46078 | AZ8: TRUE | BA8: 46094 | BC8: 46083 | BE8: 46083 | BH8: YES | BI8: 500 | BO8: MATCH COLOR | BP8: YES | BQ8: Approved | BR8: NO | BT8: NO | BV8: NO | CC8: RTS Titans | CD8: TRUE | CE8: TRUE | CF8: TRUE | CG8: AXYZ Titans Line | DB8: TRUE | DC8: TRUE | DF8: 24051 | DG8: FS | DI8: 209.1 | DK8: 209.1 | DL8: 24051-FS231 | DQ8: No Hold | DU8: No Hold | DY8: No Hold | EC8: No Hold | ED8: No Hold | EE8: 8 | EF8: 40 | EQ8: In House | ET8: AXYZ | EU8: AXYZ Titans Line Clean and Brake Fab | EV8: 46077 | EW8: 46078 | EX8: 2 | EZ8: QC Not Requested | FA8: 46105 | FB8: 1 | FC8: David Hasty | FD8: Ramon Estrada, Shane Watson | FE8: 46105 | FG8: Issue Still in Process | FH8: Arnold Jurado - @dusatenko@jwmcd.com @jdavis@jwmcd.com PROGRAMMED | FI8: 1010 | FK8: Marc Ribar | FL8: Hennadii Stakhurskyi | FM8: Denis Usatenko | FN8: 24051-FS209.1 In-House | FP8: 2026, Week 010
A9: 8 | B9: 24051-FS212 | D9: TN Titans Stadium | E9: 1 Titans Way Nashville, TN 37213 | F9: Marc Ribar | G9: 360.798.3603 | H9: 400 | K9: NORTH LEVEL 400 INSTALL RIGHT TO LEFT | N9: Q:\Jobs\24051 - TN Titans Stadium\04_Production\24051FS212 | O9: 0.34985468 | P9: 6741 | Q9: 19268 | R9: 26 | S9: 26 | T9: 2 | U9: 182 | V9: 300 | W9: 196 X 62 - 9 | X9: 03:38:58 | Y9: 4MM FR CORE MOONSTONE METALLIC 62X196 FR ACM, Grain | Z9: FR ACM | AA9: 4MM FR CORE MOONSTONE METALLIC 62X196 | AB9: Yes | AE9: 12 | AF9: -224 | AG9: Unassigned | AH9: Denis Usatenko | AI9: Hennadii Stakhurskyi | AJ9: Hennadii Stakhurskyi | AL9: Hennadii Stakhurskyi | AM9: Denis Usatenko | AN9: Hennadii Stakhurskyi | AP9: Issiah Havens | AS9: TRUE | AU9: Hennadii Stakhurskyi | AV9: 45751.661 | AX9: 45798 | AY9: 45762 | BA9: 45817 | BC9: 45819 | BE9: 45819 | BH9: NO | BI9: 500 | BJ9: 45757 | BO9: MATCH COLOR | BP9: YES | BQ9: Approved | BR9: NO | BT9: NO | BV9: NO | CC9: RTS Titans | CD9: TRUE | CE9: TRUE | CF9: TRUE | CG9: AXYZ Titans Line | DB9: TRUE | DC9: TRUE | DF9: 24051 | DG9: FS | DI9: 212 | DK9: 212 | DL9: 24051-FS231 | DQ9: No Hold | DU9: No Hold | DY9: No Hold | EC9: No Hold | ED9: No Hold | EE9: 4 | EF9: 50 | EQ9: In House | ET9: AXYZ | EU9: AXYZ Titans Line Clean and Brake Fab | EV9: 45762 | EW9: 45762 | EX9: 1 | EZ9: QC Not Requested | FA9: 45826 | FB9: 2 | FC9: David Hasty | FD9: Ramon Estrada, Shane Watson | FE9: 45827 | FG9: Issue Still in Process | FH9: Issiah Havens - @hstakhurskyi@jwmcd.com @jdavis@jwmcd.com @tgraves@jwmcd.com Programmed | FI9: 1010 | FK9: Marc Ribar | FL9: Hennadii Stakhurskyi | FM9: Denis Usatenko | FN9: 24051-FS212 In-House | FP9: 2025, Week 24
A10: 9 | B10: 25002-FS11.1 | D10: Med Center Health | E10: 250 Park Street Bowling Green, KY 42101 | F10: Carlos Silva | G10: 980.246.6545 | H10: 600 | K10: PLEASE SEE ATTACHED IMAGE COLUMNS NORTH - WEST ELEVATION 238, 239, 240, 241, 129/242 130/242 131/242 132/242 | L10: * SKETCHES * CUT LIST * EXTRUSION TIGER SAW LIST * COLOR LABELS | M10: * 2 SETS - INSTALL DRAWINGS * (215 LF) 1-3/4" Reveals * (14 LF) PE1N * (10 PCS) PET * (180 PCS) PE2N | N10: "Q:\Jobs\25002 - Med Center Health\04_Production\25002FS11.1" | O10: 0.80585899 | P10: 1623 | Q10: 2014 | R10: 18 | S10: 18 | T10: 2 | U10: 50 | V10: 215 | W10: 18 SHEETS | X10: 00d04h02m33s | Y10: ACM: 4mm X 62" X 196", MICA GRAY FR ACM, Grain | Z10: FR ACM | AA10: ACM: 4mm X 62" X 196", MICA GRAY | AB10: Yes | AE10: 1 | AF10: -10 | AG10: Corey Howse | AH10: Denis Usatenko | AI10: Gabriela Hoyle | AJ10: Gabriela Hoyle | AL10: Gabriela Hoyle | AM10: Denis Usatenko | AN10: Gabriela Hoyle | AP10: Arnold Jurado, Issiah Havens | AS10: TRUE | AU10: Gabriela Herrera, Gabriela Hoyle | AV10: 46058.42 | AW10: TRUE | AX10: 46079 | AY10: 46099 | AZ10: TRUE | BA10: 46115 | BC10: 46083 | BE10: 46083 | BH10: YES | BI10: 00 | BO10: MATCH COLOR | BP10: YES | BQ10: Approved | BR10: NO | BT10: NO | BV10: NO | CC10: Clean and Brake | CD10: TRUE | CE10: TRUE | CF10: TRUE | CG10: AXYZ Titans Line | DB10: TRUE | DC10: TRUE | DF10: 25002 | DG10: FS | DI10: 11.1 | DK10: 11.1 | DL10: 25002-FS16 | DQ10: No Hold | DU10: No Hold | DY10: No Hold | EC10: No Hold | ED10: No Hold | EE10: 5 | EF10: 20 | EQ10: Semi | ET10: AXYZ | EU10: AXYZ Titans Line Clean and Brake Fab | EV10: 46097 | EW10: 46098 | EX10: 2 | EZ10: Issue Still In Process | FB10: Issue Still In Process | FC10: David Hasty | FD10: Ramon Estrada, Shane Watson | FG10: Issue Still in Process | FH10: Tony Graves - still waiting on the roller to be fixed. | FI10: 1010 | FK10: Carlos Silva | FL10: Gabriela Hoyle | FM10: Denis Usatenko | FN10: 25002-FS11.1 In-House | FP10: 2026, Week 010
A11: 10 | B11: 26014-02-ST01 | D11: 2026 R & D | E11: 3731 Amy Lynn Drive Nashville, TN 37218-3813 | F11: TBC | H11: --- | J11: Deliver part 260112ST-1001 to Paul Roberts after deburr. Neither DA, timesaver, nor paint/powder are required for 260112ST. Parts are needed as soon as possible. Parts 26014-01-1001 and 26014-01-1002 go to PWX and return to JWM. Provide drawings to PWX for powder instruction. Ship to paint and ship target are for the sign parts. | O11: N/A | P11: N/A | Q11: N/A | S11: 10 | T11: 3 | Y11: Min. drop 11 Ga. SS Sheet, No Grain | Z11: SS Sheet | AA11: Min. drop 11 Ga. | AB11: No | AE11: 1 | AF11: -54 | AG11: Rogerson Jean-Charles, Sean Doss | AH11: David Hasty | AQ11: Chris Gambrel | AV11: 46035.641 | AW11: TRUE | AX11: 46056 | AY11: 46037 | AZ11: TRUE | BA11: 46055 | BB11: 46037 | BC11: 46044 | BE11: 46044 | BH11: YES | BK11: TRUE | BL11: Powder Coat | BM11: PWX. Sign is black, backer plate is white. Provide drawings to PWX for specific instructions. | BN11: Coating Ship Back To JWM | BQ11: None Available | BR11: NO | BT11: NO | BV11: NO | CC11: QC | CI11: TRUE | DF11: 26014-02 | DG11: ST | DI11: 01 | DK11: 1 | DL11: 26014-02-ST01 | DQ11: No Hold | DU11: No Hold | DY11: No Hold | EC11: No Hold | ED11: No Hold | EE11: 2 | EF11: 2 | ET11: Flat Laser | EU11: Flat Laser Powder Coat | EX11: No Program Requested | EY11: 46050 | EZ11: 57 (In Progress) | FB11: Issue Still In Process | FC11: David Hasty | FD11: Ramon Estrada, Shane Watson | FG11: Issue Still in Process | FI11: 1010 | FK11: TBC | FN11: 26014-02-ST01 In-House | FO11: TRUE | FP11: 2026, Week 04
A12: 11 | B12: 24051-FS46.1 | D12: TN Titans Stadium | E12: 1 Titans Way Nashville, TN 37213 | F12: Marc Ribar | G12: 360.798.3603 | H12: 400 | K12: SOUTH LEVEL 200 | L12: * SKETCHES * CUT LIST * EXTRUSION TIGER SAW LIST * COLOR LABELS | M12: * 2 SETS - INSTALL DRAWINGS * ( 504LF) 1-5/8" Reveals * ( 107 pcs) Corner Clips * ( 214 pcs ) Color Matching Screws﻿ * ( 140 LF) JR2 (EXTENDED?) | N12: Q:\Jobs\24051 - TN Titans Stadium\04_Production\24051FS46.1 | O12: 0.65813785 | P12: 12681 | Q12: 19268 | R12: 56 | S12: 56 | T12: 8 | U12: 362 | V12: 140 | W12: 13 sheets | X12: 00d06h31m30s | Y12: 4mm X 62" X 196", TOB BLACK FR ACM, No Grain | Z12: FR ACM | AA12: 4mm X 62" X 196", TOB BLACK | AB12: No | AE12: 75 | AF12: -46 | AG12: Unassigned | AH12: Denis Usatenko | AI12: Hennadii Stakhurskyi | AJ12: Hennadii Stakhurskyi | AL12: Hennadii Stakhurskyi | AM12: Denis Usatenko | AN12: Ailen Niedfeld | AP12: Arnold Jurado, Issiah Havens | AS12: TRUE | AU12: Ailen Niedfeld | AV12: 46009.683 | AX12: 46034 | AY12: 46049 | AZ12: TRUE | BA12: 46065 | BC12: 46055 | BE12: 46055 | BH12: YES | BI12: 1000 | BO12: MATCH COLOR | BP12: YES | BQ12: Approved | BR12: NO | BT12: NO | BV12: NO | CC12: RTS Titans | CE12: TRUE | CF12: TRUE | DB12: TRUE | DC12: TRUE | DF12: 24051 | DG12: FS | DI12: 46.1 | DK12: 46.1 | DL12: 24051-FS231 | DQ12: No Hold | DU12: No Hold | DY12: No Hold | EC12: No Hold | ED12: No Hold | EE12: 16 | EF12: 200 | EQ12: In House | ET12: AXYZ | EU12: AXYZ Clean and Brake Fab | EV12: 46046 | EW12: 46048 | EX12: 1 | EZ12: QC Not Requested | FA12: 46083 | FB12: 2 | FC12: David Hasty | FD12: Ramon Estrada, Shane Watson | FE12: 46084 | FG12: Issue Still in Process | FH12: Arnold Jurado - @aniedfeld@jwmcd.com | FI12: 1010 | FK12: Marc Ribar | FL12: Hennadii Stakhurskyi | FM12: Denis Usatenko | FN12: 24051-FS46.1 In-House | FP12: 2026, Week 06
A13: 12 | B13: 24051-FS46C | D13: TN Titans Stadium | E13: 1 Titans Way Nashville, TN 37213 | F13: Marc Ribar | G13: 360.798.3603 | H13: 400 | J13: EVERY CRATE REQUIRES REVEALS | K13: COPING FOR SOUTH LEVEL 200 | L13: * SKETCHES * CUT LIST * EXTRUSION TIGER SAW LIST * COLOR LABELS | M13: 2 SETS - INSTALL DRAWINGS 150 LF - 1 5/8" REVEALS TO MATCH 200 pcs - Corner Clips 400 pcs - Color Matched Screws | N13: Q:\Jobs\24051 - TN Titans Stadium\04_Production\24051FS46C | O13: 0.53352709 | P13: 10280 | Q13: 19268 | R13: 25 | S13: 25 | T13: 2 | U13: 175 | V13: 150 | W13: 3 SHEETS | X13: 00d02h35m22s | Y13: Alpolic - 4mm - 3600 pcs - [62 X 196] - TOB BLACK FR ACM, No Grain | Z13: FR ACM | AA13: Alpolic - 4mm - 3600 pcs - [62 X 196] - TOB BLACK | AB13: No | AE13: 52 | AF13: -96 | AG13: Unassigned | AH13: Denis Usatenko | AI13: Hennadii Stakhurskyi | AJ13: Hennadii Stakhurskyi | AL13: Hennadii Stakhurskyi | AM13: Denis Usatenko | AN13: Hennadii Stakhurskyi | AP13: Arnold Jurado, Issiah Havens | AS13: TRUE | AU13: Hennadii Stakhurskyi | AV13: 45946.439 | AX13: 45978 | AY13: 45971 | BA13: 45995 | BC13: 45999 | BE13: 45999 | BH13: YES | BI13: 1000 | BO13: MATCH COLOR | BP13: YES | BQ13: Approved | BR13: NO | BT13: NO | BV13: NO | CC13: RTS Titans | CD13: TRUE | CE13: TRUE | CF13: TRUE | CG13: AXYZ Titans Line | DB13: TRUE | DC13: TRUE | DF13: 24051 | DG13: FS | DI13: 46C | DK13: 0 | DL13: 24051-FS231 | DQ13: No Hold | DU13: No Hold | DY13: No Hold | EC13: No Hold | ED13: No Hold | EE13: 8 | EF13: 8 | EQ13: In House | ET13: AXYZ | EU13: AXYZ Titans Line Clean and Brake Fab | EV13: 45967 | EW13: 45968 | EX13: 2 | EZ13: QC Not Requested | FA13: 45996 | FB13: 2 | FC13: David Hasty | FD13: Ramon Estrada, Shane Watson | FE13: 45999 | FG13: Issue Still in Process | FH13: Arnold Jurado - @hstakhurskyi@jwmcd.com @jdavis@jwmcd.com PROGRAMMED | FI13: 1010 | FK13: Marc Ribar | FL13: Hennadii Stakhurskyi | FM13: Denis Usatenko | FN13: 24051-FS46C In-House | FO13: TRUE | FP13: 2025, Week 50
A14: 13 | B14: 24051-FS47C | D14: TN Titans Stadium | E14: 1 Titans Way Nashville, TN 37213 | F14: Marc Ribar | G14: 360.798.3603 | H14: 400 | J14: EVERY CRATE REQUIRES REVEALS | K14: COPING FOR FS 47. | L14: * SKETCHES * CUT LIST * EXTRUSION TIGER SAW LIST * COLOR LABELS | M14: 2 SETS - INSTALL DRAWINGS 700 LF - 1 5/8" REVEALS TO MATCH 400 pcs - Corner Clips 800 pcs - Color Matched Screws | N14: Q:\Jobs\24051 - TN Titans Stadium\04_Production\24051FS47C | O14: 0.53866514 | P14: 10379 | Q14: 19268 | R14: 99 | S14: 99 | T14: 2 | U14: 693 | V14: 700 | W14: 20 SHEETS | X14: 00d11h55m27s | Y14: Alpolic - 4mm - 3600 pcs - [62 X 196] - TOB BLACK FR ACM, No Grain | Z14: FR ACM | AA14: Alpolic - 4mm - 3600 pcs - [62 X 196] - TOB BLACK | AB14: No | AE14: 54 | AF14: -92 | AG14: Unassigned | AH14: Denis Usatenko | AI14: Hennadii Stakhurskyi | AJ14: Hennadii Stakhurskyi | AL14: Hennadii Stakhurskyi | AM14: Denis Usatenko | AN14: Hennadii Stakhurskyi | AP14: Arnold Jurado, Issiah Havens | AS14: TRUE | AU14: Hennadii Stakhurskyi | AV14: 45946.614 | AX14: 45982 | AY14: 45971 | BA14: 46001 | BC14: 46003 | BE14: 46003 | BH14: YES | BI14: 1000 | BO14: MATCH COLOR | BP14: YES | BQ14: Approved | BR14: NO | BT14: NO | BV14: NO | CC14: RTS Titans | CD14: TRUE | CE14: TRUE | CF14: TRUE | CG14: AXYZ Titans Line | DB14: TRUE | DC14: TRUE | DF14: 24051 | DG14: FS | DI14: 47C | DK14: 0 | DL14: 24051-FS231 | DQ14: No Hold | DU14: No Hold | DY14: No Hold | EC14: No Hold | ED14: No Hold | EE14: 4 | EF14: 16 | EQ14: In House | ET14: AXYZ | EU14: AXYZ Titans Line Clean and Brake Fab | EV14: 45967 | EW14: 45968 | EX14: 2 | EZ14: QC Not Requested | FA14: 45999 | FB14: 5 | FC14: David Hasty | FD14: Ramon Estrada, Shane Watson | FE14: 46003 | FG14: Issue Still in Process | FH14: Arnold Jurado - @hstakhurskyi@jwmcd.com @jdavis@jwmcd.com PROGRAMMED | FI14: 1010 | FK14: Marc Ribar | FL14: Hennadii Stakhurskyi | FM14: Denis Usatenko | FN14: 24051-FS47C In-House | FO14: TRUE | FP14: 2025, Week 50
A15: 14 | B15: 24051-FS48 | D15: TN Titans Stadium | E15: 1 Titans Way Nashville, TN 37213 | F15: Marc Ribar | G15: 360.798.3603 | H15: 400 | J15: EVERY CRATE REQUIRES REVEALS | K15: EAST LEVEL 200 | L15: * SKETCHES * CUT LIST * EXTRUSION TIGER SAW LIST * COLOR LABELS | M15: 2 SETS - INSTALL DRAWINGS 600 LF - 1 5/8" REVEALS TO MATCH 600 LF - 1 1/8" REVEALS TO MATCH 500 pcs - Corner Clips 1000 pcs﻿ - Color Matched Screws | N15: Q:\Jobs\24051 - TN Titans Stadium\04_Production\24051FS48 | O15: 0.54899315 | P15: 10578 | Q15: 19268 | R15: 124 | S15: 124 | T15: 2 | U15: 992 | V15: 1200 | W15: 42 | X15: 21:14:58 | Y15: 4MM FR CORE TOB BLACK 62 X 196 FR ACM, No Grain | Z15: FR ACM | AA15: 4MM FR CORE TOB BLACK 62 X 196 | AB15: No | AE15: 54 | AF15: -92 | AG15: Unassigned | AH15: Denis Usatenko | AI15: Hennadii Stakhurskyi | AJ15: Hennadii Stakhurskyi | AK15: Hennadii Stakhurskyi | AL15: Hennadii Stakhurskyi | AM15: Denis Usatenko | AN15: Hennadii Stakhurskyi | AP15: Arnold Jurado, Issiah Havens | AS15: TRUE | AU15: Hennadii Stakhurskyi | AV15: 45946.65 | AX15: 45982 | AY15: 45979 | BA15: 46001 | BC15: 46003 | BE15: 46003 | BH15: YES | BI15: 1000 | BO15: MATCH COLOR | BP15: YES | BQ15: Approved | BR15: NO | BT15: NO | BV15: NO | CC15: RTS Titans | CD15: TRUE | CE15: TRUE | CF15: TRUE | CG15: AXYZ Titans Line | DB15: TRUE | DC15: TRUE | DF15: 24051 | DG15: FS | DI15: 48 | DK15: 48 | DL15: 24051-FS231 | DQ15: No Hold | DU15: No Hold | DY15: No Hold | EC15: No Hold | ED15: No Hold | EE15: 24 | EF15: 200 | EQ15: In House | ET15: AXYZ | EU15: AXYZ Titans Line Clean and Brake Fab | EV15: 45979 | EW15: 45979 | EX15: 1 | EZ15: QC Not Requested | FA15: 46001 | FB15: 3 | FC15: David Hasty | FD15: Ramon Estrada, Shane Watson | FE15: 46003 | FG15: Issue Still in Process | FH15: Issiah Havens - @hstakhurskyi@jwmcd.com @jdavis@jwmcd.com PROGRAMMED | FI15: 1010 | FK15: Marc Ribar | FL15: Hennadii Stakhurskyi | FM15: Denis Usatenko | FN15: 24051-FS48 In-House | FP15: 2025, Week 50
A16: 15 | B16: 24051-FS49 | D16: TN Titans Stadium | E16: 1 Titans Way Nashville, TN 37213 | F16: Marc Ribar | G16: 360.798.3603 | H16: 400 | J16: EVERY CRATE REQUIRES REVEALS EVERY CRATE REQUIRES PR2 | K16: EAST LEVEL 200 | L16: * SKETCHES * CUT LIST * EXTRUSION TIGER SAW LIST * COLOR LABELS | M16: 2 SETS - INSTALL DRAWINGS 600 LF - 1 5/8" REVEALS TO MATCH 600 LF - 1 1/8" REVEALS TO MATCH 600 LF - PR2 | N16: Q:\Jobs\24051 - TN Titans Stadium\04_Production\24051FS49 | O16: 0.55542869 | P16: 10702 | Q16: 19268 | R16: 124 | S16: 124 | T16: 2 | U16: 571 | V16: 750 | W16: 9 | X16: 09:12:28 | Y16: 4MM FR CORE TOB BLACK 62 X 196 FR ACM, No Grain | Z16: FR ACM | AA16: 4MM FR CORE TOB BLACK 62 X 196 | AB16: No | AE16: 56 | AF16: -91 | AG16: Unassigned | AH16: Denis Usatenko | AI16: Hennadii Stakhurskyi | AJ16: Hennadii Stakhurskyi | AK16: Hennadii Stakhurskyi | AL16: Hennadii Stakhurskyi | AM16: Denis Usatenko | AN16: Hennadii Stakhurskyi | AP16: Arnold Jurado, Issiah Havens | AS16: TRUE | AU16: Hennadii Stakhurskyi | AV16: 45946.658 | AX16: 45985 | AY16: 45979 | BA16: 46002 | BC16: 46006 | BE16: 46006 | BH16: YES | BI16: 1000 | BO16: MATCH COLOR | BP16: YES | BQ16: Approved | BR16: NO | BT16: NO | BV16: NO | CC16: RTS Titans | CD16: TRUE | CE16: TRUE | CF16: TRUE | CG16: AXYZ Titans Line | DB16: TRUE | DC16: TRUE | DF16: 24051 | DG16: FS | DI16: 49 | DK16: 49 | DL16: 24051-FS231 | DQ16: No Hold | DU16: No Hold | DY16: No Hold | EC16: No Hold | ED16: No Hold | EE16: 8 | EF16: 200 | EQ16: In House | ET16: AXYZ | EU16: AXYZ Titans Line Clean and Brake Fab | EV16: 45979 | EW16: 45979 | EX16: 1 | EZ16: QC Not Requested | FA16: 46001 | FB16: 4 | FC16: David Hasty | FD16: Ramon Estrada, Shane Watson | FE16: 46006 | FG16: Issue Still in Process | FH16: Issiah Havens - @hstakhurskyi@jwmcd.com @jdavis@jwmcd.com PROGRAMMED | FI16: 1010 | FK16: Marc Ribar | FL16: Hennadii Stakhurskyi | FM16: Denis Usatenko | FN16: 24051-FS49 In-House | FP16: 2025, Week 51
A17: 16 | B17: 24051-FS50 | D17: TN Titans Stadium | E17: 1 Titans Way Nashville, TN 37213 | F17: Marc Ribar | G17: 360.798.3603 | H17: 400 | J17: EVERY CRATE REQUIRES REVEALS | K17: AEAST LEVEL 200 | L17: * SKETCHES * CUT LIST * EXTRUSION TIGER SAW LIST * COLOR LABELS | M17: 2 SETS - INSTALL DRAWINGS 600 LF - 1 5/8" REVEALS TO MATCH 600 LF - 1 1/8" REVEALS TO MATCH 250 pcs - Corner Clips 500 pcs﻿ - Color Matched Screws | N17: Q:\Jobs\24051 - TN Titans Stadium\04_Production\24051FS50 | O17: 0.56186423 | P17: 10826 | Q17: 19268 | R17: 124 | S17: 124 | T17: 4 | U17: 744 | V17: 1200 | W17: 39 | X17: 16:51:46 | Y17: 4MM FR CORE TOB BLACK 62 X 196 FR ACM, No Grain | Z17: FR ACM | AA17: 4MM FR CORE TOB BLACK 62 X 196 | AB17: No | AE17: 56 | AF17: -91 | AG17: Unassigned | AH17: Denis Usatenko | AI17: Hennadii Stakhurskyi | AJ17: Hennadii Stakhurskyi | AK17: Hennadii Stakhurskyi | AL17: Hennadii Stakhurskyi | AM17: Denis Usatenko | AN17: Hennadii Stakhurskyi | AP17: Arnold Jurado, Issiah Havens | AS17: TRUE | AU17: Hennadii Stakhurskyi | AV17: 45946.661 | AX17: 45985 | AY17: 45979 | BA17: 46002 | BC17: 46006 | BE17: 46006 | BH17: YES | BI17: 1000 | BO17: MATCH COLOR | BP17: YES | BQ17: Approved | BR17: NO | BT17: NO | BV17: NO | CC17: RTS Titans | CD17: TRUE | CE17: TRUE | CF17: TRUE | CG17: AXYZ Titans Line | DB17: TRUE | DC17: TRUE | DF17: 24051 | DG17: FS | DI17: 50 | DK17: 50 | DL17: 24051-FS231 | DQ17: No Hold | DU17: No Hold | DY17: No Hold | EC17: No Hold | ED17: No Hold | EE17: 8 | EF17: 200 | EQ17: In House | ET17: AXYZ | EU17: AXYZ Titans Line Clean and Brake Fab | EV17: 45979 | EW17: 45979 | EX17: 1 | EZ17: QC Not Requested | FA17: 46006 | FB17: 1 | FC17: David Hasty | FD17: Ramon Estrada, Shane Watson | FE17: 46006 | FG17: Issue Still in Process | FH17: Issiah Havens - @hstakhurskyi@jwmcd.com @jdavis@jwmcd.com PROGRAMMED | FI17: 1010 | FK17: Marc Ribar | FL17: Hennadii Stakhurskyi | FM17: Denis Usatenko | FN17: 24051-FS50 In-House | FP17: 2025, Week 51
A18: 17 | B18: 24051-FS50C | D18: TN Titans Stadium | E18: 1 Titans Way Nashville, TN 37213 | F18: Marc Ribar | G18: 360.798.3603 | H18: 400 | J18: EVERY CRATE REQUIRES REVEALS | K18: EAST LEVEL 200 COPING | L18: * SKETCHES * CUT LIST * EXTRUSION TIGER SAW LIST * COLOR LABELS | M18: 2 SETS - INSTALL DRAWINGS 200 LF - 1 5/8" REVEALS TO MATCH 50 pcs - Corner Clips 100 pcs﻿ - Color Matched Screws | N18: Q:\Jobs\24051 - TN Titans Stadium\04_Production\24051FS50C | O18: 0.56310982 | P18: 10850 | Q18: 19268 | R18: 24 | S18: 24 | T18: 2 | U18: 168 | V18: 200 | W18: 3 | X18: 02:29:59 | Y18: 4MM FR CORE TOB BLACK 62 X 196 FR ACM, No Grain | Z18: FR ACM | AA18: 4MM FR CORE TOB BLACK 62 X 196 | AB18: No | AE18: 56 | AF18: -91 | AG18: Unassigned | AH18: Denis Usatenko | AI18: Hennadii Stakhurskyi | AJ18: Hennadii Stakhurskyi | AK18: Hennadii Stakhurskyi | AL18: Hennadii Stakhurskyi | AM18: Denis Usatenko | AN18: Hennadii Stakhurskyi | AP18: Arnold Jurado, Issiah Havens | AS18: TRUE | AU18: Hennadii Stakhurskyi | AV18: 45946.667 | AX18: 45985 | AY18: 45979 | BA18: 46002 | BC18: 46006 | BE18: 46006 | BH18: YES | BI18: 1000 | BO18: MATCH COLOR | BP18: YES | BQ18: Approved | BR18: NO | BT18: NO | BV18: NO | CC18: RTS Titans | CD18: TRUE | CE18: TRUE | CF18: TRUE | CG18: AXYZ Titans Line | DB18: TRUE | DC18: TRUE | DF18: 24051 | DG18: FS | DI18: 50C | DK18: 0 | DL18: 24051-FS231 | DQ18: No Hold | DU18: No Hold | DY18: No Hold | EC18: No Hold | ED18: No Hold | EE18: 4 | EF18: 40 | EQ18: In House | ET18: AXYZ | EU18: AXYZ Titans Line Clean and Brake Fab | EV18: 45979 | EW18: 45979 | EX18: 1 | EZ18: QC Not Requested | FA18: 46006 | FB18: 1 | FC18: David Hasty | FD18: Ramon Estrada, Shane Watson | FE18: 46006 | FG18: Issue Still in Process | FH18: Issiah Havens - @hstakhurskyi@jwmcd.com @jdavis@jwmcd.com PROGRAMMED | FI18: 1010 | FK18: Marc Ribar | FL18: Hennadii Stakhurskyi | FM18: Denis Usatenko | FN18: 24051-FS50C In-House | FP18: 2025, Week 51
A19: 18 | B19: 24051-FS51 | D19: TN Titans Stadium | E19: 1 Titans Way Nashville, TN 37213 | F19: Marc Ribar | G19: 360.798.3603 | H19: 400 | J19: EVERY CRATE REQUIRES REVEALS EVERY CRATE REQUIRES PR2 | K19: EAST LEVEL 300 | L19: * SKETCHES * CUT LIST * EXTRUSION TIGER SAW LIST * COLOR LABELS | M19: 2 SETS - INSTALL DRAWINGS 700 LF - 1 5/8" REVEALS TO MATCH 500 LF - 1 1/8" REVEALS TO MATCH 200 LF - PR2 500 pcs - Corner Clips 1000 pcs﻿ - Color Matched Screws | N19: Q:\Jobs\24051 - TN Titans Stadium\04_Production\24051FS51 | O19: 0.56933776 | P19: 10970 | Q19: 19268 | R19: 120 | S19: 120 | T19: 9 | U19: 825 | V19: 1200 | W19: 34 | X19: 16:19:31 | Y19: 4M X 62" X 196", TOB BLACK FR ACM, No Grain | Z19: FR ACM | AA19: 4M X 62" X 196", TOB BLACK | AB19: No | AE19: 61 | AF19: -73 | AG19: Unassigned | AH19: Denis Usatenko | AI19: Hennadii Stakhurskyi | AJ19: Hennadii Stakhurskyi | AK19: Hennadii Stakhurskyi | AL19: Hennadii Stakhurskyi | AM19: Denis Usatenko | AN19: Hennadii Stakhurskyi | AP19: Arnold Jurado, Issiah Havens | AS19: TRUE | AU19: Hennadii Stakhurskyi | AV19: 45951.434 | AX19: 46009 | AY19: 45979 | BA19: 46028 | BC19: 46030 | BE19: 46030 | BH19: YES | BI19: 1000 | BO19: MATCH COLOR | BP19: YES | BQ19: Approved | BR19: NO | BT19: NO | BV19: NO | CC19: RTS Titans | CD19: TRUE | CE19: TRUE | CF19: TRUE | CG19: AXYZ Titans Line | DB19: TRUE | DC19: TRUE | DF19: 24051 | DG19: FS | DI19: 51 | DK19: 51 | DL19: 24051-FS231 | DQ19: No Hold | DU19: No Hold | DY19: No Hold | EC19: No Hold | ED19: No Hold | EE19: 8 | EF19: 200 | EQ19: In House | ET19: AXYZ | EU19: AXYZ Titans Line Clean and Brake Fab | EV19: 45979 | EW19: 45979 | EX19: 1 | EZ19: QC Not Requested | FA19: 46025 | FB19: 4 | FC19: David Hasty | FD19: Ramon Estrada, Shane Watson | FE19: 46030 | FG19: Issue Still in Process | FH19: Issiah Havens - @hstakhurskyi@jwmcd.com @jdavis@jwmcd.com PROGRAMMED | FI19: 1010 | FK19: Marc Ribar | FL19: Hennadii Stakhurskyi | FM19: Denis Usatenko | FN19: 24051-FS51 In-House | FP19: 2026, Week 02
A20: 19 | B20: 24051-FS51C | D20: TN Titans Stadium | E20: 1 Titans Way Nashville, TN 37213 | F20: Marc Ribar | G20: 360.798.3603 | H20: 400 | J20: EVERY CRATE REQUIRES REVEALS | K20: EAST LEVEL 300 COPING | L20: * SKETCHES * CUT LIST * EXTRUSION TIGER SAW LIST * COLOR LABELS | M20: 2 SETS - INSTALL DRAWINGS 250 LF - 1 5/8" REVEALS TO MATCH 175 pcs - Corner Clips 350 pcs﻿ - Color Matched Screws | N20: Q:\Jobs\24051 - TN Titans Stadium\04_Production\24051FS51C | O20: 0.57141374 | P20: 11010 | Q20: 19268 | R20: 40 | S20: 40 | T20: 3 | U20: 280 | V20: 250 | W20: 4 | X20: 04:05:04 | Y20: 4mm X 62" X 196", TOB BLACK FR ACM, No Grain | Z20: FR ACM | AA20: 4mm X 62" X 196", TOB BLACK | AB20: No | AE20: 59 | AF20: -75 | AG20: Unassigned | AH20: Denis Usatenko | AI20: Hennadii Stakhurskyi | AJ20: Hennadii Stakhurskyi | AK20: Hennadii Stakhurskyi | AL20: Hennadii Stakhurskyi | AM20: Denis Usatenko | AN20: Hennadii Stakhurskyi | AP20: Arnold Jurado, Issiah Havens | AS20: TRUE | AU20: Hennadii Stakhurskyi | AV20: 45951.437 | AX20: 46007 | AY20: 45979 | BA20: 46024 | BC20: 46028 | BE20: 46028 | BH20: YES | BI20: 1000 | BO20: MATCH COLOR | BP20: YES | BQ20: Approved | BR20: NO | BT20: NO | BV20: NO | CC20: RTS Titans | CD20: TRUE | CE20: TRUE | CF20: TRUE | CG20: AXYZ Titans Line | DB20: TRUE | DC20: TRUE | DF20: 24051 | DG20: FS | DI20: 51C | DK20: 0 | DL20: 24051-FS231 | DQ20: No Hold | DU20: No Hold | DY20: No Hold | EC20: No Hold | ED20: No Hold | EE20: 4 | EF20: 40 | EQ20: In House | ET20: AXYZ | EU20: AXYZ Titans Line Clean and Brake Fab | EV20: 45979 | EW20: 45979 | EX20: 1 | EZ20: QC Not Requested | FA20: 46025 | FB20: 2 | FC20: David Hasty | FD20: Ramon Estrada, Shane Watson | FE20: 46028 | FG20: Issue Still in Process | FH20: Issiah Havens - @jdavis@jwmcd.com @hstakhurskyi@jwmcd.com PROGRAMMED | FI20: 1010 | FK20: Marc Ribar | FL20: Hennadii Stakhurskyi | FM20: Denis Usatenko | FN20: 24051-FS51C In-House | FP20: 2026, Week 02
A21: 20 | B21: 24051-FS217 | D21: TN Titans Stadium | E21: 1 Titans Way Nashville, TN 37213 | F21: Marc Ribar | G21: 360.798.3603 | H21: 400 | J21: EVERY CRATE REQUIRES REVEALS | K21: REF SHOP DRAWING 4113. EAST ELEVATION ON THE SOUTH SIDE. CL S16 | L21: * SKETCHES * CUT LIST * EXTRUSION TIGER SAW LIST * COLOR LABELS | M21: 2 SETS - INSTALL DRAWINGS 100 LF - 1 5/8" REVEALS TO MATCH 25 pcs - Corner Clips 50 pcs - Color Matched Screws | N21: Q:\Jobs\24051 - TN Titans Stadium\04_Production\24051FS217 | O21: 0.51479136 | P21: 9919 | Q21: 19268 | R21: 12 | S21: 12 | T21: 3 | U21: 84 | V21: 100 | W21: 4 | X21: 01:41:18 | Y21: Alpolic - 4mm - 880 pcs - [62 X 196] - MOONSTONE METALLIC FR ACM, Grain | Z21: FR ACM | AA21: Alpolic - 4mm - 880 pcs - [62 X 196] - MOONSTONE METALLIC | AB21: Yes | AE21: 50 | AF21: -97 | AG21: Unassigned | AH21: Denis Usatenko | AI21: Hennadii Stakhurskyi | AJ21: Hennadii Stakhurskyi | AL21: Hennadii Stakhurskyi | AM21: Denis Usatenko | AN21: Hennadii Stakhurskyi | AP21: Arnold Jurado, Issiah Havens | AS21: TRUE | AU21: Hennadii Stakhurskyi | AV21: 45946.602 | AX21: 45975 | AY21: 45960 | BA21: 45994 | BC21: 45996 | BE21: 45996 | BH21: YES | BI21: 500 | BO21: MATCH COLOR | BP21: YES | BQ21: Approved | BR21: NO | BT21: NO | BV21: NO | CC21: RTS Titans | CD21: TRUE | CE21: TRUE | CF21: TRUE | CG21: AXYZ Titans Line | DB21: TRUE | DC21: TRUE | DF21: 24051 | DG21: FS | DI21: 217 | DK21: 217 | DL21: 24051-FS231 | DQ21: No Hold | DU21: No Hold | DY21: No Hold | EC21: No Hold | ED21: No Hold | EE21: 4 | EF21: 16 | EQ21: In House | ET21: AXYZ | EU21: AXYZ Titans Line Clean and Brake Fab | EV21: 45959 | EW21: 45959 | EX21: 1 | EZ21: QC Not Requested | FA21: 45975 | FB21: 9 | FC21: David Hasty | FD21: Ramon Estrada, Shane Watson | FE21: 45987 | FG21: Issue Still in Process | FH21: Issiah Havens - @jdavis@jwmcd.com @hstakhurskyi@jwmcd.com PROGRAMMED | FI21: 1010 | FK21: Marc Ribar | FL21: Hennadii Stakhurskyi | FM21: Denis Usatenko | FN21: 24051-FS217 In-House | FP21: 2025, Week 49
A22: 21 | B22: 24051-FS218 | D22: TN Titans Stadium | E22: 1 Titans Way Nashville, TN 37213 | F22: Marc Ribar | G22: 360.798.3603 | H22: 400 | J22: EVERY CRATE REQUIRES REVEALS | K22: EAST LEVEL 300 | L22: * SKETCHES * CUT LIST * EXTRUSION TIGER SAW LIST * COLOR LABELS | M22: 2 SETS - INSTALL DRAWINGS 600 LF - 1 5/8" REVEALS TO MATCH 590 pcs - Corner Clips 1180 pcs - Color Matched Screws | N22: Q:\Jobs\24051 - TN Titans Stadium\04_Production\24051FS218 | O22: 0.51982562 | P22: 10016 | Q22: 19268 | R22: 97 | S22: 97 | T22: 2 | U22: 970 | V22: 600 | W22: 49 | X22: 18:13:15 | Y22: Alpolic - 4mm - 880 pcs - [62 X 196] - MOONSTONE METALLIC FR ACM, Grain | Z22: FR ACM | AA22: Alpolic - 4mm - 880 pcs - [62 X 196] - MOONSTONE METALLIC | AB22: Yes | AE22: 50 | AF22: -97 | AG22: Unassigned | AH22: Denis Usatenko | AI22: Hennadii Stakhurskyi | AJ22: Hennadii Stakhurskyi | AL22: Hennadii Stakhurskyi | AM22: Denis Usatenko | AN22: Hennadii Stakhurskyi | AP22: Arnold Jurado, Issiah Havens | AS22: TRUE | AU22: Hennadii Stakhurskyi | AV22: 45950.367 | AX22: 45975 | AY22: 45960 | BA22: 45994 | BC22: 45996 | BE22: 45996 | BH22: YES | BI22: 500 | BO22: MATCH COLOR | BP22: YES | BQ22: Approved | BR22: NO | BT22: NO | BV22: NO | CC22: RTS Titans | CD22: TRUE | CE22: TRUE | CF22: TRUE | CG22: AXYZ Titans Line | DB22: TRUE | DC22: TRUE | DF22: 24051 | DG22: FS | DI22: 218 | DK22: 218 | DL22: 24051-FS231 | DQ22: No Hold | DU22: No Hold | DY22: No Hold | EC22: No Hold | ED22: No Hold | EE22: 8 | EF22: 180 | EQ22: In House | ET22: AXYZ | EU22: AXYZ Titans Line Clean and Brake Fab | EV22: 45959 | EW22: 45959 | EX22: 1 | EZ22: QC Not Requested | FA22: 45976 | FB22: 6 | FC22: David Hasty | FD22: Ramon Estrada, Shane Watson | FE22: 45985 | FG22: Issue Still in Process | FH22: Issiah Havens - @hstakhurskyi@jwmcd.com @jdavis@jwmcd.com PROGRAMMED | FI22: 1010 | FK22: Marc Ribar | FL22: Hennadii Stakhurskyi | FM22: Denis Usatenko | FN22: 24051-FS218 In-House | FP22: 2025, Week 49
A23: 22 | B23: 24051-FS219 | D23: TN Titans Stadium | E23: 1 Titans Way Nashville, TN 37213 | F23: Marc Ribar | G23: 360.798.3603 | H23: 400 | J23: EVERY CRATE REQUIRES REVEALS | K23: EAST LEVEL 400 | L23: * SKETCHES * CUT LIST * EXTRUSION TIGER SAW LIST * COLOR LABELS | M23: 2 SETS - INSTALL DRAWINGS 650 LF - 1 5/8" REVEALS TO MATCH 660 pcs - Corner Clips 1320 pcs - Color Matched Screws | N23: Q:\Jobs\24051 - TN Titans Stadium\04_Production\24051FS219 | O23: 0.52548267 | P23: 10125 | Q23: 19268 | R23: 109 | S23: 109 | T23: 2 | U23: 1090 | V23: 650 | W23: 55 | X23: 20:28:06 | Y23: Alpolic - 4mm - 880 pcs - [62 X 196] - MOONSTONE METALLIC FR ACM, Grain | Z23: FR ACM | AA23: Alpolic - 4mm - 880 pcs - [62 X 196] - MOONSTONE METALLIC | AB23: Yes | AE23: 49 | AF23: -99 | AG23: Unassigned | AH23: Denis Usatenko | AI23: Hennadii Stakhurskyi | AJ23: Hennadii Stakhurskyi | AL23: Hennadii Stakhurskyi | AM23: Denis Usatenko | AN23: Hennadii Stakhurskyi | AP23: Arnold Jurado, Issiah Havens | AS23: TRUE | AU23: Hennadii Stakhurskyi | AV23: 45951.636 | AX23: 45973 | AY23: 45960 | BA23: 45992 | BC23: 45994 | BE23: 45994 | BH23: YES | BI23: 500 | BO23: MATCH COLOR | BP23: YES | BQ23: Approved | BR23: NO | BT23: NO | BV23: NO | CC23: RTS Titans | CD23: TRUE | CE23: TRUE | CF23: TRUE | CG23: AXYZ Titans Line | DB23: TRUE | DC23: TRUE | DF23: 24051 | DG23: FS | DI23: 219 | DK23: 219 | DL23: 24051-FS231 | DQ23: No Hold | DU23: No Hold | DY23: No Hold | EC23: No Hold | ED23: No Hold | EE23: 12 | EF23: 300 | EQ23: In House | ET23: AXYZ | EU23: AXYZ Titans Line Clean and Brake Fab | EV23: 45959 | EW23: 45959 | EX23: 1 | EZ23: QC Not Requested | FA23: 45996 | FB23: 2 | FC23: David Hasty | FD23: Ramon Estrada, Shane Watson | FE23: 45999 | FG23: Issue Still in Process | FH23: Issiah Havens - @hstakhurskyi@jwmcd.com @jdavis@jwmcd.com PROGRAMMED | FI23: 1010 | FK23: Marc Ribar | FL23: Hennadii Stakhurskyi | FM23: Denis Usatenko | FN23: 24051-FS219 In-House | FP23: 2025, Week 49
A24: 23 | B24: 24051-FS221 | D24: TN Titans Stadium | E24: 1 Titans Way Nashville, TN 37213 | F24: Marc Ribar | G24: 360.798.3603 | H24: 400 | K24: Moonstone panels for sheet 6110 install right to left | L24: * SKETCHES * CUT LIST * EXTRUSION TIGER SAW LIST * COLOR LABELS | M24: * 2 SETS - INSTALL DRAWINGS * (75 LF) 1-5/8" Reveals | N24: Q:\Jobs\24051 - TN Titans Stadium\04_Production\24051FS221 | O24: 0.65881254 | P24: 12694 | Q24: 19268 | R24: 13 | S24: 13 | T24: 3 | U24: 91 | V24: 55 | W24: 5 | X24: 01:53:04 | Y24: 4mm X 62" X 196", moonstone metallic FR ACM, Grain | Z24: FR ACM | AA24: 4mm X 62" X 196", moonstone metallic | AB24: Yes | AE24: 75 | AF24: -46 | AG24: Unassigned | AH24: Denis Usatenko | AI24: Hennadii Stakhurskyi | AJ24: Hennadii Stakhurskyi | AL24: Hennadii Stakhurskyi | AM24: Denis Usatenko | AN24: Ailen Niedfeld | AP24: Arnold Jurado, Issiah Havens | AS24: TRUE | AU24: Ailen Niedfeld | AV24: 46010.47 | AX24: 46041 | AY24: 46049 | AZ24: TRUE | BA24: 46065 | BC24: 46062 | BE24: 46062 | BH24: YES | BI24: 200 | BO24: MATCH COLOR | BP24: YES | BQ24: Approved | BR24: NO | BT24: NO | BV24: NO | CC24: RTS Titans | CE24: TRUE | CF24: TRUE | CG24: AXYZ Titans Line | DB24: TRUE | DC24: TRUE | DF24: 24051 | DG24: FS | DI24: 221 | DK24: 221 | DL24: 24051-FS231 | DQ24: No Hold | DU24: No Hold | DY24: No Hold | EC24: No Hold | ED24: No Hold | EE24: 8 | EF24: 16 | EQ24: In House | ET24: AXYZ | EU24: AXYZ Titans Line Clean and Brake Fab | EV24: 46045 | EW24: 46049 | EX24: 3 | EZ24: QC Not Requested | FA24: 46080 | FB24: 1 | FC24: David Hasty | FD24: Ramon Estrada, Shane Watson | FE24: 46081 | FG24: Issue Still in Process | FH24: Issiah Havens - @jdavis@jwmcd.com PROGRAMMED. @aniedfeld@jwmcd.com please print all programming documents in the "PROGRAMMING DOCS" folder | FI24: 1010 | FK24: Marc Ribar | FL24: Hennadii Stakhurskyi | FM24: Denis Usatenko | FN24: 24051-FS221 In-House | FO24: TRUE | FP24: 2026, Week 07
A25: 24 | B25: 24051-FS223 | D25: TN Titans Stadium | E25: 1 Titans Way Nashville, TN 37213 | F25: Marc Ribar | G25: 360.798.3603 | H25: 400 | K25: LEVEL 50 NORTH ELEVATION | L25: * SKETCHES * CUT LIST * EXTRUSION TIGER SAW LIST * COLOR LABELS | M25: * 2 SETS - INSTALL DRAWINGS * (500 LF) 1-5/8" Reveals * (100 LF) 1-1/8" Reveals * (20 LF) JR-Extended * (24 pcs) 2' - 0" x 2' - 0" x 1-5/8" Corner reveals | N25: Q:\Jobs\24051 - TN Titans Stadium\04_Production\24051FS223 | O25: 0.75467096 | P25: 14541 | Q25: 19268 | R25: 44 | S25: 90 | T25: 59 | U25: 387 | V25: 700 | W25: 23 | X25: 08:01:00 | Y25: 4mm X 62" X 196", MOONSTONE METALLIC FR ACM, Grain | Z25: FR ACM | AA25: 4mm X 62" X 196", MOONSTONE METALLIC | AB25: Yes | AE25: 2 | AF25: -6 | AG25: Corey Howse | AH25: Denis Usatenko | AI25: Hennadii Stakhurskyi | AJ25: Hennadii Stakhurskyi | AL25: Hennadii Stakhurskyi | AM25: Denis Usatenko | AN25: Hennadii Stakhurskyi | AP25: Arnold Jurado, Issiah Havens | AS25: TRUE | AU25: Hennadii Stakhurskyi | AV25: 46055.457 | AX25: 46076 | AY25: 46105 | AZ25: TRUE | BA25: 46121 | BC25: 46097 | BE25: 46097 | BH25: YES | BI25: 500 | BO25: MATCH COLOR | BP25: YES | BQ25: Approved | BR25: NO | BT25: NO | BV25: NO | CC25: Clean and Brake | CD25: TRUE | CE25: TRUE | CF25: TRUE | CG25: AXYZ Titans Line | DB25: TRUE | DC25: TRUE | DF25: 24051 | DG25: FS | DI25: 223 | DK25: 223 | DL25: 24051-FS231 | DQ25: No Hold | DU25: No Hold | DY25: No Hold | EC25: No Hold | ED25: No Hold | EE25: 12 | EF25: 40 | EQ25: In House | ET25: AXYZ | EU25: AXYZ Titans Line Clean and Brake Fab | EV25: 46105 | EW25: 46105 | EX25: 1 | EZ25: Issue Still In Process | FB25: Issue Still In Process | FC25: David Hasty | FD25: Ramon Estrada, Shane Watson | FG25: Issue Still in Process | FH25: Issiah Havens - @dusatenko@jwmcd.com @jdavis@jwmcd.com programmed | FI25: 1010 | FK25: Marc Ribar | FL25: Hennadii Stakhurskyi | FM25: Denis Usatenko | FN25: 24051-FS223 In-House | FP25: 2026, Week 12
A26: 25 | B26: 24051-FS224 | D26: TN Titans Stadium | E26: 1 Titans Way Nashville, TN 37213 | F26: Marc Ribar | G26: 360.798.3603 | H26: 400 | J26: NORTH FIELD MEASURES | L26: * SKETCHES * CUT LIST * EXTRUSION TIGER SAW LIST * COLOR LABELS | M26: * 2 SETS - INSTALL DRAWINGS * (8 LF) JR2 | N26: Q:\Jobs\24051 - TN Titans Stadium\04_Production\24051FS224 | O26: 0.75477476 | P26: 14543 | Q26: 19268 | R26: 2 | S26: 2 | T26: 2 | U26: 16 | V26: 0 | W26: 1 | X26: 00:17:51 | Y26: 4mm X 62" X 196", MOONSTONE METALLIC FR ACM, Grain | Z26: FR ACM | AA26: 4mm X 62" X 196", MOONSTONE METALLIC | AB26: Yes | AE26: 101 | AF26: -6 | AG26: Unassigned | AH26: Denis Usatenko | AI26: Hennadii Stakhurskyi | AJ26: Hennadii Stakhurskyi | AL26: Hennadii Stakhurskyi | AM26: Denis Usatenko | AN26: Hennadii Stakhurskyi | AP26: Arnold Jurado, Issiah Havens | AS26: TRUE | AU26: Hennadii Stakhurskyi | AV26: 46058.48 | AW26: TRUE | AX26: 46079 | AY26: 46105 | AZ26: TRUE | BA26: 46121 | BC26: 46097 | BE26: 46097 | BH26: YES | BI26: 500 | BO26: MATCH COLOR | BP26: YES | BQ26: Approved | BR26: NO | BT26: NO | BV26: NO | CC26: RTS Titans | CD26: TRUE | CE26: TRUE | CF26: TRUE | CG26: AXYZ Titans Line | DB26: TRUE | DC26: TRUE | DF26: 24051 | DG26: FS | DI26: 224 | DK26: 224 | DL26: 24051-FS231 | DQ26: No Hold | DU26: No Hold | DY26: No Hold | EC26: No Hold | ED26: No Hold | EE26: 2 | EF26: 4 | EQ26: In House | ET26: AXYZ | EU26: AXYZ Titans Line Clean and Brake Fab | EV26: 46105 | EW26: 46105 | EX26: 1 | EZ26: QC Not Requested | FA26: 46108 | FB26: 7 | FC26: David Hasty | FD26: Ramon Estrada, Shane Watson | FE26: 46118 | FG26: Issue Still in Process | FH26: Issiah Havens - @dusatenko@jwmcd.com @jdavis@jwmcd.com programmed | FI26: 1010 | FK26: Marc Ribar | FL26: Hennadii Stakhurskyi | FM26: Denis Usatenko | FN26: 24051-FS224 In-House | FP26: 2026, Week 12
A27: 26 | B27: 24051-FS67 | D27: TN Titans Stadium | E27: 1 Titans Way Nashville, TN 37213 | F27: Marc Ribar | G27: 360.798.3603 | H27: 400 | J27: THIS IS WEST ELEVTION LEVEL 00 - 200 FIELD MEASURES. PLEASE NOT THAT THEY ARE PROVIDING FINISHED PANEL SIZES. | L27: * SKETCHES * CUT LIST * EXTRUSION TIGER SAW LIST * COLOR LABELS | M27: * 2 SETS - INSTALL DRAWINGS * (60 LF) 1-5/8" Reveals * (11 LF) JR-EXTENDED * 70 PCS CORNER CLIPS * 162 PCS COLOR MATCHING SCREWS | N27: Q:\Jobs\24051 - TN Titans Stadium\04_Production\24051FS67 | O27: 0.66462529 | P27: 12806 | Q27: 19268 | R27: 14 | S27: 14 | T27: 14 | U27: 138 | V27: 60 | W27: 4 | X27: 01:51:35 | Y27: 4mm X 62" X 196", TOB BLACK FR ACM, No Grain | Z27: FR ACM | AA27: 4mm X 62" X 196", TOB BLACK | AB27: No | AE27: 79 | AF27: -43 | AG27: Unassigned | AH27: Denis Usatenko | AI27: Hennadii Stakhurskyi | AJ27: Hennadii Stakhurskyi | AL27: Hennadii Stakhurskyi | AM27: Denis Usatenko | AN27: Gabriela Herrera | AP27: Arnold Jurado, Issiah Havens | AS27: TRUE | AU27: Gabriela Herrera | AV27: 46007.484 | AW27: TRUE | AX27: 46028 | AY27: 46052 | AZ27: TRUE | BA27: 46070 | BC27: 46041 | BE27: 46041 | BH27: YES | BI27: 1000 | BO27: MATCH COLOR | BP27: YES | BQ27: Approved | BR27: NO | BT27: NO | BV27: NO | CC27: RTS Titans | CD27: TRUE | CE27: TRUE | CF27: TRUE | CG27: AXYZ Titans Line | DB27: TRUE | DC27: TRUE | DF27: 24051 | DG27: FS | DI27: 67 | DK27: 67 | DL27: 24051-FS231 | DQ27: No Hold | DU27: No Hold | DY27: No Hold | EC27: No Hold | ED27: No Hold | EE27: 4 | EF27: 16 | EQ27: In House | ET27: AXYZ | EU27: AXYZ Titans Line Clean and Brake Fab | EV27: 46052 | EW27: 46052 | EX27: 1 | EZ27: QC Not Requested | FA27: 46073 | FB27: 2 | FC27: David Hasty | FD27: Ramon Estrada, Shane Watson | FE27: 46076 | FG27: Issue Still in Process | FH27: Issiah Havens - @gherrera@jwmcd.com @jdavis@jwmcd.com PROGRAMMED | FI27: 1010 | FK27: Marc Ribar | FL27: Hennadii Stakhurskyi | FM27: Denis Usatenko | FN27: 24051-FS67 In-House | FP27: 2026, Week 04
A28: 27 | B28: 24051-FS72 | D28: TN Titans Stadium | E28: 1 Titans Way Nashville, TN 37213 | F28: Marc Ribar | G28: 360.798.3603 | H28: 400 | K28: LEVEL 300 NORTH ELEVATION | L28: * SKETCHES * CUT LIST * EXTRUSION TIGER SAW LIST * COLOR LABELS | M28: * 2 SETS - INSTALL DRAWINGS * (1300 LF) 1-5/8" Reveals * (100 LF) 1-1/8" Reveals﻿ * (120 LF) JR2 | N28: Q:\Jobs\24051 - TN Titans Stadium\04_Production\24051FS72 | O28: 0.67002284 | P28: 12910 | Q28: 19268 | R28: 104 | S28: 104 | T28: 12 | U28: 704 | V28: 1400 | W28: 104 SHEETS | X28: 00d21h07m06s | Y28: 4mm X 62" X 196", TOB BLACK FR ACM, No Grain | Z28: FR ACM | AA28: 4mm X 62" X 196", TOB BLACK | AB28: No | AE28: 81 | AF28: -34 | AG28: Unassigned | AH28: Denis Usatenko | AI28: Hennadii Stakhurskyi | AJ28: Hennadii Stakhurskyi | AL28: Hennadii Stakhurskyi | AM28: Denis Usatenko | AN28: Hennadii Stakhurskyi | AP28: Arnold Jurado, Issiah Havens | AS28: TRUE | AU28: Hennadii Stakhurskyi | AV28: 46009.443 | AX28: 46034 | AY28: 46065 | AZ28: TRUE | BA28: 46083 | BC28: 46055 | BE28: 46055 | BH28: YES | BI28: 1000 | BO28: MATCH COLOR | BP28: YES | BQ28: Approved | BR28: NO | BT28: NO | BV28: NO | CC28: RTS Titans | CD28: TRUE | CE28: TRUE | CF28: TRUE | DB28: TRUE | DC28: TRUE | DF28: 24051 | DG28: FS | DI28: 72 | DK28: 72 | DL28: 24051-FS231 | DQ28: No Hold | DU28: No Hold | DY28: No Hold | EC28: No Hold | ED28: No Hold | EE28: 4 | EF28: 200 | EQ28: In House | ET28: AXYZ | EU28: AXYZ Clean and Brake Fab | EV28: 46064 | EW28: 46065 | EX28: 2 | EZ28: QC Not Requested | FA28: 46085 | FB28: 1 | FC28: David Hasty | FD28: Ramon Estrada, Shane Watson | FE28: 46085 | FG28: Issue Still in Process | FH28: Arnold Jurado - @hstakhurskyi@jwmcd.com @jdavis@jwmcd.com PROGRAMMED | FI28: 1010 | FK28: Marc Ribar | FL28: Hennadii Stakhurskyi | FM28: Denis Usatenko | FN28: 24051-FS72 In-House | FO28: TRUE | FP28: 2026, Week 06
A29: 28 | B29: 24051-FS73 | D29: TN Titans Stadium | E29: 1 Titans Way Nashville, TN 37213 | F29: Marc Ribar | G29: 360.798.3603 | H29: 400 | K29: NORTH LEVEL 50 | L29: * SKETCHES * CUT LIST * EXTRUSION TIGER SAW LIST * COLOR LABELS | M29: * 2 SETS - INSTALL DRAWINGS * ( 750 LF) 1-5/8" Reveals * ( 150 LF) 1-1/8" Reveals * ( 120 LF) JR-EXTENDED | N29: Q:\Jobs\24051 - TN Titans Stadium\04_Production\24051FS73 | O29: 0.6734482 | P29: 12976 | Q29: 19268 | R29: 66 | S29: 66 | T29: 24 | U29: 386 | V29: 900 | W29: 65 SHEETS | X29: 00d12h40m13s | Y29: 4mm X 62" X 196", TOB BLACK FR ACM, No Grain | Z29: FR ACM | AA29: 4mm X 62" X 196", TOB BLACK | AB29: No | AE29: 81 | AF29: -34 | AG29: Unassigned | AH29: Denis Usatenko | AI29: Hennadii Stakhurskyi | AJ29: Hennadii Stakhurskyi | AL29: Hennadii Stakhurskyi | AM29: Denis Usatenko | AN29: Hennadii Stakhurskyi | AP29: Arnold Jurado, Issiah Havens | AS29: TRUE | AU29: Hennadii Stakhurskyi | AV29: 46009.466 | AX29: 46034 | AY29: 46065 | AZ29: TRUE | BA29: 46083 | BC29: 46055 | BE29: 46055 | BH29: YES | BI29: 1000 | BO29: MATCH COLOR | BP29: YES | BQ29: Approved | BR29: NO | BT29: NO | BV29: NO | CC29: RTS Titans | CD29: TRUE | CE29: TRUE | CF29: TRUE | DB29: TRUE | DC29: TRUE | DF29: 24051 | DG29: FS | DI29: 73 | DK29: 73 | DL29: 24051-FS231 | DQ29: No Hold | DU29: No Hold | DY29: No Hold | EC29: No Hold | ED29: No Hold | EE29: 16 | EF29: 120 | EQ29: In House | ET29: AXYZ | EU29: AXYZ Clean and Brake Fab | EV29: 46064 | EW29: 46065 | EX29: 2 | EZ29: QC Not Requested | FA29: 46085 | FB29: 2 | FC29: David Hasty | FD29: Ramon Estrada, Shane Watson | FE29: 46086 | FG29: Issue Still in Process | FH29: Arnold Jurado - @hstakhurskyi@jwmcd.com @jdavis@jwmcd.com PROGRAMMED | FI29: 1010 | FK29: Marc Ribar | FL29: Hennadii Stakhurskyi | FM29: Denis Usatenko | FN29: 24051-FS73 In-House | FP29: 2026, Week 06
A30: 29 | B30: 24051-FS56 | D30: TN Titans Stadium | E30: 1 Titans Way Nashville, TN 37213 | F30: Marc Ribar | G30: 360.798.3603 | H30: 400 | J30: EVERY CRATE REQUIRES REVEALS | K30: EAST LEVEL 400 | L30: * SKETCHES * CUT LIST * EXTRUSION TIGER SAW LIST * COLOR LABELS | M30: * 2 SETS - INSTALL DRAWINGS * 700 LF - 1 1/8" REVEALS TO MATCH * 1300 LF - 1 5/8" REVEALS TO MATCH * 300 pcs - Corner Clips * 600 pcs﻿ - Color Matched Screws | N30: Q:\Jobs\24051 - TN Titans Stadium\04_Production\24051FS56 | O30: 0.59367864 | P30: 11439 | Q30: 19268 | R30: 149 | S30: 149 | T30: 2 | U30: 894 | V30: 2000 | W30: 38 SHEETS | X30: 00d19h23m01s | Y30: 4mm X 62" X 196", TOB BLACK FR ACM, No Grain | Z30: FR ACM | AA30: 4mm X 62" X 196", TOB BLACK | AB30: No | AE30: 67 | AF30: -57 | AG30: Unassigned | AH30: Denis Usatenko | AI30: Hennadii Stakhurskyi | AJ30: Hennadii Stakhurskyi | AL30: Hennadii Stakhurskyi | AM30: Denis Usatenko | AN30: Hennadii Stakhurskyi | AP30: Arnold Jurado, Issiah Havens | AS30: TRUE | AU30: Hennadii Stakhurskyi | AV30: 45951.676 | AX30: 46031 | AY30: 46003 | BA30: 46050 | BC30: 46052 | BE30: 46052 | BH30: YES | BI30: 1000 | BO30: MATCH COLOR | BP30: YES | BQ30: Approved | BR30: NO | BT30: NO | BV30: NO | CC30: RTS Titans | CD30: TRUE | CE30: TRUE | CF30: TRUE | CG30: AXYZ Titans Line | DB30: TRUE | DC30: TRUE | DF30: 24051 | DG30: FS | DI30: 56 | DK30: 56 | DL30: 24051-FS231 | DQ30: No Hold | DU30: No Hold | DY30: No Hold | EC30: No Hold | ED30: No Hold | EE30: 8 | EF30: 300 | EQ30: In House | ET30: AXYZ | EU30: AXYZ Titans Line Clean and Brake Fab | EV30: 46002 | EW30: 46003 | EX30: 2 | EZ30: QC Not Requested | FA30: 46051 | FB30: 2 | FC30: David Hasty | FD30: Ramon Estrada, Shane Watson | FE30: 46052 | FG30: Issue Still in Process | FH30: Arnold Jurado - @hstakhurskyi@jwmcd.com @jdavis@jwmcd.com PROGRAMMED | FI30: 1010 | FK30: Marc Ribar | FL30: Hennadii Stakhurskyi | FM30: Denis Usatenko | FN30: 24051-FS56 In-House | FP30: 2026, Week 05
A31: 30 | B31: 24051-FS56C | D31: TN Titans Stadium | E31: 1 Titans Way Nashville, TN 37213 | F31: Marc Ribar | G31: 360.798.3603 | H31: 400 | J31: EVERY CRATE REQUIRES REVEALS | K31: EAST LEVEL 400 COPING | L31: * SKETCHES * CUT LIST * EXTRUSION TIGER SAW LIST * COLOR LABELS | M31: * 2 SETS - INSTALL DRAWINGS * 800 LF - 1 1/8" REVEALS TO MATCH * 200 LF - 1 5/8" REVEALS TO MATCH * 600 pcs - Corner Clips * 1200 pcs﻿ - Color Matched Screws | N31: Q:\Jobs\24051 - TN Titans Stadium\04_Production\24051FS56C | O31: 0.60141167 | P31: 11588 | Q31: 19268 | R31: 149 | S31: 149 | T31: 2 | U31: 1043 | V31: 1000 | W31: 15 | X31: 15:13:12 | Y31: 4mm X 62" X 196", TOB BLACK FR ACM, No Grain | Z31: FR ACM | AA31: 4mm X 62" X 196", TOB BLACK | AB31: No | AE31: 68 | AF31: -56 | AG31: Unassigned | AH31: Denis Usatenko | AI31: Hennadii Stakhurskyi | AJ31: Hennadii Stakhurskyi | AL31: Hennadii Stakhurskyi | AM31: Denis Usatenko | AN31: Hennadii Stakhurskyi | AP31: Arnold Jurado, Issiah Havens | AS31: TRUE | AU31: Hennadii Stakhurskyi | AV31: 45952.367 | AX31: 46034 | AY31: 46003 | BA31: 46051 | BC31: 46055 | BE31: 46055 | BH31: YES | BI31: 1000 | BO31: MATCH COLOR | BP31: YES | BQ31: Approved | BR31: NO | BT31: NO | BV31: NO | CC31: RTS Titans | CD31: TRUE | CE31: TRUE | CF31: TRUE | CG31: AXYZ Titans Line | DB31: TRUE | DC31: TRUE | DF31: 24051 | DG31: FS | DI31: 56C | DK31: 0 | DL31: 24051-FS231 | DQ31: No Hold | DU31: No Hold | DY31: No Hold | EC31: No Hold | ED31: No Hold | EE31: 4 | EF31: 300 | EQ31: In House | ET31: AXYZ | EU31: AXYZ Titans Line Clean and Brake Fab | EV31: 46002 | EW31: 46003 | EX31: 2 | EZ31: QC Not Requested | FA31: 46055 | FB31: 1 | FC31: David Hasty | FD31: Ramon Estrada, Shane Watson | FE31: 46055 | FG31: Issue Still in Process | FH31: Issiah Havens - @hstakhurskyi@jwmcd.com @jdavis@jwmcd.com PROGRAMMED | FI31: 1010 | FK31: Marc Ribar | FL31: Hennadii Stakhurskyi | FM31: Denis Usatenko | FN31: 24051-FS56C In-House | FP31: 2026, Week 06
