Workbook

Sheet Tube Laser
J1: Estimate | R1: Actual | V1: Setup | X1: Results
A2: Date | B2: Job# | C2: Job Type | D2: Part# | E2: Start Time | F2: End Time | G2: Qty Required | H2: Qty Complete | I2: % Complete | J2: PPH | K2: # of men | L2: Total hours | M2: Adj. Total Hours | N2: Batch Hours | O2: Material ID | P2: Adj. Mat. Qty | Q2: Mat. Qty | R2: PPH Act | S2: # of men Act | T2: Total Hours Act | U2: Act. Mat. Qty | V2: Est. Hours | W2: Act. Hours | X2: Efficiency | Y2: Job Efficiency | Z2: Mat. Over/Under | AA2: Total Job Mat O/U | AB2: Notes | AC2: Employee 1 | AD2: Employee 2 | AE2: Employee 3 | AF2: Employee 4
A3: 46120 | B3: 143113 | C3: =IF(tbl_TubeLaser[[#This Row],[Part'#]]="", "Batch", "Part") -> Part | D3: NAS000056961 | E3: 0.2625 | F3: 0.27361111 | G3: 24 | H3: 2 | I3: =tbl_TubeLaser[[#This Row],[Qty Complete]]/tbl_TubeLaser[[#This Row],[Qty Required]] -> 0.083333333 | J3: 45 | K3: 1 | L3: =IF(tbl_TubeLaser[[#This Row],[Job Type]]="Batch",0,tbl_TubeLaser[[#This Row],[Qty Required]]/tbl_TubeLaser[[#This Row],[PPH]]*tbl_TubeLaser[[#This Row],['# of men]]) -> 0.53333333 | M3: =IF(tbl_TubeLaser[[#This Row],[Job Type]]="Batch",tbl_TubeLaser[[#This Row],[Batch Hours]]*tbl_TubeLaser[[#This Row],[% Complete]],tbl_TubeLaser[[#This Row],[Total hours]]*tbl_TubeLaser[[#This Row],[% Complete]]) -> 0.044444444 | O3: RECT TUBE 5 X 2 X 11GA X 303" A36 | P3: =tbl_TubeLaser[[#This Row],[Mat. Qty]]*tbl_TubeLaser[[#This Row],[% Complete]] -> 0.33333333 | Q3: 4 | R3: =IFERROR(tbl_TubeLaser[[#This Row],[Qty Complete]]/tbl_TubeLaser[[#This Row],[Total Hours Act]]*tbl_TubeLaser[[#This Row],['# of men Act]],"") -> 7.5 | S3: 1 | T3: =(MOD(tbl_TubeLaser[[#This Row],[End Time]]-tbl_TubeLaser[[#This Row],[Start Time]],1)*24*tbl_TubeLaser[[#This Row],['# of men Act]])- ( IF(AND(tbl_TubeLaser[[#This Row],[Start Time]]<=Data!$B$2+(Data!$B$2<tbl_TubeLaser[[#This Row],[Start Time]]),tbl_TubeLaser[[#This Row],[Start Time]]+MOD(tbl_TubeLaser[[#This Row],[End Time]]-tbl_TubeLaser[[#This Row],[Start Time]],1)>=Data!$C$2+(Data!$C$2<tbl_TubeLaser[[#This Row],[Start Time]])),0.5*tbl_TubeLaser[[#This Row],['# of men Act]],0) + IF(AND(tbl_TubeLaser[[#This Row],[Start Time]]<=Data!$B$3+(Data!$B$3<tbl_TubeLaser[[#This Row],[Start Time]]),tbl_TubeLaser[[#This Row],[Start Time]]+MOD(tbl_TubeLaser[[#This Row],[End Time]]-tbl_TubeLaser[[#This Row],[Start Time]],1)>=Data!$C$3+(Data!$C$3<tbl_TubeLaser[[#This Row],[Start Time]])),0.5*tbl_TubeLaser[[#This Row],['# of men Act]],0) ) -> 0.26666667 | U3: 1 | V3: 0.51 | W3: 0.23 | X3: =IFERROR((tbl_TubeLaser[[#This Row],[Adj. Total Hours]]+tbl_TubeLaser[[#This Row],[Est. Hours]])/(tbl_TubeLaser[[#This Row],[Total Hours Act]]+tbl_TubeLaser[[#This Row],[Act. Hours]]),"") -> 1.1163311 | Y3: =IF(AND(SUMIFS(tbl_TubeLaser[% Complete],tbl_TubeLaser[Job'#],tbl_TubeLaser[[#This Row],[Job'#]])>=1,COUNTIF(INDEX(tbl_TubeLaser[Job'#],1):tbl_TubeLaser[[#This Row],[Job'#]],tbl_TubeLaser[[#This Row],[Job'#]])=COUNTIF(tbl_TubeLaser[Job'#],tbl_TubeLaser[[#This Row],[Job'#]])),IFERROR((SUMIFS(tbl_TubeLaser[Adj. Total Hours],tbl_TubeLaser[Job'#],tbl_TubeLaser[[#This Row],[Job'#]])+SUMIFS(tbl_TubeLaser[Est. Hours],tbl_TubeLaser[Job'#],tbl_TubeLaser[[#This Row],[Job'#]]))/(SUMIFS(tbl_TubeLaser[Total Hours Act],tbl_TubeLaser[Job'#],tbl_TubeLaser[[#This Row],[Job'#]])+SUMIFS(tbl_TubeLaser[Act. Hours],tbl_TubeLaser[Job'#],tbl_TubeLaser[[#This Row],[Job'#]])),""),"") | Z3: =IFERROR(tbl_TubeLaser[[#This Row],[Act. Mat. Qty]]-tbl_TubeLaser[[#This Row],[Adj. Mat. Qty]],"") -> 0.66666667 | AA3: =IF(AND(SUMIFS(tbl_TubeLaser[% Complete],tbl_TubeLaser[Job'#],tbl_TubeLaser[[#This Row],[Job'#]])>=1,COUNTIF(INDEX(tbl_TubeLaser[Job'#],1):tbl_TubeLaser[[#This Row],[Job'#]],tbl_TubeLaser[[#This Row],[Job'#]])=COUNTIF(tbl_TubeLaser[Job'#],tbl_TubeLaser[[#This Row],[Job'#]])),(SUMIFS(tbl_TubeLaser[Act. Mat. Qty],tbl_TubeLaser[Job'#],tbl_TubeLaser[[#This Row],[Job'#]]))-(SUMIFS(tbl_TubeLaser[Adj. Mat. Qty],tbl_TubeLaser[Job'#],tbl_TubeLaser[[#This Row],[Job'#]])),"") | AC3: Jarett Matlock
A4: 46120 | B4: 152593-1-1 | C4: =IF(tbl_TubeLaser[[#This Row],[Part'#]]="", "Batch", "Part") -> Part | D4: 15024304 | E4: 0.35694444 | F4: 0.47291667 | G4: 30 | H4: 20 | I4: =tbl_TubeLaser[[#This Row],[Qty Complete]]/tbl_TubeLaser[[#This Row],[Qty Required]] -> 0.66666667 | J4: 9 | K4: 1 | L4: 3.33 | M4: =IF(tbl_TubeLaser[[#This Row],[Job Type]]="Batch",tbl_TubeLaser[[#This Row],[Batch Hours]]*tbl_TubeLaser[[#This Row],[% Complete]],tbl_TubeLaser[[#This Row],[Total hours]]*tbl_TubeLaser[[#This Row],[% Complete]]) -> 2.22 | O4: HR ANGLE 2" X 2" X 1/4" X 20' A36 | P4: =tbl_TubeLaser[[#This Row],[Mat. Qty]]*tbl_TubeLaser[[#This Row],[% Complete]] -> 20 | Q4: 30 | R4: =IFERROR(tbl_TubeLaser[[#This Row],[Qty Complete]]/tbl_TubeLaser[[#This Row],[Total Hours Act]]*tbl_TubeLaser[[#This Row],['# of men Act]],"") -> 7.1856287 | S4: 1 | T4: =(MOD(tbl_TubeLaser[[#This Row],[End Time]]-tbl_TubeLaser[[#This Row],[Start Time]],1)*24*tbl_TubeLaser[[#This Row],['# of men Act]])- ( IF(AND(tbl_TubeLaser[[#This Row],[Start Time]]<=Data!$B$2+(Data!$B$2<tbl_TubeLaser[[#This Row],[Start Time]]),tbl_TubeLaser[[#This Row],[Start Time]]+MOD(tbl_TubeLaser[[#This Row],[End Time]]-tbl_TubeLaser[[#This Row],[Start Time]],1)>=Data!$C$2+(Data!$C$2<tbl_TubeLaser[[#This Row],[Start Time]])),0.5*tbl_TubeLaser[[#This Row],['# of men Act]],0) + IF(AND(tbl_TubeLaser[[#This Row],[Start Time]]<=Data!$B$3+(Data!$B$3<tbl_TubeLaser[[#This Row],[Start Time]]),tbl_TubeLaser[[#This Row],[Start Time]]+MOD(tbl_TubeLaser[[#This Row],[End Time]]-tbl_TubeLaser[[#This Row],[Start Time]],1)>=Data!$C$3+(Data!$C$3<tbl_TubeLaser[[#This Row],[Start Time]])),0.5*tbl_TubeLaser[[#This Row],['# of men Act]],0) ) -> 2.7833333 | U4: 20 | V4: 0.5 | W4: 1.97 | X4: =IFERROR((tbl_TubeLaser[[#This Row],[Adj. Total Hours]]+tbl_TubeLaser[[#This Row],[Est. Hours]])/(tbl_TubeLaser[[#This Row],[Total Hours Act]]+tbl_TubeLaser[[#This Row],[Act. Hours]]),"") -> 0.57223001 | Y4: =IF(AND(SUMIFS(tbl_TubeLaser[% Complete],tbl_TubeLaser[Job'#],tbl_TubeLaser[[#This Row],[Job'#]])>=1,COUNTIF(INDEX(tbl_TubeLaser[Job'#],1):tbl_TubeLaser[[#This Row],[Job'#]],tbl_TubeLaser[[#This Row],[Job'#]])=COUNTIF(tbl_TubeLaser[Job'#],tbl_TubeLaser[[#This Row],[Job'#]])),IFERROR((SUMIFS(tbl_TubeLaser[Adj. Total Hours],tbl_TubeLaser[Job'#],tbl_TubeLaser[[#This Row],[Job'#]])+SUMIFS(tbl_TubeLaser[Est. Hours],tbl_TubeLaser[Job'#],tbl_TubeLaser[[#This Row],[Job'#]]))/(SUMIFS(tbl_TubeLaser[Total Hours Act],tbl_TubeLaser[Job'#],tbl_TubeLaser[[#This Row],[Job'#]])+SUMIFS(tbl_TubeLaser[Act. Hours],tbl_TubeLaser[Job'#],tbl_TubeLaser[[#This Row],[Job'#]])),""),"") | Z4: =IFERROR(tbl_TubeLaser[[#This Row],[Act. Mat. Qty]]-tbl_TubeLaser[[#This Row],[Adj. Mat. Qty]],"") -> 0 | AA4: =IF(AND(SUMIFS(tbl_TubeLaser[% Complete],tbl_TubeLaser[Job'#],tbl_TubeLaser[[#This Row],[Job'#]])>=1,COUNTIF(INDEX(tbl_TubeLaser[Job'#],1):tbl_TubeLaser[[#This Row],[Job'#]],tbl_TubeLaser[[#This Row],[Job'#]])=COUNTIF(tbl_TubeLaser[Job'#],tbl_TubeLaser[[#This Row],[Job'#]])),(SUMIFS(tbl_TubeLaser[Act. Mat. Qty],tbl_TubeLaser[Job'#],tbl_TubeLaser[[#This Row],[Job'#]]))-(SUMIFS(tbl_TubeLaser[Adj. Mat. Qty],tbl_TubeLaser[Job'#],tbl_TubeLaser[[#This Row],[Job'#]])),"") | AB4: Issues with hole tolerance. Cody came from meeting and went to programmer to allow keft adjustment then made the adjustment to fix hole size. | AC4: Jarett Matlock
A5: 46120 | B5: 152732-1-1 | C5: =IF(tbl_TubeLaser[[#This Row],[Part'#]]="", "Batch", "Part") -> Part | D5: v2832 | E5: 0.68055556 | F5: 0.68611111 | G5: 60 | H5: 30 | I5: =tbl_TubeLaser[[#This Row],[Qty Complete]]/tbl_TubeLaser[[#This Row],[Qty Required]] -> 0.5 | J5: 60 | K5: 1 | L5: 1 | M5: =IF(tbl_TubeLaser[[#This Row],[Job Type]]="Batch",tbl_TubeLaser[[#This Row],[Batch Hours]]*tbl_TubeLaser[[#This Row],[% Complete]],tbl_TubeLaser[[#This Row],[Total hours]]*tbl_TubeLaser[[#This Row],[% Complete]]) -> 0.5 | O5: C4 X 5.4 CHANNEL 20' | P5: =tbl_TubeLaser[[#This Row],[Mat. Qty]]*tbl_TubeLaser[[#This Row],[% Complete]] -> 1.5 | Q5: 3 | R5: =IFERROR(tbl_TubeLaser[[#This Row],[Qty Complete]]/tbl_TubeLaser[[#This Row],[Total Hours Act]]*tbl_TubeLaser[[#This Row],['# of men Act]],"") -> 225 | S5: 1 | T5: =(MOD(tbl_TubeLaser[[#This Row],[End Time]]-tbl_TubeLaser[[#This Row],[Start Time]],1)*24*tbl_TubeLaser[[#This Row],['# of men Act]])- ( IF(AND(tbl_TubeLaser[[#This Row],[Start Time]]<=Data!$B$2+(Data!$B$2<tbl_TubeLaser[[#This Row],[Start Time]]),tbl_TubeLaser[[#This Row],[Start Time]]+MOD(tbl_TubeLaser[[#This Row],[End Time]]-tbl_TubeLaser[[#This Row],[Start Time]],1)>=Data!$C$2+(Data!$C$2<tbl_TubeLaser[[#This Row],[Start Time]])),0.5*tbl_TubeLaser[[#This Row],['# of men Act]],0) + IF(AND(tbl_TubeLaser[[#This Row],[Start Time]]<=Data!$B$3+(Data!$B$3<tbl_TubeLaser[[#This Row],[Start Time]]),tbl_TubeLaser[[#This Row],[Start Time]]+MOD(tbl_TubeLaser[[#This Row],[End Time]]-tbl_TubeLaser[[#This Row],[Start Time]],1)>=Data!$C$3+(Data!$C$3<tbl_TubeLaser[[#This Row],[Start Time]])),0.5*tbl_TubeLaser[[#This Row],['# of men Act]],0) ) -> 0.13333333 | U5: 2 | V5: 0.5 | W5: 2.8 | X5: =IFERROR((tbl_TubeLaser[[#This Row],[Adj. Total Hours]]+tbl_TubeLaser[[#This Row],[Est. Hours]])/(tbl_TubeLaser[[#This Row],[Total Hours Act]]+tbl_TubeLaser[[#This Row],[Act. Hours]]),"") -> 0.34090909 | Y5: =IF(AND(SUMIFS(tbl_TubeLaser[% Complete],tbl_TubeLaser[Job'#],tbl_TubeLaser[[#This Row],[Job'#]])>=1,COUNTIF(INDEX(tbl_TubeLaser[Job'#],1):tbl_TubeLaser[[#This Row],[Job'#]],tbl_TubeLaser[[#This Row],[Job'#]])=COUNTIF(tbl_TubeLaser[Job'#],tbl_TubeLaser[[#This Row],[Job'#]])),IFERROR((SUMIFS(tbl_TubeLaser[Adj. Total Hours],tbl_TubeLaser[Job'#],tbl_TubeLaser[[#This Row],[Job'#]])+SUMIFS(tbl_TubeLaser[Est. Hours],tbl_TubeLaser[Job'#],tbl_TubeLaser[[#This Row],[Job'#]]))/(SUMIFS(tbl_TubeLaser[Total Hours Act],tbl_TubeLaser[Job'#],tbl_TubeLaser[[#This Row],[Job'#]])+SUMIFS(tbl_TubeLaser[Act. Hours],tbl_TubeLaser[Job'#],tbl_TubeLaser[[#This Row],[Job'#]])),""),"") | Z5: =IFERROR(tbl_TubeLaser[[#This Row],[Act. Mat. Qty]]-tbl_TubeLaser[[#This Row],[Adj. Mat. Qty]],"") -> 0.5 | AA5: =IF(AND(SUMIFS(tbl_TubeLaser[% Complete],tbl_TubeLaser[Job'#],tbl_TubeLaser[[#This Row],[Job'#]])>=1,COUNTIF(INDEX(tbl_TubeLaser[Job'#],1):tbl_TubeLaser[[#This Row],[Job'#]],tbl_TubeLaser[[#This Row],[Job'#]])=COUNTIF(tbl_TubeLaser[Job'#],tbl_TubeLaser[[#This Row],[Job'#]])),(SUMIFS(tbl_TubeLaser[Act. Mat. Qty],tbl_TubeLaser[Job'#],tbl_TubeLaser[[#This Row],[Job'#]]))-(SUMIFS(tbl_TubeLaser[Adj. Mat. Qty],tbl_TubeLaser[Job'#],tbl_TubeLaser[[#This Row],[Job'#]])),"") | AB5: issues with program and tech table. made adjustments no benefit. involved leadership no benefit, troubeshot finally asked programming to make the adjustment. worked but not actually how the machine should be operated for longer periods of time . switching from N2 to O2 | AC5: Jarett Matlock
A6: 46120 | B6: 152739-4-1 | C6: =IF(tbl_TubeLaser[[#This Row],[Part'#]]="", "Batch", "Part") -> Part | D6: 2403141 | E6: 0.30555556 | F6: 0.31875 | G6: 332 | H6: 3 | I6: =tbl_TubeLaser[[#This Row],[Qty Complete]]/tbl_TubeLaser[[#This Row],[Qty Required]] -> 0.0090361446 | J6: 24 | K6: 1 | L6: 13.83 | M6: =IF(tbl_TubeLaser[[#This Row],[Job Type]]="Batch",tbl_TubeLaser[[#This Row],[Batch Hours]]*tbl_TubeLaser[[#This Row],[% Complete]],tbl_TubeLaser[[#This Row],[Total hours]]*tbl_TubeLaser[[#This Row],[% Complete]]) -> 0.12496988 | O6: AL CHANNEL 2.00 X 2.50 X .190 21' LONG -- CUSTOMER SUPPLIED MATERIAL | P6: =tbl_TubeLaser[[#This Row],[Mat. Qty]]*tbl_TubeLaser[[#This Row],[% Complete]] -> 1.5 | Q6: 166 | R6: =IFERROR(tbl_TubeLaser[[#This Row],[Qty Complete]]/tbl_TubeLaser[[#This Row],[Total Hours Act]]*tbl_TubeLaser[[#This Row],['# of men Act]],"") -> 9.4736842 | S6: 1 | T6: =(MOD(tbl_TubeLaser[[#This Row],[End Time]]-tbl_TubeLaser[[#This Row],[Start Time]],1)*24*tbl_TubeLaser[[#This Row],['# of men Act]])- ( IF(AND(tbl_TubeLaser[[#This Row],[Start Time]]<=Data!$B$2+(Data!$B$2<tbl_TubeLaser[[#This Row],[Start Time]]),tbl_TubeLaser[[#This Row],[Start Time]]+MOD(tbl_TubeLaser[[#This Row],[End Time]]-tbl_TubeLaser[[#This Row],[Start Time]],1)>=Data!$C$2+(Data!$C$2<tbl_TubeLaser[[#This Row],[Start Time]])),0.5*tbl_TubeLaser[[#This Row],['# of men Act]],0) + IF(AND(tbl_TubeLaser[[#This Row],[Start Time]]<=Data!$B$3+(Data!$B$3<tbl_TubeLaser[[#This Row],[Start Time]]),tbl_TubeLaser[[#This Row],[Start Time]]+MOD(tbl_TubeLaser[[#This Row],[End Time]]-tbl_TubeLaser[[#This Row],[Start Time]],1)>=Data!$C$3+(Data!$C$3<tbl_TubeLaser[[#This Row],[Start Time]])),0.5*tbl_TubeLaser[[#This Row],['# of men Act]],0) ) -> 0.31666667 | U6: 3 | V6: 0.5 | W6: 0.43 | X6: =IFERROR((tbl_TubeLaser[[#This Row],[Adj. Total Hours]]+tbl_TubeLaser[[#This Row],[Est. Hours]])/(tbl_TubeLaser[[#This Row],[Total Hours Act]]+tbl_TubeLaser[[#This Row],[Act. Hours]]),"") -> 0.83701323 | Y6: =IF(AND(SUMIFS(tbl_TubeLaser[% Complete],tbl_TubeLaser[Job'#],tbl_TubeLaser[[#This Row],[Job'#]])>=1,COUNTIF(INDEX(tbl_TubeLaser[Job'#],1):tbl_TubeLaser[[#This Row],[Job'#]],tbl_TubeLaser[[#This Row],[Job'#]])=COUNTIF(tbl_TubeLaser[Job'#],tbl_TubeLaser[[#This Row],[Job'#]])),IFERROR((SUMIFS(tbl_TubeLaser[Adj. Total Hours],tbl_TubeLaser[Job'#],tbl_TubeLaser[[#This Row],[Job'#]])+SUMIFS(tbl_TubeLaser[Est. Hours],tbl_TubeLaser[Job'#],tbl_TubeLaser[[#This Row],[Job'#]]))/(SUMIFS(tbl_TubeLaser[Total Hours Act],tbl_TubeLaser[Job'#],tbl_TubeLaser[[#This Row],[Job'#]])+SUMIFS(tbl_TubeLaser[Act. Hours],tbl_TubeLaser[Job'#],tbl_TubeLaser[[#This Row],[Job'#]])),""),"") | Z6: =IFERROR(tbl_TubeLaser[[#This Row],[Act. Mat. Qty]]-tbl_TubeLaser[[#This Row],[Adj. Mat. Qty]],"") -> 1.5 | AA6: =IF(AND(SUMIFS(tbl_TubeLaser[% Complete],tbl_TubeLaser[Job'#],tbl_TubeLaser[[#This Row],[Job'#]])>=1,COUNTIF(INDEX(tbl_TubeLaser[Job'#],1):tbl_TubeLaser[[#This Row],[Job'#]],tbl_TubeLaser[[#This Row],[Job'#]])=COUNTIF(tbl_TubeLaser[Job'#],tbl_TubeLaser[[#This Row],[Job'#]])),(SUMIFS(tbl_TubeLaser[Act. Mat. Qty],tbl_TubeLaser[Job'#],tbl_TubeLaser[[#This Row],[Job'#]]))-(SUMIFS(tbl_TubeLaser[Adj. Mat. Qty],tbl_TubeLaser[Job'#],tbl_TubeLaser[[#This Row],[Job'#]])),"") | AB6: I misread the blue print and had to wait for Cody to get out of a meeting to examine the part, ran with part below | AC6: Sterling Caldwell
A7: 46120 | B7: 152739-1-1 | C7: =IF(tbl_TubeLaser[[#This Row],[Part'#]]="", "Batch", "Part") -> Part | D7: 2403130 | E7: 0.30625 | F7: 0.31944444 | G7: 328 | H7: 3 | I7: =tbl_TubeLaser[[#This Row],[Qty Complete]]/tbl_TubeLaser[[#This Row],[Qty Required]] -> 0.0091463415 | J7: 21 | K7: 1 | L7: 15.62 | M7: =IF(tbl_TubeLaser[[#This Row],[Job Type]]="Batch",tbl_TubeLaser[[#This Row],[Batch Hours]]*tbl_TubeLaser[[#This Row],[% Complete]],tbl_TubeLaser[[#This Row],[Total hours]]*tbl_TubeLaser[[#This Row],[% Complete]]) -> 0.14286585 | O7: AL CHANNEL 2.00 X 2.50 X .190 21' LONG -- CUSTOMER SUPPLIED MATERIAL | P7: =tbl_TubeLaser[[#This Row],[Mat. Qty]]*tbl_TubeLaser[[#This Row],[% Complete]] -> 1.5 | Q7: 164 | R7: =IFERROR(tbl_TubeLaser[[#This Row],[Qty Complete]]/tbl_TubeLaser[[#This Row],[Total Hours Act]]*tbl_TubeLaser[[#This Row],['# of men Act]],"") -> 9.4736842 | S7: 1 | T7: =(MOD(tbl_TubeLaser[[#This Row],[End Time]]-tbl_TubeLaser[[#This Row],[Start Time]],1)*24*tbl_TubeLaser[[#This Row],['# of men Act]])- ( IF(AND(tbl_TubeLaser[[#This Row],[Start Time]]<=Data!$B$2+(Data!$B$2<tbl_TubeLaser[[#This Row],[Start Time]]),tbl_TubeLaser[[#This Row],[Start Time]]+MOD(tbl_TubeLaser[[#This Row],[End Time]]-tbl_TubeLaser[[#This Row],[Start Time]],1)>=Data!$C$2+(Data!$C$2<tbl_TubeLaser[[#This Row],[Start Time]])),0.5*tbl_TubeLaser[[#This Row],['# of men Act]],0) + IF(AND(tbl_TubeLaser[[#This Row],[Start Time]]<=Data!$B$3+(Data!$B$3<tbl_TubeLaser[[#This Row],[Start Time]]),tbl_TubeLaser[[#This Row],[Start Time]]+MOD(tbl_TubeLaser[[#This Row],[End Time]]-tbl_TubeLaser[[#This Row],[Start Time]],1)>=Data!$C$3+(Data!$C$3<tbl_TubeLaser[[#This Row],[Start Time]])),0.5*tbl_TubeLaser[[#This Row],['# of men Act]],0) ) -> 0.31666667 | U7: 3 | V7: 0.5 | W7: 0.84 | X7: =IFERROR((tbl_TubeLaser[[#This Row],[Adj. Total Hours]]+tbl_TubeLaser[[#This Row],[Est. Hours]])/(tbl_TubeLaser[[#This Row],[Total Hours Act]]+tbl_TubeLaser[[#This Row],[Act. Hours]]),"") -> 0.5557918 | Y7: =IF(AND(SUMIFS(tbl_TubeLaser[% Complete],tbl_TubeLaser[Job'#],tbl_TubeLaser[[#This Row],[Job'#]])>=1,COUNTIF(INDEX(tbl_TubeLaser[Job'#],1):tbl_TubeLaser[[#This Row],[Job'#]],tbl_TubeLaser[[#This Row],[Job'#]])=COUNTIF(tbl_TubeLaser[Job'#],tbl_TubeLaser[[#This Row],[Job'#]])),IFERROR((SUMIFS(tbl_TubeLaser[Adj. Total Hours],tbl_TubeLaser[Job'#],tbl_TubeLaser[[#This Row],[Job'#]])+SUMIFS(tbl_TubeLaser[Est. Hours],tbl_TubeLaser[Job'#],tbl_TubeLaser[[#This Row],[Job'#]]))/(SUMIFS(tbl_TubeLaser[Total Hours Act],tbl_TubeLaser[Job'#],tbl_TubeLaser[[#This Row],[Job'#]])+SUMIFS(tbl_TubeLaser[Act. Hours],tbl_TubeLaser[Job'#],tbl_TubeLaser[[#This Row],[Job'#]])),""),"") | Z7: =IFERROR(tbl_TubeLaser[[#This Row],[Act. Mat. Qty]]-tbl_TubeLaser[[#This Row],[Adj. Mat. Qty]],"") -> 1.5 | AA7: =IF(AND(SUMIFS(tbl_TubeLaser[% Complete],tbl_TubeLaser[Job'#],tbl_TubeLaser[[#This Row],[Job'#]])>=1,COUNTIF(INDEX(tbl_TubeLaser[Job'#],1):tbl_TubeLaser[[#This Row],[Job'#]],tbl_TubeLaser[[#This Row],[Job'#]])=COUNTIF(tbl_TubeLaser[Job'#],tbl_TubeLaser[[#This Row],[Job'#]])),(SUMIFS(tbl_TubeLaser[Act. Mat. Qty],tbl_TubeLaser[Job'#],tbl_TubeLaser[[#This Row],[Job'#]]))-(SUMIFS(tbl_TubeLaser[Adj. Mat. Qty],tbl_TubeLaser[Job'#],tbl_TubeLaser[[#This Row],[Job'#]])),"") | AB7: Ran with job above then pulled off due to hot parts of other jobs | AC7: Sterling Caldwell
A8: 46120 | B8: 152759-1-1 | C8: =IF(tbl_TubeLaser[[#This Row],[Part'#]]="", "Batch", "Part") -> Part | D8: 13871--Upper Pipe | E8: 0.33055556 | F8: 0.38263889 | G8: 28 | H8: 28 | I8: =tbl_TubeLaser[[#This Row],[Qty Complete]]/tbl_TubeLaser[[#This Row],[Qty Required]] -> 1 | J8: 36 | K8: 1 | L8: 0.78 | M8: =IF(tbl_TubeLaser[[#This Row],[Job Type]]="Batch",tbl_TubeLaser[[#This Row],[Batch Hours]]*tbl_TubeLaser[[#This Row],[% Complete]],tbl_TubeLaser[[#This Row],[Total hours]]*tbl_TubeLaser[[#This Row],[% Complete]]) -> 0.78 | O8: HR ROUND TUBE 4" OD X 0.188" WALL X 20' DOM -- Customer Supplied Material | P8: =tbl_TubeLaser[[#This Row],[Mat. Qty]]*tbl_TubeLaser[[#This Row],[% Complete]] -> 3 | Q8: 3 | R8: =IFERROR(tbl_TubeLaser[[#This Row],[Qty Complete]]/tbl_TubeLaser[[#This Row],[Total Hours Act]]*tbl_TubeLaser[[#This Row],['# of men Act]],"") -> 22.4 | S8: 1 | T8: =(MOD(tbl_TubeLaser[[#This Row],[End Time]]-tbl_TubeLaser[[#This Row],[Start Time]],1)*24*tbl_TubeLaser[[#This Row],['# of men Act]])- ( IF(AND(tbl_TubeLaser[[#This Row],[Start Time]]<=Data!$B$2+(Data!$B$2<tbl_TubeLaser[[#This Row],[Start Time]]),tbl_TubeLaser[[#This Row],[Start Time]]+MOD(tbl_TubeLaser[[#This Row],[End Time]]-tbl_TubeLaser[[#This Row],[Start Time]],1)>=Data!$C$2+(Data!$C$2<tbl_TubeLaser[[#This Row],[Start Time]])),0.5*tbl_TubeLaser[[#This Row],['# of men Act]],0) + IF(AND(tbl_TubeLaser[[#This Row],[Start Time]]<=Data!$B$3+(Data!$B$3<tbl_TubeLaser[[#This Row],[Start Time]]),tbl_TubeLaser[[#This Row],[Start Time]]+MOD(tbl_TubeLaser[[#This Row],[End Time]]-tbl_TubeLaser[[#This Row],[Start Time]],1)>=Data!$C$3+(Data!$C$3<tbl_TubeLaser[[#This Row],[Start Time]])),0.5*tbl_TubeLaser[[#This Row],['# of men Act]],0) ) -> 1.25 | U8: 3 | V8: 0.5 | W8: 0.27 | X8: =IFERROR((tbl_TubeLaser[[#This Row],[Adj. Total Hours]]+tbl_TubeLaser[[#This Row],[Est. Hours]])/(tbl_TubeLaser[[#This Row],[Total Hours Act]]+tbl_TubeLaser[[#This Row],[Act. Hours]]),"") -> 0.84210526 | Y8: =IF(AND(SUMIFS(tbl_TubeLaser[% Complete],tbl_TubeLaser[Job'#],tbl_TubeLaser[[#This Row],[Job'#]])>=1,COUNTIF(INDEX(tbl_TubeLaser[Job'#],1):tbl_TubeLaser[[#This Row],[Job'#]],tbl_TubeLaser[[#This Row],[Job'#]])=COUNTIF(tbl_TubeLaser[Job'#],tbl_TubeLaser[[#This Row],[Job'#]])),IFERROR((SUMIFS(tbl_TubeLaser[Adj. Total Hours],tbl_TubeLaser[Job'#],tbl_TubeLaser[[#This Row],[Job'#]])+SUMIFS(tbl_TubeLaser[Est. Hours],tbl_TubeLaser[Job'#],tbl_TubeLaser[[#This Row],[Job'#]]))/(SUMIFS(tbl_TubeLaser[Total Hours Act],tbl_TubeLaser[Job'#],tbl_TubeLaser[[#This Row],[Job'#]])+SUMIFS(tbl_TubeLaser[Act. Hours],tbl_TubeLaser[Job'#],tbl_TubeLaser[[#This Row],[Job'#]])),""),"") -> 0.84210526 | Z8: =IFERROR(tbl_TubeLaser[[#This Row],[Act. Mat. Qty]]-tbl_TubeLaser[[#This Row],[Adj. Mat. Qty]],"") -> 0 | AA8: =IF(AND(SUMIFS(tbl_TubeLaser[% Complete],tbl_TubeLaser[Job'#],tbl_TubeLaser[[#This Row],[Job'#]])>=1,COUNTIF(INDEX(tbl_TubeLaser[Job'#],1):tbl_TubeLaser[[#This Row],[Job'#]],tbl_TubeLaser[[#This Row],[Job'#]])=COUNTIF(tbl_TubeLaser[Job'#],tbl_TubeLaser[[#This Row],[Job'#]])),(SUMIFS(tbl_TubeLaser[Act. Mat. Qty],tbl_TubeLaser[Job'#],tbl_TubeLaser[[#This Row],[Job'#]]))-(SUMIFS(tbl_TubeLaser[Adj. Mat. Qty],tbl_TubeLaser[Job'#],tbl_TubeLaser[[#This Row],[Job'#]])),"") -> 0 | AB8: Pallet needed added to in order to hold parts but nail gun was missing battery then broken just hand nailed it. | AC8: Sterling Caldwell
A9: 46120 | B9: 152731-1-1 | C9: =IF(tbl_TubeLaser[[#This Row],[Part'#]]="", "Batch", "Part") -> Part | D9: 033472-009-00820DD4 | E9: 0.40833333 | F9: 0.41388889 | G9: 8 | H9: 2 | I9: =tbl_TubeLaser[[#This Row],[Qty Complete]]/tbl_TubeLaser[[#This Row],[Qty Required]] -> 0.25 | J9: 18 | K9: 1 | L9: 0.44 | M9: =IF(tbl_TubeLaser[[#This Row],[Job Type]]="Batch",tbl_TubeLaser[[#This Row],[Batch Hours]]*tbl_TubeLaser[[#This Row],[% Complete]],tbl_TubeLaser[[#This Row],[Total hours]]*tbl_TubeLaser[[#This Row],[% Complete]]) -> 0.11 | O9: RT211214GA-24 | P9: =tbl_TubeLaser[[#This Row],[Mat. Qty]]*tbl_TubeLaser[[#This Row],[% Complete]] -> 0.25 | Q9: 1 | R9: =IFERROR(tbl_TubeLaser[[#This Row],[Qty Complete]]/tbl_TubeLaser[[#This Row],[Total Hours Act]]*tbl_TubeLaser[[#This Row],['# of men Act]],"") -> 15 | S9: 1 | T9: =(MOD(tbl_TubeLaser[[#This Row],[End Time]]-tbl_TubeLaser[[#This Row],[Start Time]],1)*24*tbl_TubeLaser[[#This Row],['# of men Act]])- ( IF(AND(tbl_TubeLaser[[#This Row],[Start Time]]<=Data!$B$2+(Data!$B$2<tbl_TubeLaser[[#This Row],[Start Time]]),tbl_TubeLaser[[#This Row],[Start Time]]+MOD(tbl_TubeLaser[[#This Row],[End Time]]-tbl_TubeLaser[[#This Row],[Start Time]],1)>=Data!$C$2+(Data!$C$2<tbl_TubeLaser[[#This Row],[Start Time]])),0.5*tbl_TubeLaser[[#This Row],['# of men Act]],0) + IF(AND(tbl_TubeLaser[[#This Row],[Start Time]]<=Data!$B$3+(Data!$B$3<tbl_TubeLaser[[#This Row],[Start Time]]),tbl_TubeLaser[[#This Row],[Start Time]]+MOD(tbl_TubeLaser[[#This Row],[End Time]]-tbl_TubeLaser[[#This Row],[Start Time]],1)>=Data!$C$3+(Data!$C$3<tbl_TubeLaser[[#This Row],[Start Time]])),0.5*tbl_TubeLaser[[#This Row],['# of men Act]],0) ) -> 0.13333333 | U9: 1 | V9: 0.5 | W9: 0.6 | X9: =IFERROR((tbl_TubeLaser[[#This Row],[Adj. Total Hours]]+tbl_TubeLaser[[#This Row],[Est. Hours]])/(tbl_TubeLaser[[#This Row],[Total Hours Act]]+tbl_TubeLaser[[#This Row],[Act. Hours]]),"") -> 0.83181818 | Y9: =IF(AND(SUMIFS(tbl_TubeLaser[% Complete],tbl_TubeLaser[Job'#],tbl_TubeLaser[[#This Row],[Job'#]])>=1,COUNTIF(INDEX(tbl_TubeLaser[Job'#],1):tbl_TubeLaser[[#This Row],[Job'#]],tbl_TubeLaser[[#This Row],[Job'#]])=COUNTIF(tbl_TubeLaser[Job'#],tbl_TubeLaser[[#This Row],[Job'#]])),IFERROR((SUMIFS(tbl_TubeLaser[Adj. Total Hours],tbl_TubeLaser[Job'#],tbl_TubeLaser[[#This Row],[Job'#]])+SUMIFS(tbl_TubeLaser[Est. Hours],tbl_TubeLaser[Job'#],tbl_TubeLaser[[#This Row],[Job'#]]))/(SUMIFS(tbl_TubeLaser[Total Hours Act],tbl_TubeLaser[Job'#],tbl_TubeLaser[[#This Row],[Job'#]])+SUMIFS(tbl_TubeLaser[Act. Hours],tbl_TubeLaser[Job'#],tbl_TubeLaser[[#This Row],[Job'#]])),""),"") | Z9: =IFERROR(tbl_TubeLaser[[#This Row],[Act. Mat. Qty]]-tbl_TubeLaser[[#This Row],[Adj. Mat. Qty]],"") -> 0.75 | AA9: =IF(AND(SUMIFS(tbl_TubeLaser[% Complete],tbl_TubeLaser[Job'#],tbl_TubeLaser[[#This Row],[Job'#]])>=1,COUNTIF(INDEX(tbl_TubeLaser[Job'#],1):tbl_TubeLaser[[#This Row],[Job'#]],tbl_TubeLaser[[#This Row],[Job'#]])=COUNTIF(tbl_TubeLaser[Job'#],tbl_TubeLaser[[#This Row],[Job'#]])),(SUMIFS(tbl_TubeLaser[Act. Mat. Qty],tbl_TubeLaser[Job'#],tbl_TubeLaser[[#This Row],[Job'#]]))-(SUMIFS(tbl_TubeLaser[Adj. Mat. Qty],tbl_TubeLaser[Job'#],tbl_TubeLaser[[#This Row],[Job'#]])),"") | AB9: Job name on traveler didn't match lead went to programming to get issue sorted | AC9: Sterling Caldwell
A10: 46120 | B10: 152690-1-1 | C10: =IF(tbl_TubeLaser[[#This Row],[Part'#]]="", "Batch", "Part") -> Part | D10: 300032 | E10: 0.47847222 | F10: 0.55416667 | G10: 200 | H10: 49 | I10: =tbl_TubeLaser[[#This Row],[Qty Complete]]/tbl_TubeLaser[[#This Row],[Qty Required]] -> 0.245 | J10: 19 | K10: 1 | L10: 10.53 | M10: =IF(tbl_TubeLaser[[#This Row],[Job Type]]="Batch",tbl_TubeLaser[[#This Row],[Batch Hours]]*tbl_TubeLaser[[#This Row],[% Complete]],tbl_TubeLaser[[#This Row],[Total hours]]*tbl_TubeLaser[[#This Row],[% Complete]]) -> 2.57985 | O10: 5 X 5 X 1/2 20 A36 ANGLE | P10: =tbl_TubeLaser[[#This Row],[Mat. Qty]]*tbl_TubeLaser[[#This Row],[% Complete]] -> 2.94 | Q10: 12 | R10: =IFERROR(tbl_TubeLaser[[#This Row],[Qty Complete]]/tbl_TubeLaser[[#This Row],[Total Hours Act]]*tbl_TubeLaser[[#This Row],['# of men Act]],"") -> 37.21519 | S10: 1 | T10: =(MOD(tbl_TubeLaser[[#This Row],[End Time]]-tbl_TubeLaser[[#This Row],[Start Time]],1)*24*tbl_TubeLaser[[#This Row],['# of men Act]])- ( IF(AND(tbl_TubeLaser[[#This Row],[Start Time]]<=Data!$B$2+(Data!$B$2<tbl_TubeLaser[[#This Row],[Start Time]]),tbl_TubeLaser[[#This Row],[Start Time]]+MOD(tbl_TubeLaser[[#This Row],[End Time]]-tbl_TubeLaser[[#This Row],[Start Time]],1)>=Data!$C$2+(Data!$C$2<tbl_TubeLaser[[#This Row],[Start Time]])),0.5*tbl_TubeLaser[[#This Row],['# of men Act]],0) + IF(AND(tbl_TubeLaser[[#This Row],[Start Time]]<=Data!$B$3+(Data!$B$3<tbl_TubeLaser[[#This Row],[Start Time]]),tbl_TubeLaser[[#This Row],[Start Time]]+MOD(tbl_TubeLaser[[#This Row],[End Time]]-tbl_TubeLaser[[#This Row],[Start Time]],1)>=Data!$C$3+(Data!$C$3<tbl_TubeLaser[[#This Row],[Start Time]])),0.5*tbl_TubeLaser[[#This Row],['# of men Act]],0) ) -> 1.3166667 | U10: 3 | V10: 0.5 | W10: 1.53 | X10: =IFERROR((tbl_TubeLaser[[#This Row],[Adj. Total Hours]]+tbl_TubeLaser[[#This Row],[Est. Hours]])/(tbl_TubeLaser[[#This Row],[Total Hours Act]]+tbl_TubeLaser[[#This Row],[Act. Hours]]),"") -> 1.0819145 | Y10: =IF(AND(SUMIFS(tbl_TubeLaser[% Complete],tbl_TubeLaser[Job'#],tbl_TubeLaser[[#This Row],[Job'#]])>=1,COUNTIF(INDEX(tbl_TubeLaser[Job'#],1):tbl_TubeLaser[[#This Row],[Job'#]],tbl_TubeLaser[[#This Row],[Job'#]])=COUNTIF(tbl_TubeLaser[Job'#],tbl_TubeLaser[[#This Row],[Job'#]])),IFERROR((SUMIFS(tbl_TubeLaser[Adj. Total Hours],tbl_TubeLaser[Job'#],tbl_TubeLaser[[#This Row],[Job'#]])+SUMIFS(tbl_TubeLaser[Est. Hours],tbl_TubeLaser[Job'#],tbl_TubeLaser[[#This Row],[Job'#]]))/(SUMIFS(tbl_TubeLaser[Total Hours Act],tbl_TubeLaser[Job'#],tbl_TubeLaser[[#This Row],[Job'#]])+SUMIFS(tbl_TubeLaser[Act. Hours],tbl_TubeLaser[Job'#],tbl_TubeLaser[[#This Row],[Job'#]])),""),"") | Z10: =IFERROR(tbl_TubeLaser[[#This Row],[Act. Mat. Qty]]-tbl_TubeLaser[[#This Row],[Adj. Mat. Qty]],"") -> 0.06 | AA10: =IF(AND(SUMIFS(tbl_TubeLaser[% Complete],tbl_TubeLaser[Job'#],tbl_TubeLaser[[#This Row],[Job'#]])>=1,COUNTIF(INDEX(tbl_TubeLaser[Job'#],1):tbl_TubeLaser[[#This Row],[Job'#]],tbl_TubeLaser[[#This Row],[Job'#]])=COUNTIF(tbl_TubeLaser[Job'#],tbl_TubeLaser[[#This Row],[Job'#]])),(SUMIFS(tbl_TubeLaser[Act. Mat. Qty],tbl_TubeLaser[Job'#],tbl_TubeLaser[[#This Row],[Job'#]]))-(SUMIFS(tbl_TubeLaser[Adj. Mat. Qty],tbl_TubeLaser[Job'#],tbl_TubeLaser[[#This Row],[Job'#]])),"") | AB10: Had to manually load the laser with forklift due to loader being down and not having a crane on the 20' tube laser | AC10: Sterling Caldwell
A11: 46121 | B11: 152739-4-1 | C11: =IF(tbl_TubeLaser[[#This Row],[Part'#]]="", "Batch", "Part") -> Part | D11: 2403141 | E11: 0.22916667 | F11: 0.34375 | G11: 332 | H11: 80 | I11: =tbl_TubeLaser[[#This Row],[Qty Complete]]/tbl_TubeLaser[[#This Row],[Qty Required]] -> 0.24096386 | J11: 24 | K11: 1 | L11: =IF(tbl_TubeLaser[[#This Row],[Job Type]]="Batch",0,tbl_TubeLaser[[#This Row],[Qty Required]]/tbl_TubeLaser[[#This Row],[PPH]]*tbl_TubeLaser[[#This Row],['# of men]]) -> 13.833333 | M11: =IF(tbl_TubeLaser[[#This Row],[Job Type]]="Batch",tbl_TubeLaser[[#This Row],[Batch Hours]]*tbl_TubeLaser[[#This Row],[% Complete]],tbl_TubeLaser[[#This Row],[Total hours]]*tbl_TubeLaser[[#This Row],[% Complete]]) -> 3.3333333 | O11: CSM-ACH2212190-21 | P11: =tbl_TubeLaser[[#This Row],[Mat. Qty]]*tbl_TubeLaser[[#This Row],[% Complete]] -> 9.6385542 | Q11: 40 | R11: =IFERROR(tbl_TubeLaser[[#This Row],[Qty Complete]]/tbl_TubeLaser[[#This Row],[Total Hours Act]]*tbl_TubeLaser[[#This Row],['# of men Act]],"") -> 29.090909 | S11: 1 | T11: =(MOD(tbl_TubeLaser[[#This Row],[End Time]]-tbl_TubeLaser[[#This Row],[Start Time]],1)*24*tbl_TubeLaser[[#This Row],['# of men Act]])- ( IF(AND(tbl_TubeLaser[[#This Row],[Start Time]]<=Data!$B$2+(Data!$B$2<tbl_TubeLaser[[#This Row],[Start Time]]),tbl_TubeLaser[[#This Row],[Start Time]]+MOD(tbl_TubeLaser[[#This Row],[End Time]]-tbl_TubeLaser[[#This Row],[Start Time]],1)>=Data!$C$2+(Data!$C$2<tbl_TubeLaser[[#This Row],[Start Time]])),0.5*tbl_TubeLaser[[#This Row],['# of men Act]],0) + IF(AND(tbl_TubeLaser[[#This Row],[Start Time]]<=Data!$B$3+(Data!$B$3<tbl_TubeLaser[[#This Row],[Start Time]]),tbl_TubeLaser[[#This Row],[Start Time]]+MOD(tbl_TubeLaser[[#This Row],[End Time]]-tbl_TubeLaser[[#This Row],[Start Time]],1)>=Data!$C$3+(Data!$C$3<tbl_TubeLaser[[#This Row],[Start Time]])),0.5*tbl_TubeLaser[[#This Row],['# of men Act]],0) ) -> 2.75 | U11: 166 | V11: 0.5 | W11: 0.32 | X11: =IFERROR((tbl_TubeLaser[[#This Row],[Adj. Total Hours]]+tbl_TubeLaser[[#This Row],[Est. Hours]])/(tbl_TubeLaser[[#This Row],[Total Hours Act]]+tbl_TubeLaser[[#This Row],[Act. Hours]]),"") -> 1.2486428 | Y11: =IF(AND(SUMIFS(tbl_TubeLaser[% Complete],tbl_TubeLaser[Job'#],tbl_TubeLaser[[#This Row],[Job'#]])>=1,COUNTIF(INDEX(tbl_TubeLaser[Job'#],1):tbl_TubeLaser[[#This Row],[Job'#]],tbl_TubeLaser[[#This Row],[Job'#]])=COUNTIF(tbl_TubeLaser[Job'#],tbl_TubeLaser[[#This Row],[Job'#]])),IFERROR((SUMIFS(tbl_TubeLaser[Adj. Total Hours],tbl_TubeLaser[Job'#],tbl_TubeLaser[[#This Row],[Job'#]])+SUMIFS(tbl_TubeLaser[Est. Hours],tbl_TubeLaser[Job'#],tbl_TubeLaser[[#This Row],[Job'#]]))/(SUMIFS(tbl_TubeLaser[Total Hours Act],tbl_TubeLaser[Job'#],tbl_TubeLaser[[#This Row],[Job'#]])+SUMIFS(tbl_TubeLaser[Act. Hours],tbl_TubeLaser[Job'#],tbl_TubeLaser[[#This Row],[Job'#]])),""),"") | Z11: =IFERROR(tbl_TubeLaser[[#This Row],[Act. Mat. Qty]]-tbl_TubeLaser[[#This Row],[Adj. Mat. Qty]],"") -> 156.36145 | AA11: =IF(AND(SUMIFS(tbl_TubeLaser[% Complete],tbl_TubeLaser[Job'#],tbl_TubeLaser[[#This Row],[Job'#]])>=1,COUNTIF(INDEX(tbl_TubeLaser[Job'#],1):tbl_TubeLaser[[#This Row],[Job'#]],tbl_TubeLaser[[#This Row],[Job'#]])=COUNTIF(tbl_TubeLaser[Job'#],tbl_TubeLaser[[#This Row],[Job'#]])),(SUMIFS(tbl_TubeLaser[Act. Mat. Qty],tbl_TubeLaser[Job'#],tbl_TubeLaser[[#This Row],[Job'#]]))-(SUMIFS(tbl_TubeLaser[Adj. Mat. Qty],tbl_TubeLaser[Job'#],tbl_TubeLaser[[#This Row],[Job'#]])),"") | AC11: Jarett Matlock
A12: 46121 | B12: 143036 | C12: =IF(tbl_TubeLaser[[#This Row],[Part'#]]="", "Batch", "Part") -> Part | D12: NAS000055513 | E12: 0.35694444 | F12: 0.41319444 | G12: 255 | H12: 47 | I12: =tbl_TubeLaser[[#This Row],[Qty Complete]]/tbl_TubeLaser[[#This Row],[Qty Required]] -> 0.18431373 | J12: 30 | K12: 1 | L12: =IF(tbl_TubeLaser[[#This Row],[Job Type]]="Batch",0,tbl_TubeLaser[[#This Row],[Qty Required]]/tbl_TubeLaser[[#This Row],[PPH]]*tbl_TubeLaser[[#This Row],['# of men]]) -> 8.5 | M12: =IF(tbl_TubeLaser[[#This Row],[Job Type]]="Batch",tbl_TubeLaser[[#This Row],[Batch Hours]]*tbl_TubeLaser[[#This Row],[% Complete]],tbl_TubeLaser[[#This Row],[Total hours]]*tbl_TubeLaser[[#This Row],[% Complete]]) -> 1.5666667 | O12: RT4211GA-303 | P12: =tbl_TubeLaser[[#This Row],[Mat. Qty]]*tbl_TubeLaser[[#This Row],[% Complete]] -> 23.592157 | Q12: 128 | R12: =IFERROR(tbl_TubeLaser[[#This Row],[Qty Complete]]/tbl_TubeLaser[[#This Row],[Total Hours Act]]*tbl_TubeLaser[[#This Row],['# of men Act]],"") -> 34.814815 | S12: 1 | T12: =(MOD(tbl_TubeLaser[[#This Row],[End Time]]-tbl_TubeLaser[[#This Row],[Start Time]],1)*24*tbl_TubeLaser[[#This Row],['# of men Act]])- ( IF(AND(tbl_TubeLaser[[#This Row],[Start Time]]<=Data!$B$2+(Data!$B$2<tbl_TubeLaser[[#This Row],[Start Time]]),tbl_TubeLaser[[#This Row],[Start Time]]+MOD(tbl_TubeLaser[[#This Row],[End Time]]-tbl_TubeLaser[[#This Row],[Start Time]],1)>=Data!$C$2+(Data!$C$2<tbl_TubeLaser[[#This Row],[Start Time]])),0.5*tbl_TubeLaser[[#This Row],['# of men Act]],0) + IF(AND(tbl_TubeLaser[[#This Row],[Start Time]]<=Data!$B$3+(Data!$B$3<tbl_TubeLaser[[#This Row],[Start Time]]),tbl_TubeLaser[[#This Row],[Start Time]]+MOD(tbl_TubeLaser[[#This Row],[End Time]]-tbl_TubeLaser[[#This Row],[Start Time]],1)>=Data!$C$3+(Data!$C$3<tbl_TubeLaser[[#This Row],[Start Time]])),0.5*tbl_TubeLaser[[#This Row],['# of men Act]],0) ) -> 1.35 | U12: 24 | V12: 0.51 | W12: 3.15 | X12: =IFERROR((tbl_TubeLaser[[#This Row],[Adj. Total Hours]]+tbl_TubeLaser[[#This Row],[Est. Hours]])/(tbl_TubeLaser[[#This Row],[Total Hours Act]]+tbl_TubeLaser[[#This Row],[Act. Hours]]),"") -> 0.46148148 | Y12: =IF(AND(SUMIFS(tbl_TubeLaser[% Complete],tbl_TubeLaser[Job'#],tbl_TubeLaser[[#This Row],[Job'#]])>=1,COUNTIF(INDEX(tbl_TubeLaser[Job'#],1):tbl_TubeLaser[[#This Row],[Job'#]],tbl_TubeLaser[[#This Row],[Job'#]])=COUNTIF(tbl_TubeLaser[Job'#],tbl_TubeLaser[[#This Row],[Job'#]])),IFERROR((SUMIFS(tbl_TubeLaser[Adj. Total Hours],tbl_TubeLaser[Job'#],tbl_TubeLaser[[#This Row],[Job'#]])+SUMIFS(tbl_TubeLaser[Est. Hours],tbl_TubeLaser[Job'#],tbl_TubeLaser[[#This Row],[Job'#]]))/(SUMIFS(tbl_TubeLaser[Total Hours Act],tbl_TubeLaser[Job'#],tbl_TubeLaser[[#This Row],[Job'#]])+SUMIFS(tbl_TubeLaser[Act. Hours],tbl_TubeLaser[Job'#],tbl_TubeLaser[[#This Row],[Job'#]])),""),"") | Z12: =IFERROR(tbl_TubeLaser[[#This Row],[Act. Mat. Qty]]-tbl_TubeLaser[[#This Row],[Adj. Mat. Qty]],"") -> 0.40784314 | AA12: =IF(AND(SUMIFS(tbl_TubeLaser[% Complete],tbl_TubeLaser[Job'#],tbl_TubeLaser[[#This Row],[Job'#]])>=1,COUNTIF(INDEX(tbl_TubeLaser[Job'#],1):tbl_TubeLaser[[#This Row],[Job'#]],tbl_TubeLaser[[#This Row],[Job'#]])=COUNTIF(tbl_TubeLaser[Job'#],tbl_TubeLaser[[#This Row],[Job'#]])),(SUMIFS(tbl_TubeLaser[Act. Mat. Qty],tbl_TubeLaser[Job'#],tbl_TubeLaser[[#This Row],[Job'#]]))-(SUMIFS(tbl_TubeLaser[Adj. Mat. Qty],tbl_TubeLaser[Job'#],tbl_TubeLaser[[#This Row],[Job'#]])),"") | AB12: Issues with waste conveyor belt worked on for some time operator did not clock out i've told him previously will get this dealt with monday. | AC12: Jarett Matlock
A13: 46121 | B13: 143200 | C13: =IF(tbl_TubeLaser[[#This Row],[Part'#]]="", "Batch", "Part") -> Batch | E13: 0.46041667 | F13: 0.59930556 | G13: 48 | H13: 48 | I13: =tbl_TubeLaser[[#This Row],[Qty Complete]]/tbl_TubeLaser[[#This Row],[Qty Required]] -> 1 | J13: 6 | K13: 1 | L13: =IF(tbl_TubeLaser[[#This Row],[Job Type]]="Batch",0,tbl_TubeLaser[[#This Row],[Qty Required]]/tbl_TubeLaser[[#This Row],[PPH]]*tbl_TubeLaser[[#This Row],['# of men]]) -> 0 | M13: =IF(tbl_TubeLaser[[#This Row],[Job Type]]="Batch",tbl_TubeLaser[[#This Row],[Batch Hours]]*tbl_TubeLaser[[#This Row],[% Complete]],tbl_TubeLaser[[#This Row],[Total hours]]*tbl_TubeLaser[[#This Row],[% Complete]]) -> 8 | N13: 8 | O13: RT5211GA-330 | P13: =tbl_TubeLaser[[#This Row],[Mat. Qty]]*tbl_TubeLaser[[#This Row],[% Complete]] -> 24 | Q13: 24 | R13: =IFERROR(tbl_TubeLaser[[#This Row],[Qty Complete]]/tbl_TubeLaser[[#This Row],[Total Hours Act]]*tbl_TubeLaser[[#This Row],['# of men Act]],"") -> 16.941176 | S13: 1 | T13: =(MOD(tbl_TubeLaser[[#This Row],[End Time]]-tbl_TubeLaser[[#This Row],[Start Time]],1)*24*tbl_TubeLaser[[#This Row],['# of men Act]])- ( IF(AND(tbl_TubeLaser[[#This Row],[Start Time]]<=Data!$B$2+(Data!$B$2<tbl_TubeLaser[[#This Row],[Start Time]]),tbl_TubeLaser[[#This Row],[Start Time]]+MOD(tbl_TubeLaser[[#This Row],[End Time]]-tbl_TubeLaser[[#This Row],[Start Time]],1)>=Data!$C$2+(Data!$C$2<tbl_TubeLaser[[#This Row],[Start Time]])),0.5*tbl_TubeLaser[[#This Row],['# of men Act]],0) + IF(AND(tbl_TubeLaser[[#This Row],[Start Time]]<=Data!$B$3+(Data!$B$3<tbl_TubeLaser[[#This Row],[Start Time]]),tbl_TubeLaser[[#This Row],[Start Time]]+MOD(tbl_TubeLaser[[#This Row],[End Time]]-tbl_TubeLaser[[#This Row],[Start Time]],1)>=Data!$C$3+(Data!$C$3<tbl_TubeLaser[[#This Row],[Start Time]])),0.5*tbl_TubeLaser[[#This Row],['# of men Act]],0) ) -> 2.8333333 | U13: 24 | V13: 0.5 | W13: 1.13 | X13: =IFERROR((tbl_TubeLaser[[#This Row],[Adj. Total Hours]]+tbl_TubeLaser[[#This Row],[Est. Hours]])/(tbl_TubeLaser[[#This Row],[Total Hours Act]]+tbl_TubeLaser[[#This Row],[Act. Hours]]),"") -> 2.1446594 | Y13: =IF(AND(SUMIFS(tbl_TubeLaser[% Complete],tbl_TubeLaser[Job'#],tbl_TubeLaser[[#This Row],[Job'#]])>=1,COUNTIF(INDEX(tbl_TubeLaser[Job'#],1):tbl_TubeLaser[[#This Row],[Job'#]],tbl_TubeLaser[[#This Row],[Job'#]])=COUNTIF(tbl_TubeLaser[Job'#],tbl_TubeLaser[[#This Row],[Job'#]])),IFERROR((SUMIFS(tbl_TubeLaser[Adj. Total Hours],tbl_TubeLaser[Job'#],tbl_TubeLaser[[#This Row],[Job'#]])+SUMIFS(tbl_TubeLaser[Est. Hours],tbl_TubeLaser[Job'#],tbl_TubeLaser[[#This Row],[Job'#]]))/(SUMIFS(tbl_TubeLaser[Total Hours Act],tbl_TubeLaser[Job'#],tbl_TubeLaser[[#This Row],[Job'#]])+SUMIFS(tbl_TubeLaser[Act. Hours],tbl_TubeLaser[Job'#],tbl_TubeLaser[[#This Row],[Job'#]])),""),"") -> 2.1446594 | Z13: =IFERROR(tbl_TubeLaser[[#This Row],[Act. Mat. Qty]]-tbl_TubeLaser[[#This Row],[Adj. Mat. Qty]],"") -> 0 | AA13: =IF(AND(SUMIFS(tbl_TubeLaser[% Complete],tbl_TubeLaser[Job'#],tbl_TubeLaser[[#This Row],[Job'#]])>=1,COUNTIF(INDEX(tbl_TubeLaser[Job'#],1):tbl_TubeLaser[[#This Row],[Job'#]],tbl_TubeLaser[[#This Row],[Job'#]])=COUNTIF(tbl_TubeLaser[Job'#],tbl_TubeLaser[[#This Row],[Job'#]])),(SUMIFS(tbl_TubeLaser[Act. Mat. Qty],tbl_TubeLaser[Job'#],tbl_TubeLaser[[#This Row],[Job'#]]))-(SUMIFS(tbl_TubeLaser[Adj. Mat. Qty],tbl_TubeLaser[Job'#],tbl_TubeLaser[[#This Row],[Job'#]])),"") -> 0 | AC13: Jarett Matlock
A14: 46121 | B14: 152787-1-1 | C14: =IF(tbl_TubeLaser[[#This Row],[Part'#]]="", "Batch", "Part") -> Part | D14: 11101EA1 | E14: 0.70555556 | F14: 0.98611111 | G14: 280 | H14: 280 | I14: =tbl_TubeLaser[[#This Row],[Qty Complete]]/tbl_TubeLaser[[#This Row],[Qty Required]] -> 1 | J14: 30 | K14: 1 | L14: =IF(tbl_TubeLaser[[#This Row],[Job Type]]="Batch",0,tbl_TubeLaser[[#This Row],[Qty Required]]/tbl_TubeLaser[[#This Row],[PPH]]*tbl_TubeLaser[[#This Row],['# of men]]) -> 9.3333333 | M14: =IF(tbl_TubeLaser[[#This Row],[Job Type]]="Batch",tbl_TubeLaser[[#This Row],[Batch Hours]]*tbl_TubeLaser[[#This Row],[% Complete]],tbl_TubeLaser[[#This Row],[Total hours]]*tbl_TubeLaser[[#This Row],[% Complete]]) -> 9.3333333 | O14: AN4414-20 | P14: =tbl_TubeLaser[[#This Row],[Mat. Qty]]*tbl_TubeLaser[[#This Row],[% Complete]] -> 15 | Q14: 15 | R14: =IFERROR(tbl_TubeLaser[[#This Row],[Qty Complete]]/tbl_TubeLaser[[#This Row],[Total Hours Act]]*tbl_TubeLaser[[#This Row],['# of men Act]],"") -> 41.584158 | S14: 1 | T14: =(MOD(tbl_TubeLaser[[#This Row],[End Time]]-tbl_TubeLaser[[#This Row],[Start Time]],1)*24*tbl_TubeLaser[[#This Row],['# of men Act]])- ( IF(AND(tbl_TubeLaser[[#This Row],[Start Time]]<=Data!$B$2+(Data!$B$2<tbl_TubeLaser[[#This Row],[Start Time]]),tbl_TubeLaser[[#This Row],[Start Time]]+MOD(tbl_TubeLaser[[#This Row],[End Time]]-tbl_TubeLaser[[#This Row],[Start Time]],1)>=Data!$C$2+(Data!$C$2<tbl_TubeLaser[[#This Row],[Start Time]])),0.5*tbl_TubeLaser[[#This Row],['# of men Act]],0) + IF(AND(tbl_TubeLaser[[#This Row],[Start Time]]<=Data!$B$3+(Data!$B$3<tbl_TubeLaser[[#This Row],[Start Time]]),tbl_TubeLaser[[#This Row],[Start Time]]+MOD(tbl_TubeLaser[[#This Row],[End Time]]-tbl_TubeLaser[[#This Row],[Start Time]],1)>=Data!$C$3+(Data!$C$3<tbl_TubeLaser[[#This Row],[Start Time]])),0.5*tbl_TubeLaser[[#This Row],['# of men Act]],0) ) -> 6.7333333 | U14: 15 | V14: 0.5 | W14: 0.3 | X14: =IFERROR((tbl_TubeLaser[[#This Row],[Adj. Total Hours]]+tbl_TubeLaser[[#This Row],[Est. Hours]])/(tbl_TubeLaser[[#This Row],[Total Hours Act]]+tbl_TubeLaser[[#This Row],[Act. Hours]]),"") -> 1.3981043 | Y14: =IF(AND(SUMIFS(tbl_TubeLaser[% Complete],tbl_TubeLaser[Job'#],tbl_TubeLaser[[#This Row],[Job'#]])>=1,COUNTIF(INDEX(tbl_TubeLaser[Job'#],1):tbl_TubeLaser[[#This Row],[Job'#]],tbl_TubeLaser[[#This Row],[Job'#]])=COUNTIF(tbl_TubeLaser[Job'#],tbl_TubeLaser[[#This Row],[Job'#]])),IFERROR((SUMIFS(tbl_TubeLaser[Adj. Total Hours],tbl_TubeLaser[Job'#],tbl_TubeLaser[[#This Row],[Job'#]])+SUMIFS(tbl_TubeLaser[Est. Hours],tbl_TubeLaser[Job'#],tbl_TubeLaser[[#This Row],[Job'#]]))/(SUMIFS(tbl_TubeLaser[Total Hours Act],tbl_TubeLaser[Job'#],tbl_TubeLaser[[#This Row],[Job'#]])+SUMIFS(tbl_TubeLaser[Act. Hours],tbl_TubeLaser[Job'#],tbl_TubeLaser[[#This Row],[Job'#]])),""),"") -> 1.3981043 | Z14: =IFERROR(tbl_TubeLaser[[#This Row],[Act. Mat. Qty]]-tbl_TubeLaser[[#This Row],[Adj. Mat. Qty]],"") -> 0 | AA14: =IF(AND(SUMIFS(tbl_TubeLaser[% Complete],tbl_TubeLaser[Job'#],tbl_TubeLaser[[#This Row],[Job'#]])>=1,COUNTIF(INDEX(tbl_TubeLaser[Job'#],1):tbl_TubeLaser[[#This Row],[Job'#]],tbl_TubeLaser[[#This Row],[Job'#]])=COUNTIF(tbl_TubeLaser[Job'#],tbl_TubeLaser[[#This Row],[Job'#]])),(SUMIFS(tbl_TubeLaser[Act. Mat. Qty],tbl_TubeLaser[Job'#],tbl_TubeLaser[[#This Row],[Job'#]]))-(SUMIFS(tbl_TubeLaser[Adj. Mat. Qty],tbl_TubeLaser[Job'#],tbl_TubeLaser[[#This Row],[Job'#]])),"") -> 0 | AC14: BRAD OLIVER
A15: 46121 | B15: 143201 | C15: 143201 | D15: NAS100003006 | E15: 0.72916667 | F15: 0.79791667 | G15: 24 | H15: 18 | I15: =tbl_TubeLaser[[#This Row],[Qty Complete]]/tbl_TubeLaser[[#This Row],[Qty Required]] -> 0.75 | J15: 18 | K15: 1 | L15: =IF(tbl_TubeLaser[[#This Row],[Job Type]]="Batch",0,tbl_TubeLaser[[#This Row],[Qty Required]]/tbl_TubeLaser[[#This Row],[PPH]]*tbl_TubeLaser[[#This Row],['# of men]]) -> 1.3333333 | M15: =IF(tbl_TubeLaser[[#This Row],[Job Type]]="Batch",tbl_TubeLaser[[#This Row],[Batch Hours]]*tbl_TubeLaser[[#This Row],[% Complete]],tbl_TubeLaser[[#This Row],[Total hours]]*tbl_TubeLaser[[#This Row],[% Complete]]) -> 1 | O15: RT5211GA-303 | P15: =tbl_TubeLaser[[#This Row],[Mat. Qty]]*tbl_TubeLaser[[#This Row],[% Complete]] -> 9 | Q15: 12 | R15: =IFERROR(tbl_TubeLaser[[#This Row],[Qty Complete]]/tbl_TubeLaser[[#This Row],[Total Hours Act]]*tbl_TubeLaser[[#This Row],['# of men Act]],"") -> 10.909091 | S15: 1 | T15: =(MOD(tbl_TubeLaser[[#This Row],[End Time]]-tbl_TubeLaser[[#This Row],[Start Time]],1)*24*tbl_TubeLaser[[#This Row],['# of men Act]])- ( IF(AND(tbl_TubeLaser[[#This Row],[Start Time]]<=Data!$B$2+(Data!$B$2<tbl_TubeLaser[[#This Row],[Start Time]]),tbl_TubeLaser[[#This Row],[Start Time]]+MOD(tbl_TubeLaser[[#This Row],[End Time]]-tbl_TubeLaser[[#This Row],[Start Time]],1)>=Data!$C$2+(Data!$C$2<tbl_TubeLaser[[#This Row],[Start Time]])),0.5*tbl_TubeLaser[[#This Row],['# of men Act]],0) + IF(AND(tbl_TubeLaser[[#This Row],[Start Time]]<=Data!$B$3+(Data!$B$3<tbl_TubeLaser[[#This Row],[Start Time]]),tbl_TubeLaser[[#This Row],[Start Time]]+MOD(tbl_TubeLaser[[#This Row],[End Time]]-tbl_TubeLaser[[#This Row],[Start Time]],1)>=Data!$C$3+(Data!$C$3<tbl_TubeLaser[[#This Row],[Start Time]])),0.5*tbl_TubeLaser[[#This Row],['# of men Act]],0) ) -> 1.65 | U15: 9 | V15: 0.5 | W15: 0.3 | X15: =IFERROR((tbl_TubeLaser[[#This Row],[Adj. Total Hours]]+tbl_TubeLaser[[#This Row],[Est. Hours]])/(tbl_TubeLaser[[#This Row],[Total Hours Act]]+tbl_TubeLaser[[#This Row],[Act. Hours]]),"") -> 0.76923077 | Y15: =IF(AND(SUMIFS(tbl_TubeLaser[% Complete],tbl_TubeLaser[Job'#],tbl_TubeLaser[[#This Row],[Job'#]])>=1,COUNTIF(INDEX(tbl_TubeLaser[Job'#],1):tbl_TubeLaser[[#This Row],[Job'#]],tbl_TubeLaser[[#This Row],[Job'#]])=COUNTIF(tbl_TubeLaser[Job'#],tbl_TubeLaser[[#This Row],[Job'#]])),IFERROR((SUMIFS(tbl_TubeLaser[Adj. Total Hours],tbl_TubeLaser[Job'#],tbl_TubeLaser[[#This Row],[Job'#]])+SUMIFS(tbl_TubeLaser[Est. Hours],tbl_TubeLaser[Job'#],tbl_TubeLaser[[#This Row],[Job'#]]))/(SUMIFS(tbl_TubeLaser[Total Hours Act],tbl_TubeLaser[Job'#],tbl_TubeLaser[[#This Row],[Job'#]])+SUMIFS(tbl_TubeLaser[Act. Hours],tbl_TubeLaser[Job'#],tbl_TubeLaser[[#This Row],[Job'#]])),""),"") | Z15: =IFERROR(tbl_TubeLaser[[#This Row],[Act. Mat. Qty]]-tbl_TubeLaser[[#This Row],[Adj. Mat. Qty]],"") -> 0 | AA15: =IF(AND(SUMIFS(tbl_TubeLaser[% Complete],tbl_TubeLaser[Job'#],tbl_TubeLaser[[#This Row],[Job'#]])>=1,COUNTIF(INDEX(tbl_TubeLaser[Job'#],1):tbl_TubeLaser[[#This Row],[Job'#]],tbl_TubeLaser[[#This Row],[Job'#]])=COUNTIF(tbl_TubeLaser[Job'#],tbl_TubeLaser[[#This Row],[Job'#]])),(SUMIFS(tbl_TubeLaser[Act. Mat. Qty],tbl_TubeLaser[Job'#],tbl_TubeLaser[[#This Row],[Job'#]]))-(SUMIFS(tbl_TubeLaser[Adj. Mat. Qty],tbl_TubeLaser[Job'#],tbl_TubeLaser[[#This Row],[Job'#]])),"") | AB15: MATERIAL HANDLING
A16: 46121 | B16: 143117 | C16: 143117 | D16: NAS100000134 | E16: 0.72986111 | F16: 0.79722222 | G16: 12 | H16: 18 | I16: =tbl_TubeLaser[[#This Row],[Qty Complete]]/tbl_TubeLaser[[#This Row],[Qty Required]] -> 1.5 | J16: 30 | K16: 1 | L16: =IF(tbl_TubeLaser[[#This Row],[Job Type]]="Batch",0,tbl_TubeLaser[[#This Row],[Qty Required]]/tbl_TubeLaser[[#This Row],[PPH]]*tbl_TubeLaser[[#This Row],['# of men]]) -> 0.4 | M16: =IF(tbl_TubeLaser[[#This Row],[Job Type]]="Batch",tbl_TubeLaser[[#This Row],[Batch Hours]]*tbl_TubeLaser[[#This Row],[% Complete]],tbl_TubeLaser[[#This Row],[Total hours]]*tbl_TubeLaser[[#This Row],[% Complete]]) -> 0.6 | O16: RT5211GA-303 | P16: =tbl_TubeLaser[[#This Row],[Mat. Qty]]*tbl_TubeLaser[[#This Row],[% Complete]] -> 9 | Q16: 6 | R16: =IFERROR(tbl_TubeLaser[[#This Row],[Qty Complete]]/tbl_TubeLaser[[#This Row],[Total Hours Act]]*tbl_TubeLaser[[#This Row],['# of men Act]],"") -> 11.134021 | S16: 1 | T16: =(MOD(tbl_TubeLaser[[#This Row],[End Time]]-tbl_TubeLaser[[#This Row],[Start Time]],1)*24*tbl_TubeLaser[[#This Row],['# of men Act]])- ( IF(AND(tbl_TubeLaser[[#This Row],[Start Time]]<=Data!$B$2+(Data!$B$2<tbl_TubeLaser[[#This Row],[Start Time]]),tbl_TubeLaser[[#This Row],[Start Time]]+MOD(tbl_TubeLaser[[#This Row],[End Time]]-tbl_TubeLaser[[#This Row],[Start Time]],1)>=Data!$C$2+(Data!$C$2<tbl_TubeLaser[[#This Row],[Start Time]])),0.5*tbl_TubeLaser[[#This Row],['# of men Act]],0) + IF(AND(tbl_TubeLaser[[#This Row],[Start Time]]<=Data!$B$3+(Data!$B$3<tbl_TubeLaser[[#This Row],[Start Time]]),tbl_TubeLaser[[#This Row],[Start Time]]+MOD(tbl_TubeLaser[[#This Row],[End Time]]-tbl_TubeLaser[[#This Row],[Start Time]],1)>=Data!$C$3+(Data!$C$3<tbl_TubeLaser[[#This Row],[Start Time]])),0.5*tbl_TubeLaser[[#This Row],['# of men Act]],0) ) -> 1.6166667 | U16: 9 | V16: 0.5 | W16: 0.09 | X16: =IFERROR((tbl_TubeLaser[[#This Row],[Adj. Total Hours]]+tbl_TubeLaser[[#This Row],[Est. Hours]])/(tbl_TubeLaser[[#This Row],[Total Hours Act]]+tbl_TubeLaser[[#This Row],[Act. Hours]]),"") -> 0.64453125 | Y16: =IF(AND(SUMIFS(tbl_TubeLaser[% Complete],tbl_TubeLaser[Job'#],tbl_TubeLaser[[#This Row],[Job'#]])>=1,COUNTIF(INDEX(tbl_TubeLaser[Job'#],1):tbl_TubeLaser[[#This Row],[Job'#]],tbl_TubeLaser[[#This Row],[Job'#]])=COUNTIF(tbl_TubeLaser[Job'#],tbl_TubeLaser[[#This Row],[Job'#]])),IFERROR((SUMIFS(tbl_TubeLaser[Adj. Total Hours],tbl_TubeLaser[Job'#],tbl_TubeLaser[[#This Row],[Job'#]])+SUMIFS(tbl_TubeLaser[Est. Hours],tbl_TubeLaser[Job'#],tbl_TubeLaser[[#This Row],[Job'#]]))/(SUMIFS(tbl_TubeLaser[Total Hours Act],tbl_TubeLaser[Job'#],tbl_TubeLaser[[#This Row],[Job'#]])+SUMIFS(tbl_TubeLaser[Act. Hours],tbl_TubeLaser[Job'#],tbl_TubeLaser[[#This Row],[Job'#]])),""),"") -> 0.64453125 | Z16: =IFERROR(tbl_TubeLaser[[#This Row],[Act. Mat. Qty]]-tbl_TubeLaser[[#This Row],[Adj. Mat. Qty]],"") -> 0 | AA16: =IF(AND(SUMIFS(tbl_TubeLaser[% Complete],tbl_TubeLaser[Job'#],tbl_TubeLaser[[#This Row],[Job'#]])>=1,COUNTIF(INDEX(tbl_TubeLaser[Job'#],1):tbl_TubeLaser[[#This Row],[Job'#]],tbl_TubeLaser[[#This Row],[Job'#]])=COUNTIF(tbl_TubeLaser[Job'#],tbl_TubeLaser[[#This Row],[Job'#]])),(SUMIFS(tbl_TubeLaser[Act. Mat. Qty],tbl_TubeLaser[Job'#],tbl_TubeLaser[[#This Row],[Job'#]]))-(SUMIFS(tbl_TubeLaser[Adj. Mat. Qty],tbl_TubeLaser[Job'#],tbl_TubeLaser[[#This Row],[Job'#]])),"") -> 0 | AB16: HC instructed operator to keep running from first shift, parts would be allocated later. | AC16: Jason Thomason
A17: 46121 | B17: 143205 | C17: 143205 | D17: NAS100000119 | E17: 0.83055556 | F17: 0.97916667 | G17: 24 | H17: 24 | I17: =tbl_TubeLaser[[#This Row],[Qty Complete]]/tbl_TubeLaser[[#This Row],[Qty Required]] -> 1 | J17: 24 | K17: 1 | L17: =IF(tbl_TubeLaser[[#This Row],[Job Type]]="Batch",0,tbl_TubeLaser[[#This Row],[Qty Required]]/tbl_TubeLaser[[#This Row],[PPH]]*tbl_TubeLaser[[#This Row],['# of men]]) -> 1 | M17: =IF(tbl_TubeLaser[[#This Row],[Job Type]]="Batch",tbl_TubeLaser[[#This Row],[Batch Hours]]*tbl_TubeLaser[[#This Row],[% Complete]],tbl_TubeLaser[[#This Row],[Total hours]]*tbl_TubeLaser[[#This Row],[% Complete]]) -> 1 | O17: RT5211GA-330 | P17: =tbl_TubeLaser[[#This Row],[Mat. Qty]]*tbl_TubeLaser[[#This Row],[% Complete]] -> 12 | Q17: 12 | R17: =IFERROR(tbl_TubeLaser[[#This Row],[Qty Complete]]/tbl_TubeLaser[[#This Row],[Total Hours Act]]*tbl_TubeLaser[[#This Row],['# of men Act]],"") -> 6.728972 | S17: 1 | T17: =(MOD(tbl_TubeLaser[[#This Row],[End Time]]-tbl_TubeLaser[[#This Row],[Start Time]],1)*24*tbl_TubeLaser[[#This Row],['# of men Act]])- ( IF(AND(tbl_TubeLaser[[#This Row],[Start Time]]<=Data!$B$2+(Data!$B$2<tbl_TubeLaser[[#This Row],[Start Time]]),tbl_TubeLaser[[#This Row],[Start Time]]+MOD(tbl_TubeLaser[[#This Row],[End Time]]-tbl_TubeLaser[[#This Row],[Start Time]],1)>=Data!$C$2+(Data!$C$2<tbl_TubeLaser[[#This Row],[Start Time]])),0.5*tbl_TubeLaser[[#This Row],['# of men Act]],0) + IF(AND(tbl_TubeLaser[[#This Row],[Start Time]]<=Data!$B$3+(Data!$B$3<tbl_TubeLaser[[#This Row],[Start Time]]),tbl_TubeLaser[[#This Row],[Start Time]]+MOD(tbl_TubeLaser[[#This Row],[End Time]]-tbl_TubeLaser[[#This Row],[Start Time]],1)>=Data!$C$3+(Data!$C$3<tbl_TubeLaser[[#This Row],[Start Time]])),0.5*tbl_TubeLaser[[#This Row],['# of men Act]],0) ) -> 3.5666667 | V17: 0.5 | X17: =IFERROR((tbl_TubeLaser[[#This Row],[Adj. Total Hours]]+tbl_TubeLaser[[#This Row],[Est. Hours]])/(tbl_TubeLaser[[#This Row],[Total Hours Act]]+tbl_TubeLaser[[#This Row],[Act. Hours]]),"") -> 0.42056075 | Y17: =IF(AND(SUMIFS(tbl_TubeLaser[% Complete],tbl_TubeLaser[Job'#],tbl_TubeLaser[[#This Row],[Job'#]])>=1,COUNTIF(INDEX(tbl_TubeLaser[Job'#],1):tbl_TubeLaser[[#This Row],[Job'#]],tbl_TubeLaser[[#This Row],[Job'#]])=COUNTIF(tbl_TubeLaser[Job'#],tbl_TubeLaser[[#This Row],[Job'#]])),IFERROR((SUMIFS(tbl_TubeLaser[Adj. Total Hours],tbl_TubeLaser[Job'#],tbl_TubeLaser[[#This Row],[Job'#]])+SUMIFS(tbl_TubeLaser[Est. Hours],tbl_TubeLaser[Job'#],tbl_TubeLaser[[#This Row],[Job'#]]))/(SUMIFS(tbl_TubeLaser[Total Hours Act],tbl_TubeLaser[Job'#],tbl_TubeLaser[[#This Row],[Job'#]])+SUMIFS(tbl_TubeLaser[Act. Hours],tbl_TubeLaser[Job'#],tbl_TubeLaser[[#This Row],[Job'#]])),""),"") -> 0.42056075 | Z17: =IFERROR(tbl_TubeLaser[[#This Row],[Act. Mat. Qty]]-tbl_TubeLaser[[#This Row],[Adj. Mat. Qty]],"") -> -12 | AA17: =IF(AND(SUMIFS(tbl_TubeLaser[% Complete],tbl_TubeLaser[Job'#],tbl_TubeLaser[[#This Row],[Job'#]])>=1,COUNTIF(INDEX(tbl_TubeLaser[Job'#],1):tbl_TubeLaser[[#This Row],[Job'#]],tbl_TubeLaser[[#This Row],[Job'#]])=COUNTIF(tbl_TubeLaser[Job'#],tbl_TubeLaser[[#This Row],[Job'#]])),(SUMIFS(tbl_TubeLaser[Act. Mat. Qty],tbl_TubeLaser[Job'#],tbl_TubeLaser[[#This Row],[Job'#]]))-(SUMIFS(tbl_TubeLaser[Adj. Mat. Qty],tbl_TubeLaser[Job'#],tbl_TubeLaser[[#This Row],[Job'#]])),"") -> -12 | AB17: signed into other jobs that can run on same material | AC17: Jason Thomason
A18: 46121 | B18: 143203 | C18: 143203 | D18: NAS000055516 | E18: 0.83055556 | F18: 0.90069444 | G18: 16 | H18: 16 | I18: =tbl_TubeLaser[[#This Row],[Qty Complete]]/tbl_TubeLaser[[#This Row],[Qty Required]] -> 1 | J18: 24 | K18: 1 | L18: =IF(tbl_TubeLaser[[#This Row],[Job Type]]="Batch",0,tbl_TubeLaser[[#This Row],[Qty Required]]/tbl_TubeLaser[[#This Row],[PPH]]*tbl_TubeLaser[[#This Row],['# of men]]) -> 0.66666667 | M18: =IF(tbl_TubeLaser[[#This Row],[Job Type]]="Batch",tbl_TubeLaser[[#This Row],[Batch Hours]]*tbl_TubeLaser[[#This Row],[% Complete]],tbl_TubeLaser[[#This Row],[Total hours]]*tbl_TubeLaser[[#This Row],[% Complete]]) -> 0.66666667 | O18: RT5211GA-20 | P18: =tbl_TubeLaser[[#This Row],[Mat. Qty]]*tbl_TubeLaser[[#This Row],[% Complete]] -> 16 | Q18: 16 | R18: =IFERROR(tbl_TubeLaser[[#This Row],[Qty Complete]]/tbl_TubeLaser[[#This Row],[Total Hours Act]]*tbl_TubeLaser[[#This Row],['# of men Act]],"") -> 9.5049505 | S18: 1 | T18: =(MOD(tbl_TubeLaser[[#This Row],[End Time]]-tbl_TubeLaser[[#This Row],[Start Time]],1)*24*tbl_TubeLaser[[#This Row],['# of men Act]])- ( IF(AND(tbl_TubeLaser[[#This Row],[Start Time]]<=Data!$B$2+(Data!$B$2<tbl_TubeLaser[[#This Row],[Start Time]]),tbl_TubeLaser[[#This Row],[Start Time]]+MOD(tbl_TubeLaser[[#This Row],[End Time]]-tbl_TubeLaser[[#This Row],[Start Time]],1)>=Data!$C$2+(Data!$C$2<tbl_TubeLaser[[#This Row],[Start Time]])),0.5*tbl_TubeLaser[[#This Row],['# of men Act]],0) + IF(AND(tbl_TubeLaser[[#This Row],[Start Time]]<=Data!$B$3+(Data!$B$3<tbl_TubeLaser[[#This Row],[Start Time]]),tbl_TubeLaser[[#This Row],[Start Time]]+MOD(tbl_TubeLaser[[#This Row],[End Time]]-tbl_TubeLaser[[#This Row],[Start Time]],1)>=Data!$C$3+(Data!$C$3<tbl_TubeLaser[[#This Row],[Start Time]])),0.5*tbl_TubeLaser[[#This Row],['# of men Act]],0) ) -> 1.6833333 | V18: 0.5 | X18: =IFERROR((tbl_TubeLaser[[#This Row],[Adj. Total Hours]]+tbl_TubeLaser[[#This Row],[Est. Hours]])/(tbl_TubeLaser[[#This Row],[Total Hours Act]]+tbl_TubeLaser[[#This Row],[Act. Hours]]),"") -> 0.69306931 | Y18: =IF(AND(SUMIFS(tbl_TubeLaser[% Complete],tbl_TubeLaser[Job'#],tbl_TubeLaser[[#This Row],[Job'#]])>=1,COUNTIF(INDEX(tbl_TubeLaser[Job'#],1):tbl_TubeLaser[[#This Row],[Job'#]],tbl_TubeLaser[[#This Row],[Job'#]])=COUNTIF(tbl_TubeLaser[Job'#],tbl_TubeLaser[[#This Row],[Job'#]])),IFERROR((SUMIFS(tbl_TubeLaser[Adj. Total Hours],tbl_TubeLaser[Job'#],tbl_TubeLaser[[#This Row],[Job'#]])+SUMIFS(tbl_TubeLaser[Est. Hours],tbl_TubeLaser[Job'#],tbl_TubeLaser[[#This Row],[Job'#]]))/(SUMIFS(tbl_TubeLaser[Total Hours Act],tbl_TubeLaser[Job'#],tbl_TubeLaser[[#This Row],[Job'#]])+SUMIFS(tbl_TubeLaser[Act. Hours],tbl_TubeLaser[Job'#],tbl_TubeLaser[[#This Row],[Job'#]])),""),"") -> 0.69306931 | Z18: =IFERROR(tbl_TubeLaser[[#This Row],[Act. Mat. Qty]]-tbl_TubeLaser[[#This Row],[Adj. Mat. Qty]],"") -> -16 | AA18: =IF(AND(SUMIFS(tbl_TubeLaser[% Complete],tbl_TubeLaser[Job'#],tbl_TubeLaser[[#This Row],[Job'#]])>=1,COUNTIF(INDEX(tbl_TubeLaser[Job'#],1):tbl_TubeLaser[[#This Row],[Job'#]],tbl_TubeLaser[[#This Row],[Job'#]])=COUNTIF(tbl_TubeLaser[Job'#],tbl_TubeLaser[[#This Row],[Job'#]])),(SUMIFS(tbl_TubeLaser[Act. Mat. Qty],tbl_TubeLaser[Job'#],tbl_TubeLaser[[#This Row],[Job'#]]))-(SUMIFS(tbl_TubeLaser[Adj. Mat. Qty],tbl_TubeLaser[Job'#],tbl_TubeLaser[[#This Row],[Job'#]])),"") -> -16 | AB18: signed into other jobs that can run on same material | AC18: Jason Thomason
A19: 46121 | B19: 143123 | C19: 143123 | D19: NAS100010979 | E19: 0.052083333 | F19: 0.10347222 | G19: 8 | H19: 8 | I19: =tbl_TubeLaser[[#This Row],[Qty Complete]]/tbl_TubeLaser[[#This Row],[Qty Required]] -> 1 | J19: 24 | K19: 1 | L19: =IF(tbl_TubeLaser[[#This Row],[Job Type]]="Batch",0,tbl_TubeLaser[[#This Row],[Qty Required]]/tbl_TubeLaser[[#This Row],[PPH]]*tbl_TubeLaser[[#This Row],['# of men]]) -> 0.33333333 | M19: =IF(tbl_TubeLaser[[#This Row],[Job Type]]="Batch",tbl_TubeLaser[[#This Row],[Batch Hours]]*tbl_TubeLaser[[#This Row],[% Complete]],tbl_TubeLaser[[#This Row],[Total hours]]*tbl_TubeLaser[[#This Row],[% Complete]]) -> 0.33333333 | P19: =tbl_TubeLaser[[#This Row],[Mat. Qty]]*tbl_TubeLaser[[#This Row],[% Complete]] -> 0 | R19: =IFERROR(tbl_TubeLaser[[#This Row],[Qty Complete]]/tbl_TubeLaser[[#This Row],[Total Hours Act]]*tbl_TubeLaser[[#This Row],['# of men Act]],"") -> 6.4864865 | S19: 1 | T19: =(MOD(tbl_TubeLaser[[#This Row],[End Time]]-tbl_TubeLaser[[#This Row],[Start Time]],1)*24*tbl_TubeLaser[[#This Row],['# of men Act]])- ( IF(AND(tbl_TubeLaser[[#This Row],[Start Time]]<=Data!$B$2+(Data!$B$2<tbl_TubeLaser[[#This Row],[Start Time]]),tbl_TubeLaser[[#This Row],[Start Time]]+MOD(tbl_TubeLaser[[#This Row],[End Time]]-tbl_TubeLaser[[#This Row],[Start Time]],1)>=Data!$C$2+(Data!$C$2<tbl_TubeLaser[[#This Row],[Start Time]])),0.5*tbl_TubeLaser[[#This Row],['# of men Act]],0) + IF(AND(tbl_TubeLaser[[#This Row],[Start Time]]<=Data!$B$3+(Data!$B$3<tbl_TubeLaser[[#This Row],[Start Time]]),tbl_TubeLaser[[#This Row],[Start Time]]+MOD(tbl_TubeLaser[[#This Row],[End Time]]-tbl_TubeLaser[[#This Row],[Start Time]],1)>=Data!$C$3+(Data!$C$3<tbl_TubeLaser[[#This Row],[Start Time]])),0.5*tbl_TubeLaser[[#This Row],['# of men Act]],0) ) -> 1.2333333 | V19: 0.5 | X19: =IFERROR((tbl_TubeLaser[[#This Row],[Adj. Total Hours]]+tbl_TubeLaser[[#This Row],[Est. Hours]])/(tbl_TubeLaser[[#This Row],[Total Hours Act]]+tbl_TubeLaser[[#This Row],[Act. Hours]]),"") -> 0.67567568 | Y19: =IF(AND(SUMIFS(tbl_TubeLaser[% Complete],tbl_TubeLaser[Job'#],tbl_TubeLaser[[#This Row],[Job'#]])>=1,COUNTIF(INDEX(tbl_TubeLaser[Job'#],1):tbl_TubeLaser[[#This Row],[Job'#]],tbl_TubeLaser[[#This Row],[Job'#]])=COUNTIF(tbl_TubeLaser[Job'#],tbl_TubeLaser[[#This Row],[Job'#]])),IFERROR((SUMIFS(tbl_TubeLaser[Adj. Total Hours],tbl_TubeLaser[Job'#],tbl_TubeLaser[[#This Row],[Job'#]])+SUMIFS(tbl_TubeLaser[Est. Hours],tbl_TubeLaser[Job'#],tbl_TubeLaser[[#This Row],[Job'#]]))/(SUMIFS(tbl_TubeLaser[Total Hours Act],tbl_TubeLaser[Job'#],tbl_TubeLaser[[#This Row],[Job'#]])+SUMIFS(tbl_TubeLaser[Act. Hours],tbl_TubeLaser[Job'#],tbl_TubeLaser[[#This Row],[Job'#]])),""),"") -> 0.67567568 | Z19: =IFERROR(tbl_TubeLaser[[#This Row],[Act. Mat. Qty]]-tbl_TubeLaser[[#This Row],[Adj. Mat. Qty]],"") -> 0 | AA19: =IF(AND(SUMIFS(tbl_TubeLaser[% Complete],tbl_TubeLaser[Job'#],tbl_TubeLaser[[#This Row],[Job'#]])>=1,COUNTIF(INDEX(tbl_TubeLaser[Job'#],1):tbl_TubeLaser[[#This Row],[Job'#]],tbl_TubeLaser[[#This Row],[Job'#]])=COUNTIF(tbl_TubeLaser[Job'#],tbl_TubeLaser[[#This Row],[Job'#]])),(SUMIFS(tbl_TubeLaser[Act. Mat. Qty],tbl_TubeLaser[Job'#],tbl_TubeLaser[[#This Row],[Job'#]]))-(SUMIFS(tbl_TubeLaser[Adj. Mat. Qty],tbl_TubeLaser[Job'#],tbl_TubeLaser[[#This Row],[Job'#]])),"") -> 0 | AB19: Jobs run concurrently, information pulled from Epicor
