Workbook

Sheet FB Laser
AA1: Notes
Y2: Outsource | Z2: 0
Y3: Programming Fee | Z3: 60
Y4: Welding (in-house) | Z4: =IF(Welding!G10="Flat",Welding!E10+Welding!D6,IF(Welding!G10="Flat&Tube",(Welding!E10+Welding!D6)/2,0)) -> 0
Y5: Hardware | Z5: 0
Y6: QC | Z6: 0
Y7: Material Source | Z7: JWMCD | AB7: User Defined
Y8: Pallet Cost | Z8: =IF(AA8="Default",(ROUNDUP((AC34/1500),0)*30),IF(AA8="User Defined",AB8,"Need Input")) -> 0 | AA8: Default | AB8: 0
A9: dwg# | B9: Qty | C9: Length (in) | D9: Width (in) | E9: Laser Time Lot (min) | F9: Notes? | G9: Laser Cost (Each) | H9: Forming Cost (Each) | I9: Hardware Install (Each) | J9: Machining (Each) | K9: Finishing (Each) | L9: Labor (Each) | M9: sqft (Each) | N9: Material ID | O9: % Material Used | P9: Material Cost (LOT) | Q9: Material PRICE (EACH) | R9: Adjustment | S9: Total Cost (Each) | T9: Total Price (Each) | U9: Cost Lot | V9: Price Lot | W9: Price/Lbs | Y9: Delivery Cost | Z9: =IF(AA9="Delivery",ROUNDUP((AC34/8000),0)*100,IF(AA9="Will-Call",0,"Need Input")) -> 0 | AA9: Delivery
G10: =IFERROR(((E10/60)*$Z$10)/B10,"") | H10: =IF(Forming!G10>0,Forming!G10,0) -> 0 | I10: =IF('Hardware Install'!E10>0,'Hardware Install'!E10,0) -> 0 | J10: =IFERROR(VLOOKUP('FB Laser'!A10,Machining!A10:G100,7,FALSE),"") | K10: =IFERROR(IF(Finishing!G10>0,VLOOKUP('FB Laser'!A10,Finishing!A10:G100,7,FALSE),""),"") | L10: =IFERROR(SUM((H10*$Z$12),G10,I10,J10,K10,'FB Data'!AM9),"") -> 0 | M10: =IFERROR((C10*D10)*0.00694,"") -> 0 | O10: =IFERROR((B10*M10)/(VLOOKUP(N10,$Y$15:$AB$33,2,FALSE)),"") | P10: =IFERROR(VLOOKUP(N10,$Y$15:$AB$33,4,FALSE)*(O10/(VLOOKUP(N10,$Y$15:$AB$33,3,FALSE))),"") | Q10: =IFERROR((P10*$Z$11)/B10,"") | S10: =IFERROR(L10+Q10+($Z$8/$B$100)+($Z$9/$B$100)+($Z$3/$B$100)+($Z$2/$B$100)+($Z$4/$B$100)+($Z$5/$B$100)+($Z$6/$B$100),"") | T10: =IFERROR(ROUND(S10*'Quote Info'!$O$4+R10,2),"") | U10: =IFERROR(S10*B10,"") | V10: =IFERROR(T10*B10,"") | W10: =IFERROR(S10/((VLOOKUP(N10,'FB Data'!$A$2:$E$150,3,FALSE))*'FB Laser'!M10),"") | Y10: Laser/Hr (Cost) | Z10: 112.24 | AA10: =Z10*'Quote Info'!O4 -> 152.6464
G11: =IFERROR(((E11/60)*$Z$10)/B11,"") | H11: =IF(Forming!G11>0,Forming!G11,0) -> 0 | I11: =IF('Hardware Install'!E11>0,'Hardware Install'!E11,0) -> 0 | J11: =IFERROR(VLOOKUP('FB Laser'!A11,Machining!A11:G101,7,FALSE),"") | K11: =IFERROR(IF(Finishing!G11>0,VLOOKUP('FB Laser'!A11,Finishing!A11:G101,7,FALSE),""),"") | L11: =IFERROR(SUM((H11*$Z$12),G11,I11,J11,K11,'FB Data'!AM10),"") -> 0 | M11: =IFERROR((C11*D11)*0.00694,"") -> 0 | O11: =IFERROR((B11*M11)/(VLOOKUP(N11,$Y$15:$AB$33,2,FALSE)),"") | P11: =IFERROR(VLOOKUP(N11,$Y$15:$AB$33,4,FALSE)*(O11/(VLOOKUP(N11,$Y$15:$AB$33,3,FALSE))),"") | Q11: =IFERROR((P11*$Z$11)/B11,"") | S11: =IFERROR(L11+Q11+($Z$8/$B$100)+($Z$9/$B$100)+($Z$3/$B$100)+($Z$2/$B$100)+($Z$4/$B$100)+($Z$5/$B$100)+($Z$6/$B$100),"") | T11: =IFERROR(ROUND(S11*'Quote Info'!$O$4+R11,2),"") | U11: =IFERROR(S11*B11,"") | V11: =IFERROR(T11*B11,"") | W11: =IFERROR(S11/((VLOOKUP(N11,'FB Data'!$A$2:$E$150,3,FALSE))*'FB Laser'!M11),"") | Y11: Material Mark-Up | Z11: 1
G12: =IFERROR(((E12/60)*$Z$10)/B12,"") | H12: =IF(Forming!G12>0,Forming!G12,0) -> 0 | I12: =IF('Hardware Install'!E12>0,'Hardware Install'!E12,0) -> 0 | J12: =IFERROR(VLOOKUP('FB Laser'!A12,Machining!A12:G102,7,FALSE),"") | K12: =IFERROR(IF(Finishing!G12>0,VLOOKUP('FB Laser'!A12,Finishing!A12:G102,7,FALSE),""),"") | L12: =IFERROR(SUM((H12*$Z$12),G12,I12,J12,K12,'FB Data'!AM11),"") -> 0 | M12: =IFERROR((C12*D12)*0.00694,"") -> 0 | O12: =IFERROR((B12*M12)/(VLOOKUP(N12,$Y$15:$AB$33,2,FALSE)),"") | P12: =IFERROR(VLOOKUP(N12,$Y$15:$AB$33,4,FALSE)*(O12/(VLOOKUP(N12,$Y$15:$AB$33,3,FALSE))),"") | Q12: =IFERROR((P12*$Z$11)/B12,"") | S12: =IFERROR(L12+Q12+($Z$8/$B$100)+($Z$9/$B$100)+($Z$3/$B$100)+($Z$2/$B$100)+($Z$4/$B$100)+($Z$5/$B$100)+($Z$6/$B$100),"") | T12: =IFERROR(ROUND(S12*'Quote Info'!$O$4+R12,2),"") | U12: =IFERROR(S12*B12,"") | V12: =IFERROR(T12*B12,"") | W12: =IFERROR(S12/((VLOOKUP(N12,'FB Data'!$A$2:$E$150,3,FALSE))*'FB Laser'!M12),"") | Y12: Forming Mark-Up | Z12: 1
G13: =IFERROR(((E13/60)*$Z$10)/B13,"") | H13: =IF(Forming!G13>0,Forming!G13,0) -> 0 | I13: =IF('Hardware Install'!E13>0,'Hardware Install'!E13,0) -> 0 | J13: =IFERROR(VLOOKUP('FB Laser'!A13,Machining!A13:G103,7,FALSE),"") | K13: =IFERROR(IF(Finishing!G13>0,VLOOKUP('FB Laser'!A13,Finishing!A13:G103,7,FALSE),""),"") | L13: =IFERROR(SUM((H13*$Z$12),G13,I13,J13,K13,'FB Data'!AM12),"") -> 0 | M13: =IFERROR((C13*D13)*0.00694,"") -> 0 | O13: =IFERROR((B13*M13)/(VLOOKUP(N13,$Y$15:$AB$33,2,FALSE)),"") | P13: =IFERROR(VLOOKUP(N13,$Y$15:$AB$33,4,FALSE)*(O13/(VLOOKUP(N13,$Y$15:$AB$33,3,FALSE))),"") | Q13: =IFERROR((P13*$Z$11)/B13,"") | S13: =IFERROR(L13+Q13+($Z$8/$B$100)+($Z$9/$B$100)+($Z$3/$B$100)+($Z$2/$B$100)+($Z$4/$B$100)+($Z$5/$B$100)+($Z$6/$B$100),"") | T13: =IFERROR(ROUND(S13*'Quote Info'!$O$4+R13,2),"") | U13: =IFERROR(S13*B13,"") | V13: =IFERROR(T13*B13,"") | W13: =IFERROR(S13/((VLOOKUP(N13,'FB Data'!$A$2:$E$150,3,FALSE))*'FB Laser'!M13),"")
G14: =IFERROR(((E14/60)*$Z$10)/B14,"") | H14: =IF(Forming!G14>0,Forming!G14,0) -> 0 | I14: =IF('Hardware Install'!E14>0,'Hardware Install'!E14,0) -> 0 | J14: =IFERROR(VLOOKUP('FB Laser'!A14,Machining!A14:G104,7,FALSE),"") | K14: =IFERROR(IF(Finishing!G14>0,VLOOKUP('FB Laser'!A14,Finishing!A14:G104,7,FALSE),""),"") | L14: =IFERROR(SUM((H14*$Z$12),G14,I14,J14,K14,'FB Data'!AM13),"") -> 0 | M14: =IFERROR((C14*D14)*0.00694,"") -> 0 | O14: =IFERROR((B14*M14)/(VLOOKUP(N14,$Y$15:$AB$33,2,FALSE)),"") | P14: =IFERROR(VLOOKUP(N14,$Y$15:$AB$33,4,FALSE)*(O14/(VLOOKUP(N14,$Y$15:$AB$33,3,FALSE))),"") | Q14: =IFERROR((P14*$Z$11)/B14,"") | S14: =IFERROR(L14+Q14+($Z$8/$B$100)+($Z$9/$B$100)+($Z$3/$B$100)+($Z$2/$B$100)+($Z$4/$B$100)+($Z$5/$B$100)+($Z$6/$B$100),"") | T14: =IFERROR(ROUND(S14*'Quote Info'!$O$4+R14,2),"") | U14: =IFERROR(S14*B14,"") | V14: =IFERROR(T14*B14,"") | W14: =IFERROR(S14/((VLOOKUP(N14,'FB Data'!$A$2:$E$150,3,FALSE))*'FB Laser'!M14),"") | Y14: Material ID | Z14: Total Sqft | AA14: Yield % | AB14: Total Cost | AC14: Total Weight (lbs)
G15: =IFERROR(((E15/60)*$Z$10)/B15,"") | H15: =IF(Forming!G15>0,Forming!G15,0) -> 0 | I15: =IF('Hardware Install'!E15>0,'Hardware Install'!E15,0) -> 0 | J15: =IFERROR(VLOOKUP('FB Laser'!A15,Machining!A15:G105,7,FALSE),"") | K15: =IFERROR(IF(Finishing!G15>0,VLOOKUP('FB Laser'!A15,Finishing!A15:G105,7,FALSE),""),"") | L15: =IFERROR(SUM((H15*$Z$12),G15,I15,J15,K15,'FB Data'!AM14),"") -> 0 | M15: =IFERROR((C15*D15)*0.00694,"") -> 0 | O15: =IFERROR((B15*M15)/(VLOOKUP(N15,$Y$15:$AB$33,2,FALSE)),"") | P15: =IFERROR(VLOOKUP(N15,$Y$15:$AB$33,4,FALSE)*(O15/(VLOOKUP(N15,$Y$15:$AB$33,3,FALSE))),"") | Q15: =IFERROR((P15*$Z$11)/B15,"") | S15: =IFERROR(L15+Q15+($Z$8/$B$100)+($Z$9/$B$100)+($Z$3/$B$100)+($Z$2/$B$100)+($Z$4/$B$100)+($Z$5/$B$100)+($Z$6/$B$100),"") | T15: =IFERROR(ROUND(S15*'Quote Info'!$O$4+R15,2),"") | U15: =IFERROR(S15*B15,"") | V15: =IFERROR(T15*B15,"") | W15: =IFERROR(S15/((VLOOKUP(N15,'FB Data'!$A$2:$E$150,3,FALSE))*'FB Laser'!M15),"") | Y15: {=IFERROR(INDEX($Y$39:$Y$65, MATCH(0,IF(ISBLANK($Y$39:$Y$65),1,COUNTIF($Y$14:Y14, $Y$39:$Y$65)), 0)),"")} | Z15: =SUMIF($Y$39:$Y$65,Y15,$AC$39:$AC$65) -> 0 | AA15: =IFERROR(SUMIF($N$10:$N$99,Y15,$O$10:$O$99),"") -> 0 | AB15: =IFERROR(SUMIF($Y$39:$Y$65,Y15,$AD$39:$AD$65),"") -> 0 | AC15: =IFERROR(Z15*AA15*VLOOKUP(Y15,'FB Data'!$A$2:$E$150,3,FALSE),"")
G16: =IFERROR(((E16/60)*$Z$10)/B16,"") | H16: =IF(Forming!G16>0,Forming!G16,0) -> 0 | I16: =IF('Hardware Install'!E16>0,'Hardware Install'!E16,0) -> 0 | J16: =IFERROR(VLOOKUP('FB Laser'!A16,Machining!A16:G106,7,FALSE),"") | K16: =IFERROR(IF(Finishing!G16>0,VLOOKUP('FB Laser'!A16,Finishing!A16:G106,7,FALSE),""),"") | L16: =IFERROR(SUM((H16*$Z$12),G16,I16,J16,K16,'FB Data'!AM15),"") -> 0 | M16: =IFERROR((C16*D16)*0.00694,"") -> 0 | O16: =IFERROR((B16*M16)/(VLOOKUP(N16,$Y$15:$AB$33,2,FALSE)),"") | P16: =IFERROR(VLOOKUP(N16,$Y$15:$AB$33,4,FALSE)*(O16/(VLOOKUP(N16,$Y$15:$AB$33,3,FALSE))),"") | Q16: =IFERROR((P16*$Z$11)/B16,"") | S16: =IFERROR(L16+Q16+($Z$8/$B$100)+($Z$9/$B$100)+($Z$3/$B$100)+($Z$2/$B$100)+($Z$4/$B$100)+($Z$5/$B$100)+($Z$6/$B$100),"") | T16: =IFERROR(ROUND(S16*'Quote Info'!$O$4+R16,2),"") | U16: =IFERROR(S16*B16,"") | V16: =IFERROR(T16*B16,"") | W16: =IFERROR(S16/((VLOOKUP(N16,'FB Data'!$A$2:$E$150,3,FALSE))*'FB Laser'!M16),"") | Y16: {=IFERROR(INDEX($Y$39:$Y$65, MATCH(0,IF(ISBLANK($Y$39:$Y$65),1,COUNTIF($Y$14:Y15, $Y$39:$Y$65)), 0)),"")} | Z16: =SUMIF($Y$39:$Y$65,Y16,$AC$39:$AC$65) -> 0 | AA16: =IFERROR(SUMIF($N$10:$N$99,Y16,$O$10:$O$99),"") -> 0 | AB16: =IFERROR(SUMIF($Y$39:$Y$65,Y16,$AD$39:$AD$65),"") -> 0 | AC16: =IFERROR(Z16*AA16*VLOOKUP(Y16,'FB Data'!$A$2:$E$150,3,FALSE),"")
G17: =IFERROR(((E17/60)*$Z$10)/B17,"") | H17: =IF(Forming!G17>0,Forming!G17,0) -> 0 | I17: =IF('Hardware Install'!E17>0,'Hardware Install'!E17,0) -> 0 | J17: =IFERROR(VLOOKUP('FB Laser'!A17,Machining!A17:G107,7,FALSE),"") | K17: =IFERROR(IF(Finishing!G17>0,VLOOKUP('FB Laser'!A17,Finishing!A17:G107,7,FALSE),""),"") | L17: =IFERROR(SUM((H17*$Z$12),G17,I17,J17,K17,'FB Data'!AM16),"") -> 0 | M17: =IFERROR((C17*D17)*0.00694,"") -> 0 | O17: =IFERROR((B17*M17)/(VLOOKUP(N17,$Y$15:$AB$33,2,FALSE)),"") | P17: =IFERROR(VLOOKUP(N17,$Y$15:$AB$33,4,FALSE)*(O17/(VLOOKUP(N17,$Y$15:$AB$33,3,FALSE))),"") | Q17: =IFERROR((P17*$Z$11)/B17,"") | S17: =IFERROR(L17+Q17+($Z$8/$B$100)+($Z$9/$B$100)+($Z$3/$B$100)+($Z$2/$B$100)+($Z$4/$B$100)+($Z$5/$B$100)+($Z$6/$B$100),"") | T17: =IFERROR(ROUND(S17*'Quote Info'!$O$4+R17,2),"") | U17: =IFERROR(S17*B17,"") | V17: =IFERROR(T17*B17,"") | W17: =IFERROR(S17/((VLOOKUP(N17,'FB Data'!$A$2:$E$150,3,FALSE))*'FB Laser'!M17),"") | Y17: {=IFERROR(INDEX($Y$39:$Y$65, MATCH(0,IF(ISBLANK($Y$39:$Y$65),1,COUNTIF($Y$14:Y16, $Y$39:$Y$65)), 0)),"")} | Z17: =SUMIF($Y$39:$Y$65,Y17,$AC$39:$AC$65) -> 0 | AA17: =IFERROR(SUMIF($N$10:$N$99,Y17,$O$10:$O$99),"") -> 0 | AB17: =IFERROR(SUMIF($Y$39:$Y$65,Y17,$AD$39:$AD$65),"") -> 0 | AC17: =IFERROR(Z17*AA17*VLOOKUP(Y17,'FB Data'!$A$2:$E$150,3,FALSE),"")
G18: =IFERROR(((E18/60)*$Z$10)/B18,"") | H18: =IF(Forming!G18>0,Forming!G18,0) -> 0 | I18: =IF('Hardware Install'!E18>0,'Hardware Install'!E18,0) -> 0 | J18: =IFERROR(VLOOKUP('FB Laser'!A18,Machining!A18:G108,7,FALSE),"") | K18: =IFERROR(IF(Finishing!G18>0,VLOOKUP('FB Laser'!A18,Finishing!A18:G108,7,FALSE),""),"") | L18: =IFERROR(SUM((H18*$Z$12),G18,I18,J18,K18,'FB Data'!AM17),"") -> 0 | M18: =IFERROR((C18*D18)*0.00694,"") -> 0 | O18: =IFERROR((B18*M18)/(VLOOKUP(N18,$Y$15:$AB$33,2,FALSE)),"") | P18: =IFERROR(VLOOKUP(N18,$Y$15:$AB$33,4,FALSE)*(O18/(VLOOKUP(N18,$Y$15:$AB$33,3,FALSE))),"") | Q18: =IFERROR((P18*$Z$11)/B18,"") | S18: =IFERROR(L18+Q18+($Z$8/$B$100)+($Z$9/$B$100)+($Z$3/$B$100)+($Z$2/$B$100)+($Z$4/$B$100)+($Z$5/$B$100)+($Z$6/$B$100),"") | T18: =IFERROR(ROUND(S18*'Quote Info'!$O$4+R18,2),"") | U18: =IFERROR(S18*B18,"") | V18: =IFERROR(T18*B18,"") | W18: =IFERROR(S18/((VLOOKUP(N18,'FB Data'!$A$2:$E$150,3,FALSE))*'FB Laser'!M18),"") | Y18: {=IFERROR(INDEX($Y$39:$Y$65, MATCH(0,IF(ISBLANK($Y$39:$Y$65),1,COUNTIF($Y$14:Y17, $Y$39:$Y$65)), 0)),"")} | Z18: =SUMIF($Y$39:$Y$65,Y18,$AC$39:$AC$65) -> 0 | AA18: =IFERROR(SUMIF($N$10:$N$99,Y18,$O$10:$O$99),"") -> 0 | AB18: =IFERROR(SUMIF($Y$39:$Y$65,Y18,$AD$39:$AD$65),"") -> 0 | AC18: =IFERROR(Z18*AA18*VLOOKUP(Y18,'FB Data'!$A$2:$E$150,3,FALSE),"")
G19: =IFERROR(((E19/60)*$Z$10)/B19,"") | H19: =IF(Forming!G19>0,Forming!G19,0) -> 0 | I19: =IF('Hardware Install'!E19>0,'Hardware Install'!E19,0) -> 0 | J19: =IFERROR(VLOOKUP('FB Laser'!A19,Machining!A19:G109,7,FALSE),"") | K19: =IFERROR(IF(Finishing!G19>0,VLOOKUP('FB Laser'!A19,Finishing!A19:G109,7,FALSE),""),"") | L19: =IFERROR(SUM((H19*$Z$12),G19,I19,J19,K19,'FB Data'!AM18),"") -> 0 | M19: =IFERROR((C19*D19)*0.00694,"") -> 0 | O19: =IFERROR((B19*M19)/(VLOOKUP(N19,$Y$15:$AB$33,2,FALSE)),"") | P19: =IFERROR(VLOOKUP(N19,$Y$15:$AB$33,4,FALSE)*(O19/(VLOOKUP(N19,$Y$15:$AB$33,3,FALSE))),"") | Q19: =IFERROR((P19*$Z$11)/B19,"") | S19: =IFERROR(L19+Q19+($Z$8/$B$100)+($Z$9/$B$100)+($Z$3/$B$100)+($Z$2/$B$100)+($Z$4/$B$100)+($Z$5/$B$100)+($Z$6/$B$100),"") | T19: =IFERROR(ROUND(S19*'Quote Info'!$O$4+R19,2),"") | U19: =IFERROR(S19*B19,"") | V19: =IFERROR(T19*B19,"") | W19: =IFERROR(S19/((VLOOKUP(N19,'FB Data'!$A$2:$E$150,3,FALSE))*'FB Laser'!M19),"") | Y19: {=IFERROR(INDEX($Y$39:$Y$65, MATCH(0,IF(ISBLANK($Y$39:$Y$65),1,COUNTIF($Y$14:Y18, $Y$39:$Y$65)), 0)),"")} | Z19: =SUMIF($Y$39:$Y$65,Y19,$AC$39:$AC$65) -> 0 | AA19: =IFERROR(SUMIF($N$10:$N$99,Y19,$O$10:$O$99),"") -> 0 | AB19: =IFERROR(SUMIF($Y$39:$Y$65,Y19,$AD$39:$AD$65),"") -> 0 | AC19: =IFERROR(Z19*AA19*VLOOKUP(Y19,'FB Data'!$A$2:$E$150,3,FALSE),"")
G20: =IFERROR(((E20/60)*$Z$10)/B20,"") | H20: =IF(Forming!G20>0,Forming!G20,0) -> 0 | I20: =IF('Hardware Install'!E20>0,'Hardware Install'!E20,0) -> 0 | J20: =IFERROR(VLOOKUP('FB Laser'!A20,Machining!A20:G110,7,FALSE),"") | K20: =IFERROR(IF(Finishing!G20>0,VLOOKUP('FB Laser'!A20,Finishing!A20:G110,7,FALSE),""),"") | L20: =IFERROR(SUM((H20*$Z$12),G20,I20,J20,K20,'FB Data'!AM19),"") -> 0 | M20: =IFERROR((C20*D20)*0.00694,"") -> 0 | O20: =IFERROR((B20*M20)/(VLOOKUP(N20,$Y$15:$AB$33,2,FALSE)),"") | P20: =IFERROR(VLOOKUP(N20,$Y$15:$AB$33,4,FALSE)*(O20/(VLOOKUP(N20,$Y$15:$AB$33,3,FALSE))),"") | Q20: =IFERROR((P20*$Z$11)/B20,"") | S20: =IFERROR(L20+Q20+($Z$8/$B$100)+($Z$9/$B$100)+($Z$3/$B$100)+($Z$2/$B$100)+($Z$4/$B$100)+($Z$5/$B$100)+($Z$6/$B$100),"") | T20: =IFERROR(ROUND(S20*'Quote Info'!$O$4+R20,2),"") | U20: =IFERROR(S20*B20,"") | V20: =IFERROR(T20*B20,"") | W20: =IFERROR(S20/((VLOOKUP(N20,'FB Data'!$A$2:$E$150,3,FALSE))*'FB Laser'!M20),"") | Y20: {=IFERROR(INDEX($Y$39:$Y$65, MATCH(0,IF(ISBLANK($Y$39:$Y$65),1,COUNTIF($Y$14:Y19, $Y$39:$Y$65)), 0)),"")} | Z20: =SUMIF($Y$39:$Y$65,Y20,$AC$39:$AC$65) -> 0 | AA20: =IFERROR(SUMIF($N$10:$N$99,Y20,$O$10:$O$99),"") -> 0 | AB20: =IFERROR(SUMIF($Y$39:$Y$65,Y20,$AD$39:$AD$65),"") -> 0 | AC20: =IFERROR(Z20*AA20*VLOOKUP(Y20,'FB Data'!$A$2:$E$150,3,FALSE),"")
G21: =IFERROR(((E21/60)*$Z$10)/B21,"") | H21: =IF(Forming!G21>0,Forming!G21,0) -> 0 | I21: =IF('Hardware Install'!E21>0,'Hardware Install'!E21,0) -> 0 | J21: =IFERROR(VLOOKUP('FB Laser'!A21,Machining!A21:G111,7,FALSE),"") | K21: =IFERROR(IF(Finishing!G21>0,VLOOKUP('FB Laser'!A21,Finishing!A21:G111,7,FALSE),""),"") | L21: =IFERROR(SUM((H21*$Z$12),G21,I21,J21,K21,'FB Data'!AM20),"") -> 0 | M21: =IFERROR((C21*D21)*0.00694,"") -> 0 | O21: =IFERROR((B21*M21)/(VLOOKUP(N21,$Y$15:$AB$33,2,FALSE)),"") | P21: =IFERROR(VLOOKUP(N21,$Y$15:$AB$33,4,FALSE)*(O21/(VLOOKUP(N21,$Y$15:$AB$33,3,FALSE))),"") | Q21: =IFERROR((P21*$Z$11)/B21,"") | S21: =IFERROR(L21+Q21+($Z$8/$B$100)+($Z$9/$B$100)+($Z$3/$B$100)+($Z$2/$B$100)+($Z$4/$B$100)+($Z$5/$B$100)+($Z$6/$B$100),"") | T21: =IFERROR(ROUND(S21*'Quote Info'!$O$4+R21,2),"") | U21: =IFERROR(S21*B21,"") | V21: =IFERROR(T21*B21,"") | W21: =IFERROR(S21/((VLOOKUP(N21,'FB Data'!$A$2:$E$150,3,FALSE))*'FB Laser'!M21),"") | Y21: {=IFERROR(INDEX($Y$39:$Y$65, MATCH(0,IF(ISBLANK($Y$39:$Y$65),1,COUNTIF($Y$14:Y20, $Y$39:$Y$65)), 0)),"")} | Z21: =SUMIF($Y$39:$Y$65,Y21,$AC$39:$AC$65) -> 0 | AA21: =IFERROR(SUMIF($N$10:$N$99,Y21,$O$10:$O$99),"") -> 0 | AB21: =IFERROR(SUMIF($Y$39:$Y$65,Y21,$AD$39:$AD$65),"") -> 0 | AC21: =IFERROR(Z21*AA21*VLOOKUP(Y21,'FB Data'!$A$2:$E$150,3,FALSE),"")
G22: =IFERROR(((E22/60)*$Z$10)/B22,"") | H22: =IF(Forming!G22>0,Forming!G22,0) -> 0 | I22: =IF('Hardware Install'!E22>0,'Hardware Install'!E22,0) -> 0 | J22: =IFERROR(VLOOKUP('FB Laser'!A22,Machining!A22:G112,7,FALSE),"") | K22: =IFERROR(IF(Finishing!G22>0,VLOOKUP('FB Laser'!A22,Finishing!A22:G112,7,FALSE),""),"") | L22: =IFERROR(SUM((H22*$Z$12),G22,I22,J22,K22,'FB Data'!AM21),"") -> 0 | M22: =IFERROR((C22*D22)*0.00694,"") -> 0 | O22: =IFERROR((B22*M22)/(VLOOKUP(N22,$Y$15:$AB$33,2,FALSE)),"") | P22: =IFERROR(VLOOKUP(N22,$Y$15:$AB$33,4,FALSE)*(O22/(VLOOKUP(N22,$Y$15:$AB$33,3,FALSE))),"") | Q22: =IFERROR((P22*$Z$11)/B22,"") | S22: =IFERROR(L22+Q22+($Z$8/$B$100)+($Z$9/$B$100)+($Z$3/$B$100)+($Z$2/$B$100)+($Z$4/$B$100)+($Z$5/$B$100)+($Z$6/$B$100),"") | T22: =IFERROR(ROUND(S22*'Quote Info'!$O$4+R22,2),"") | U22: =IFERROR(S22*B22,"") | V22: =IFERROR(T22*B22,"") | W22: =IFERROR(S22/((VLOOKUP(N22,'FB Data'!$A$2:$E$150,3,FALSE))*'FB Laser'!M22),"") | Y22: {=IFERROR(INDEX($Y$39:$Y$65, MATCH(0,IF(ISBLANK($Y$39:$Y$65),1,COUNTIF($Y$14:Y21, $Y$39:$Y$65)), 0)),"")} | Z22: =SUMIF($Y$39:$Y$65,Y22,$AC$39:$AC$65) -> 0 | AA22: =IFERROR(SUMIF($N$10:$N$99,Y22,$O$10:$O$99),"") -> 0 | AB22: =IFERROR(SUMIF($Y$39:$Y$65,Y22,$AD$39:$AD$65),"") -> 0 | AC22: =IFERROR(Z22*AA22*VLOOKUP(Y22,'FB Data'!$A$2:$E$150,3,FALSE),"")
G23: =IFERROR(((E23/60)*$Z$10)/B23,"") | H23: =IF(Forming!G23>0,Forming!G23,0) -> 0 | I23: =IF('Hardware Install'!E23>0,'Hardware Install'!E23,0) -> 0 | J23: =IFERROR(VLOOKUP('FB Laser'!A23,Machining!A23:G113,7,FALSE),"") | K23: =IFERROR(IF(Finishing!G23>0,VLOOKUP('FB Laser'!A23,Finishing!A23:G113,7,FALSE),""),"") | L23: =IFERROR(SUM((H23*$Z$12),G23,I23,J23,K23,'FB Data'!AM22),"") -> 0 | M23: =IFERROR((C23*D23)*0.00694,"") -> 0 | O23: =IFERROR((B23*M23)/(VLOOKUP(N23,$Y$15:$AB$33,2,FALSE)),"") | P23: =IFERROR(VLOOKUP(N23,$Y$15:$AB$33,4,FALSE)*(O23/(VLOOKUP(N23,$Y$15:$AB$33,3,FALSE))),"") | Q23: =IFERROR((P23*$Z$11)/B23,"") | S23: =IFERROR(L23+Q23+($Z$8/$B$100)+($Z$9/$B$100)+($Z$3/$B$100)+($Z$2/$B$100)+($Z$4/$B$100)+($Z$5/$B$100)+($Z$6/$B$100),"") | T23: =IFERROR(ROUND(S23*'Quote Info'!$O$4+R23,2),"") | U23: =IFERROR(S23*B23,"") | V23: =IFERROR(T23*B23,"") | W23: =IFERROR(S23/((VLOOKUP(N23,'FB Data'!$A$2:$E$150,3,FALSE))*'FB Laser'!M23),"") | Y23: {=IFERROR(INDEX($Y$39:$Y$65, MATCH(0,IF(ISBLANK($Y$39:$Y$65),1,COUNTIF($Y$14:Y22, $Y$39:$Y$65)), 0)),"")} | Z23: =SUMIF($Y$39:$Y$65,Y23,$AC$39:$AC$65) -> 0 | AA23: =IFERROR(SUMIF($N$10:$N$99,Y23,$O$10:$O$99),"") -> 0 | AB23: =IFERROR(SUMIF($Y$39:$Y$65,Y23,$AD$39:$AD$65),"") -> 0 | AC23: =IFERROR(Z23*AA23*VLOOKUP(Y23,'FB Data'!$A$2:$E$150,3,FALSE),"")
G24: =IFERROR(((E24/60)*$Z$10)/B24,"") | H24: =IF(Forming!G24>0,Forming!G24,0) -> 0 | I24: =IF('Hardware Install'!E24>0,'Hardware Install'!E24,0) -> 0 | J24: =IFERROR(VLOOKUP('FB Laser'!A24,Machining!A24:G114,7,FALSE),"") | K24: =IFERROR(IF(Finishing!G24>0,VLOOKUP('FB Laser'!A24,Finishing!A24:G114,7,FALSE),""),"") | L24: =IFERROR(SUM((H24*$Z$12),G24,I24,J24,K24,'FB Data'!AM23),"") -> 0 | M24: =IFERROR((C24*D24)*0.00694,"") -> 0 | O24: =IFERROR((B24*M24)/(VLOOKUP(N24,$Y$15:$AB$33,2,FALSE)),"") | P24: =IFERROR(VLOOKUP(N24,$Y$15:$AB$33,4,FALSE)*(O24/(VLOOKUP(N24,$Y$15:$AB$33,3,FALSE))),"") | Q24: =IFERROR((P24*$Z$11)/B24,"") | S24: =IFERROR(L24+Q24+($Z$8/$B$100)+($Z$9/$B$100)+($Z$3/$B$100)+($Z$2/$B$100)+($Z$4/$B$100)+($Z$5/$B$100)+($Z$6/$B$100),"") | T24: =IFERROR(ROUND(S24*'Quote Info'!$O$4+R24,2),"") | U24: =IFERROR(S24*B24,"") | V24: =IFERROR(T24*B24,"") | W24: =IFERROR(S24/((VLOOKUP(N24,'FB Data'!$A$2:$E$150,3,FALSE))*'FB Laser'!M24),"") | Y24: {=IFERROR(INDEX($Y$39:$Y$65, MATCH(0,IF(ISBLANK($Y$39:$Y$65),1,COUNTIF($Y$14:Y23, $Y$39:$Y$65)), 0)),"")} | Z24: =SUMIF($Y$39:$Y$65,Y24,$AC$39:$AC$65) -> 0 | AA24: =IFERROR(SUMIF($N$10:$N$99,Y24,$O$10:$O$99),"") -> 0 | AB24: =IFERROR(SUMIF($Y$39:$Y$65,Y24,$AD$39:$AD$65),"") -> 0 | AC24: =IFERROR(Z24*AA24*VLOOKUP(Y24,'FB Data'!$A$2:$E$150,3,FALSE),"")
G25: =IFERROR(((E25/60)*$Z$10)/B25,"") | H25: =IF(Forming!G25>0,Forming!G25,0) -> 0 | I25: =IF('Hardware Install'!E25>0,'Hardware Install'!E25,0) -> 0 | J25: =IFERROR(VLOOKUP('FB Laser'!A25,Machining!A25:G115,7,FALSE),"") | K25: =IFERROR(IF(Finishing!G25>0,VLOOKUP('FB Laser'!A25,Finishing!A25:G115,7,FALSE),""),"") | L25: =IFERROR(SUM((H25*$Z$12),G25,I25,J25,K25,'FB Data'!AM24),"") -> 0 | M25: =IFERROR((C25*D25)*0.00694,"") -> 0 | O25: =IFERROR((B25*M25)/(VLOOKUP(N25,$Y$15:$AB$33,2,FALSE)),"") | P25: =IFERROR(VLOOKUP(N25,$Y$15:$AB$33,4,FALSE)*(O25/(VLOOKUP(N25,$Y$15:$AB$33,3,FALSE))),"") | Q25: =IFERROR((P25*$Z$11)/B25,"") | S25: =IFERROR(L25+Q25+($Z$8/$B$100)+($Z$9/$B$100)+($Z$3/$B$100)+($Z$2/$B$100)+($Z$4/$B$100)+($Z$5/$B$100)+($Z$6/$B$100),"") | T25: =IFERROR(ROUND(S25*'Quote Info'!$O$4+R25,2),"") | U25: =IFERROR(S25*B25,"") | V25: =IFERROR(T25*B25,"") | W25: =IFERROR(S25/((VLOOKUP(N25,'FB Data'!$A$2:$E$150,3,FALSE))*'FB Laser'!M25),"") | Y25: {=IFERROR(INDEX($Y$39:$Y$65, MATCH(0,IF(ISBLANK($Y$39:$Y$65),1,COUNTIF($Y$14:Y24, $Y$39:$Y$65)), 0)),"")} | Z25: =SUMIF($Y$39:$Y$65,Y25,$AC$39:$AC$65) -> 0 | AA25: =IFERROR(SUMIF($N$10:$N$99,Y25,$O$10:$O$99),"") -> 0 | AB25: =IFERROR(SUMIF($Y$39:$Y$65,Y25,$AD$39:$AD$65),"") -> 0 | AC25: =IFERROR(Z25*AA25*VLOOKUP(Y25,'FB Data'!$A$2:$E$150,3,FALSE),"")
G26: =IFERROR(((E26/60)*$Z$10)/B26,"") | H26: =IF(Forming!G26>0,Forming!G26,0) -> 0 | I26: =IF('Hardware Install'!E26>0,'Hardware Install'!E26,0) -> 0 | J26: =IFERROR(VLOOKUP('FB Laser'!A26,Machining!A26:G116,7,FALSE),"") | K26: =IFERROR(IF(Finishing!G26>0,VLOOKUP('FB Laser'!A26,Finishing!A26:G116,7,FALSE),""),"") | L26: =IFERROR(SUM((H26*$Z$12),G26,I26,J26,K26,'FB Data'!AM25),"") -> 0 | M26: =IFERROR((C26*D26)*0.00694,"") -> 0 | O26: =IFERROR((B26*M26)/(VLOOKUP(N26,$Y$15:$AB$33,2,FALSE)),"") | P26: =IFERROR(VLOOKUP(N26,$Y$15:$AB$33,4,FALSE)*(O26/(VLOOKUP(N26,$Y$15:$AB$33,3,FALSE))),"") | Q26: =IFERROR((P26*$Z$11)/B26,"") | S26: =IFERROR(L26+Q26+($Z$8/$B$100)+($Z$9/$B$100)+($Z$3/$B$100)+($Z$2/$B$100)+($Z$4/$B$100)+($Z$5/$B$100)+($Z$6/$B$100),"") | T26: =IFERROR(ROUND(S26*'Quote Info'!$O$4+R26,2),"") | U26: =IFERROR(S26*B26,"") | V26: =IFERROR(T26*B26,"") | W26: =IFERROR(S26/((VLOOKUP(N26,'FB Data'!$A$2:$E$150,3,FALSE))*'FB Laser'!M26),"") | Y26: {=IFERROR(INDEX($Y$39:$Y$65, MATCH(0,IF(ISBLANK($Y$39:$Y$65),1,COUNTIF($Y$14:Y25, $Y$39:$Y$65)), 0)),"")} | Z26: =SUMIF($Y$39:$Y$65,Y26,$AC$39:$AC$65) -> 0 | AA26: =IFERROR(SUMIF($N$10:$N$99,Y26,$O$10:$O$99),"") -> 0 | AB26: =IFERROR(SUMIF($Y$39:$Y$65,Y26,$AD$39:$AD$65),"") -> 0 | AC26: =IFERROR(Z26*AA26*VLOOKUP(Y26,'FB Data'!$A$2:$E$150,3,FALSE),"")
... G33: =IFERROR(((E33/60)*$Z$10)/B33,"") | H33: =IF(Forming!G33>0,Forming!G33,0) -> 0 | I33: =IF('Hardware Install'!E33>0,'Hardware Install'!E33,0) -> 0 | J33: =IFERROR(VLOOKUP('FB Laser'!A33,Machining!A33:G123,7,FALSE),"") | K33: =IFERROR(IF(Finishing!G33>0,VLOOKUP('FB Laser'!A33,Finishing!A33:G123,7,FALSE),""),"") | L33: =IFERROR(SUM((H33*$Z$12),G33,I33,J33,K33,'FB Data'!AM32),"") -> 0 | M33: =IFERROR((C33*D33)*0.00694,"") -> 0 | O33: =IFERROR((B33*M33)/(VLOOKUP(N33,$Y$15:$AB$33,2,FALSE)),"") | P33: =IFERROR(VLOOKUP(N33,$Y$15:$AB$33,4,FALSE)*(O33/(VLOOKUP(N33,$Y$15:$AB$33,3,FALSE))),"") | Q33: =IFERROR((P33*$Z$11)/B33,"") | S33: =IFERROR(L33+Q33+($Z$8/$B$100)+($Z$9/$B$100)+($Z$3/$B$100)+($Z$2/$B$100)+($Z$4/$B$100)+($Z$5/$B$100)+($Z$6/$B$100),"") | T33: =IFERROR(ROUND(S33*'Quote Info'!$O$4+R33,2),"") | U33: =IFERROR(S33*B33,"") | V33: =IFERROR(T33*B33,"") | W33: =IFERROR(S33/((VLOOKUP(N33,'FB Data'!$A$2:$E$150,3,FALSE))*'FB Laser'!M33),"") | Y33: {=IFERROR(INDEX($Y$39:$Y$65, MATCH(0,IF(ISBLANK($Y$39:$Y$65),1,COUNTIF($Y$14:Y32, $Y$39:$Y$65)), 0)),"")} | Z33: =SUMIF($Y$39:$Y$65,Y33,$AC$39:$AC$65) -> 0 | AA33: =IFERROR(SUMIF($N$10:$N$99,Y33,$O$10:$O$99),"") -> 0 | AB33: =IFERROR(SUMIF($Y$39:$Y$65,Y33,$AD$39:$AD$65),"") -> 0 | AC33: =IFERROR(Z33*AA33*VLOOKUP(Y33,'FB Data'!$A$2:$E$150,3,FALSE),"")
G34: =IFERROR(((E34/60)*$Z$10)/B34,"") | H34: =IF(Forming!G34>0,Forming!G34,0) -> 0 | I34: =IF('Hardware Install'!E34>0,'Hardware Install'!E34,0) -> 0 | J34: =IFERROR(VLOOKUP('FB Laser'!A34,Machining!A34:G124,7,FALSE),"") | K34: =IFERROR(IF(Finishing!G34>0,VLOOKUP('FB Laser'!A34,Finishing!A34:G124,7,FALSE),""),"") | L34: =IFERROR(SUM((H34*$Z$12),G34,I34,J34,K34,'FB Data'!AM33),"") -> 0 | M34: =IFERROR((C34*D34)*0.00694,"") -> 0 | O34: =IFERROR((B34*M34)/(VLOOKUP(N34,$Y$15:$AB$33,2,FALSE)),"") | P34: =IFERROR(VLOOKUP(N34,$Y$15:$AB$33,4,FALSE)*(O34/(VLOOKUP(N34,$Y$15:$AB$33,3,FALSE))),"") | Q34: =IFERROR((P34*$Z$11)/B34,"") | S34: =IFERROR(L34+Q34+($Z$8/$B$100)+($Z$9/$B$100)+($Z$3/$B$100)+($Z$2/$B$100)+($Z$4/$B$100)+($Z$5/$B$100)+($Z$6/$B$100),"") | T34: =IFERROR(ROUND(S34*'Quote Info'!$O$4+R34,2),"") | U34: =IFERROR(S34*B34,"") | V34: =IFERROR(T34*B34,"") | W34: =IFERROR(S34/((VLOOKUP(N34,'FB Data'!$A$2:$E$150,3,FALSE))*'FB Laser'!M34),"") | AC34: =SUMIF(AC15:AC25,"<>#N/A") -> 0
G35: =IFERROR(((E35/60)*$Z$10)/B35,"") | H35: =IF(Forming!G35>0,Forming!G35,0) -> 0 | I35: =IF('Hardware Install'!E35>0,'Hardware Install'!E35,0) -> 0 | J35: =IFERROR(VLOOKUP('FB Laser'!A35,Machining!A35:G125,7,FALSE),"") | K35: =IFERROR(IF(Finishing!G35>0,VLOOKUP('FB Laser'!A35,Finishing!A35:G125,7,FALSE),""),"") | L35: =IFERROR(SUM((H35*$Z$12),G35,I35,J35,K35,'FB Data'!AM34),"") -> 0 | M35: =IFERROR((C35*D35)*0.00694,"") -> 0 | O35: =IFERROR((B35*M35)/(VLOOKUP(N35,$Y$15:$AB$33,2,FALSE)),"") | P35: =IFERROR(VLOOKUP(N35,$Y$15:$AB$33,4,FALSE)*(O35/(VLOOKUP(N35,$Y$15:$AB$33,3,FALSE))),"") | Q35: =IFERROR((P35*$Z$11)/B35,"") | S35: =IFERROR(L35+Q35+($Z$8/$B$100)+($Z$9/$B$100)+($Z$3/$B$100)+($Z$2/$B$100)+($Z$4/$B$100)+($Z$5/$B$100)+($Z$6/$B$100),"") | T35: =IFERROR(ROUND(S35*'Quote Info'!$O$4+R35,2),"") | U35: =IFERROR(S35*B35,"") | V35: =IFERROR(T35*B35,"") | W35: =IFERROR(S35/((VLOOKUP(N35,'FB Data'!$A$2:$E$150,3,FALSE))*'FB Laser'!M35),"")
G36: =IFERROR(((E36/60)*$Z$10)/B36,"") | H36: =IF(Forming!G36>0,Forming!G36,0) -> 0 | I36: =IF('Hardware Install'!E36>0,'Hardware Install'!E36,0) -> 0 | J36: =IFERROR(VLOOKUP('FB Laser'!A36,Machining!A36:G126,7,FALSE),"") | K36: =IFERROR(IF(Finishing!G36>0,VLOOKUP('FB Laser'!A36,Finishing!A36:G126,7,FALSE),""),"") | L36: =IFERROR(SUM((H36*$Z$12),G36,I36,J36,K36,'FB Data'!AM35),"") -> 0 | M36: =IFERROR((C36*D36)*0.00694,"") -> 0 | O36: =IFERROR((B36*M36)/(VLOOKUP(N36,$Y$15:$AB$33,2,FALSE)),"") | P36: =IFERROR(VLOOKUP(N36,$Y$15:$AB$33,4,FALSE)*(O36/(VLOOKUP(N36,$Y$15:$AB$33,3,FALSE))),"") | Q36: =IFERROR((P36*$Z$11)/B36,"") | S36: =IFERROR(L36+Q36+($Z$8/$B$100)+($Z$9/$B$100)+($Z$3/$B$100)+($Z$2/$B$100)+($Z$4/$B$100)+($Z$5/$B$100)+($Z$6/$B$100),"") | T36: =IFERROR(ROUND(S36*'Quote Info'!$O$4+R36,2),"") | U36: =IFERROR(S36*B36,"") | V36: =IFERROR(T36*B36,"") | W36: =IFERROR(S36/((VLOOKUP(N36,'FB Data'!$A$2:$E$150,3,FALSE))*'FB Laser'!M36),"")
G37: =IFERROR(((E37/60)*$Z$10)/B37,"") | H37: =IF(Forming!G37>0,Forming!G37,0) -> 0 | I37: =IF('Hardware Install'!E37>0,'Hardware Install'!E37,0) -> 0 | J37: =IFERROR(VLOOKUP('FB Laser'!A37,Machining!A37:G127,7,FALSE),"") | K37: =IFERROR(IF(Finishing!G37>0,VLOOKUP('FB Laser'!A37,Finishing!A37:G127,7,FALSE),""),"") | L37: =IFERROR(SUM((H37*$Z$12),G37,I37,J37,K37,'FB Data'!AM36),"") -> 0 | M37: =IFERROR((C37*D37)*0.00694,"") -> 0 | O37: =IFERROR((B37*M37)/(VLOOKUP(N37,$Y$15:$AB$33,2,FALSE)),"") | P37: =IFERROR(VLOOKUP(N37,$Y$15:$AB$33,4,FALSE)*(O37/(VLOOKUP(N37,$Y$15:$AB$33,3,FALSE))),"") | Q37: =IFERROR((P37*$Z$11)/B37,"") | S37: =IFERROR(L37+Q37+($Z$8/$B$100)+($Z$9/$B$100)+($Z$3/$B$100)+($Z$2/$B$100)+($Z$4/$B$100)+($Z$5/$B$100)+($Z$6/$B$100),"") | T37: =IFERROR(ROUND(S37*'Quote Info'!$O$4+R37,2),"") | U37: =IFERROR(S37*B37,"") | V37: =IFERROR(T37*B37,"") | W37: =IFERROR(S37/((VLOOKUP(N37,'FB Data'!$A$2:$E$150,3,FALSE))*'FB Laser'!M37),"") | Y37: Material Required
G38: =IFERROR(((E38/60)*$Z$10)/B38,"") | H38: =IF(Forming!G38>0,Forming!G38,0) -> 0 | I38: =IF('Hardware Install'!E38>0,'Hardware Install'!E38,0) -> 0 | J38: =IFERROR(VLOOKUP('FB Laser'!A38,Machining!A38:G128,7,FALSE),"") | K38: =IFERROR(IF(Finishing!G38>0,VLOOKUP('FB Laser'!A38,Finishing!A38:G128,7,FALSE),""),"") | L38: =IFERROR(SUM((H38*$Z$12),G38,I38,J38,K38,'FB Data'!AM37),"") -> 0 | M38: =IFERROR((C38*D38)*0.00694,"") -> 0 | O38: =IFERROR((B38*M38)/(VLOOKUP(N38,$Y$15:$AB$33,2,FALSE)),"") | P38: =IFERROR(VLOOKUP(N38,$Y$15:$AB$33,4,FALSE)*(O38/(VLOOKUP(N38,$Y$15:$AB$33,3,FALSE))),"") | Q38: =IFERROR((P38*$Z$11)/B38,"") | S38: =IFERROR(L38+Q38+($Z$8/$B$100)+($Z$9/$B$100)+($Z$3/$B$100)+($Z$2/$B$100)+($Z$4/$B$100)+($Z$5/$B$100)+($Z$6/$B$100),"") | T38: =IFERROR(ROUND(S38*'Quote Info'!$O$4+R38,2),"") | U38: =IFERROR(S38*B38,"") | V38: =IFERROR(T38*B38,"") | W38: =IFERROR(S38/((VLOOKUP(N38,'FB Data'!$A$2:$E$150,3,FALSE))*'FB Laser'!M38),"") | Y38: Material ID | Z38: Qty | AA38: Width (in) | AB38: Length (in) | AC38: Total Sqft | AD38: Material Cost
G39: =IFERROR(((E39/60)*$Z$10)/B39,"") | H39: =IF(Forming!G39>0,Forming!G39,0) -> 0 | I39: =IF('Hardware Install'!E39>0,'Hardware Install'!E39,0) -> 0 | J39: =IFERROR(VLOOKUP('FB Laser'!A39,Machining!A39:G129,7,FALSE),"") | K39: =IFERROR(IF(Finishing!G39>0,VLOOKUP('FB Laser'!A39,Finishing!A39:G129,7,FALSE),""),"") | L39: =IFERROR(SUM((H39*$Z$12),G39,I39,J39,K39,'FB Data'!AM38),"") -> 0 | M39: =IFERROR((C39*D39)*0.00694,"") -> 0 | O39: =IFERROR((B39*M39)/(VLOOKUP(N39,$Y$15:$AB$33,2,FALSE)),"") | P39: =IFERROR(VLOOKUP(N39,$Y$15:$AB$33,4,FALSE)*(O39/(VLOOKUP(N39,$Y$15:$AB$33,3,FALSE))),"") | Q39: =IFERROR((P39*$Z$11)/B39,"") | S39: =IFERROR(L39+Q39+($Z$8/$B$100)+($Z$9/$B$100)+($Z$3/$B$100)+($Z$2/$B$100)+($Z$4/$B$100)+($Z$5/$B$100)+($Z$6/$B$100),"") | T39: =IFERROR(ROUND(S39*'Quote Info'!$O$4+R39,2),"") | U39: =IFERROR(S39*B39,"") | V39: =IFERROR(T39*B39,"") | W39: =IFERROR(S39/((VLOOKUP(N39,'FB Data'!$A$2:$E$150,3,FALSE))*'FB Laser'!M39),"") | AC39: =IFERROR((AA39/12)*(AB39/12)*Z39,"") -> 0 | AD39: =IFERROR(IF($Z$7="JWMCD",VLOOKUP(Y39,'FB Data'!$A$2:$E$151,3,FALSE)*VLOOKUP(Y39,'FB Data'!$A$2:$E$151,5,FALSE)*AC39,IF($Z$7="Customer Supplied",0,"Need Input")),"")
G40: =IFERROR(((E40/60)*$Z$10)/B40,"") | H40: =IF(Forming!G40>0,Forming!G40,0) -> 0 | I40: =IF('Hardware Install'!E40>0,'Hardware Install'!E40,0) -> 0 | J40: =IFERROR(VLOOKUP('FB Laser'!A40,Machining!A40:G130,7,FALSE),"") | K40: =IFERROR(IF(Finishing!G40>0,VLOOKUP('FB Laser'!A40,Finishing!A40:G130,7,FALSE),""),"") | L40: =IFERROR(SUM((H40*$Z$12),G40,I40,J40,K40,'FB Data'!AM39),"") -> 0 | M40: =IFERROR((C40*D40)*0.00694,"") -> 0 | O40: =IFERROR((B40*M40)/(VLOOKUP(N40,$Y$15:$AB$33,2,FALSE)),"") | P40: =IFERROR(VLOOKUP(N40,$Y$15:$AB$33,4,FALSE)*(O40/(VLOOKUP(N40,$Y$15:$AB$33,3,FALSE))),"") | Q40: =IFERROR((P40*$Z$11)/B40,"") | S40: =IFERROR(L40+Q40+($Z$8/$B$100)+($Z$9/$B$100)+($Z$3/$B$100)+($Z$2/$B$100)+($Z$4/$B$100)+($Z$5/$B$100)+($Z$6/$B$100),"") | T40: =IFERROR(ROUND(S40*'Quote Info'!$O$4+R40,2),"") | U40: =IFERROR(S40*B40,"") | V40: =IFERROR(T40*B40,"") | W40: =IFERROR(S40/((VLOOKUP(N40,'FB Data'!$A$2:$E$150,3,FALSE))*'FB Laser'!M40),"") | AC40: =IFERROR((AA40/12)*(AB40/12)*Z40,"") -> 0 | AD40: =IFERROR(IF($Z$7="JWMCD",VLOOKUP(Y40,'FB Data'!$A$2:$E$151,3,FALSE)*VLOOKUP(Y40,'FB Data'!$A$2:$E$151,5,FALSE)*AC40,IF($Z$7="Customer Supplied",0,"Need Input")),"")
G41: =IFERROR(((E41/60)*$Z$10)/B41,"") | H41: =IF(Forming!G41>0,Forming!G41,0) -> 0 | I41: =IF('Hardware Install'!E41>0,'Hardware Install'!E41,0) -> 0 | J41: =IFERROR(VLOOKUP('FB Laser'!A41,Machining!A41:G131,7,FALSE),"") | K41: =IFERROR(IF(Finishing!G41>0,VLOOKUP('FB Laser'!A41,Finishing!A41:G131,7,FALSE),""),"") | L41: =IFERROR(SUM((H41*$Z$12),G41,I41,J41,K41,'FB Data'!AM40),"") -> 0 | M41: =IFERROR((C41*D41)*0.00694,"") -> 0 | O41: =IFERROR((B41*M41)/(VLOOKUP(N41,$Y$15:$AB$33,2,FALSE)),"") | P41: =IFERROR(VLOOKUP(N41,$Y$15:$AB$33,4,FALSE)*(O41/(VLOOKUP(N41,$Y$15:$AB$33,3,FALSE))),"") | Q41: =IFERROR((P41*$Z$11)/B41,"") | S41: =IFERROR(L41+Q41+($Z$8/$B$100)+($Z$9/$B$100)+($Z$3/$B$100)+($Z$2/$B$100)+($Z$4/$B$100)+($Z$5/$B$100)+($Z$6/$B$100),"") | T41: =IFERROR(ROUND(S41*'Quote Info'!$O$4+R41,2),"") | U41: =IFERROR(S41*B41,"") | V41: =IFERROR(T41*B41,"") | W41: =IFERROR(S41/((VLOOKUP(N41,'FB Data'!$A$2:$E$150,3,FALSE))*'FB Laser'!M41),"") | AC41: =IFERROR((AA41/12)*(AB41/12)*Z41,"") -> 0 | AD41: =IFERROR(IF($Z$7="JWMCD",VLOOKUP(Y41,'FB Data'!$A$2:$E$151,3,FALSE)*VLOOKUP(Y41,'FB Data'!$A$2:$E$151,5,FALSE)*AC41,IF($Z$7="Customer Supplied",0,"Need Input")),"")
G42: =IFERROR(((E42/60)*$Z$10)/B42,"") | H42: =IF(Forming!G42>0,Forming!G42,0) -> 0 | I42: =IF('Hardware Install'!E42>0,'Hardware Install'!E42,0) -> 0 | J42: =IFERROR(VLOOKUP('FB Laser'!A42,Machining!A42:G132,7,FALSE),"") | K42: =IFERROR(IF(Finishing!G42>0,VLOOKUP('FB Laser'!A42,Finishing!A42:G132,7,FALSE),""),"") | L42: =IFERROR(SUM((H42*$Z$12),G42,I42,J42,K42,'FB Data'!AM41),"") -> 0 | M42: =IFERROR((C42*D42)*0.00694,"") -> 0 | O42: =IFERROR((B42*M42)/(VLOOKUP(N42,$Y$15:$AB$33,2,FALSE)),"") | P42: =IFERROR(VLOOKUP(N42,$Y$15:$AB$33,4,FALSE)*(O42/(VLOOKUP(N42,$Y$15:$AB$33,3,FALSE))),"") | Q42: =IFERROR((P42*$Z$11)/B42,"") | S42: =IFERROR(L42+Q42+($Z$8/$B$100)+($Z$9/$B$100)+($Z$3/$B$100)+($Z$2/$B$100)+($Z$4/$B$100)+($Z$5/$B$100)+($Z$6/$B$100),"") | T42: =IFERROR(ROUND(S42*'Quote Info'!$O$4+R42,2),"") | U42: =IFERROR(S42*B42,"") | V42: =IFERROR(T42*B42,"") | W42: =IFERROR(S42/((VLOOKUP(N42,'FB Data'!$A$2:$E$150,3,FALSE))*'FB Laser'!M42),"") | AC42: =IFERROR((AA42/12)*(AB42/12)*Z42,"") -> 0 | AD42: =IFERROR(IF($Z$7="JWMCD",VLOOKUP(Y42,'FB Data'!$A$2:$E$151,3,FALSE)*VLOOKUP(Y42,'FB Data'!$A$2:$E$151,5,FALSE)*AC42,IF($Z$7="Customer Supplied",0,"Need Input")),"")
G43: =IFERROR(((E43/60)*$Z$10)/B43,"") | H43: =IF(Forming!G43>0,Forming!G43,0) -> 0 | I43: =IF('Hardware Install'!E43>0,'Hardware Install'!E43,0) -> 0 | J43: =IFERROR(VLOOKUP('FB Laser'!A43,Machining!A43:G133,7,FALSE),"") | K43: =IFERROR(IF(Finishing!G43>0,VLOOKUP('FB Laser'!A43,Finishing!A43:G133,7,FALSE),""),"") | L43: =IFERROR(SUM((H43*$Z$12),G43,I43,J43,K43,'FB Data'!AM42),"") -> 0 | M43: =IFERROR((C43*D43)*0.00694,"") -> 0 | O43: =IFERROR((B43*M43)/(VLOOKUP(N43,$Y$15:$AB$33,2,FALSE)),"") | P43: =IFERROR(VLOOKUP(N43,$Y$15:$AB$33,4,FALSE)*(O43/(VLOOKUP(N43,$Y$15:$AB$33,3,FALSE))),"") | Q43: =IFERROR((P43*$Z$11)/B43,"") | S43: =IFERROR(L43+Q43+($Z$8/$B$100)+($Z$9/$B$100)+($Z$3/$B$100)+($Z$2/$B$100)+($Z$4/$B$100)+($Z$5/$B$100)+($Z$6/$B$100),"") | T43: =IFERROR(ROUND(S43*'Quote Info'!$O$4+R43,2),"") | U43: =IFERROR(S43*B43,"") | V43: =IFERROR(T43*B43,"") | W43: =IFERROR(S43/((VLOOKUP(N43,'FB Data'!$A$2:$E$150,3,FALSE))*'FB Laser'!M43),"") | AC43: =IFERROR((AA43/12)*(AB43/12)*Z43,"") -> 0 | AD43: =IFERROR(IF($Z$7="JWMCD",VLOOKUP(Y43,'FB Data'!$A$2:$E$151,3,FALSE)*VLOOKUP(Y43,'FB Data'!$A$2:$E$151,5,FALSE)*AC43,IF($Z$7="Customer Supplied",0,"Need Input")),"")
G44: =IFERROR(((E44/60)*$Z$10)/B44,"") | H44: =IF(Forming!G44>0,Forming!G44,0) -> 0 | I44: =IF('Hardware Install'!E44>0,'Hardware Install'!E44,0) -> 0 | J44: =IFERROR(VLOOKUP('FB Laser'!A44,Machining!A44:G134,7,FALSE),"") | K44: =IFERROR(IF(Finishing!G44>0,VLOOKUP('FB Laser'!A44,Finishing!A44:G134,7,FALSE),""),"") | L44: =IFERROR(SUM((H44*$Z$12),G44,I44,J44,K44,'FB Data'!AM43),"") -> 0 | M44: =IFERROR((C44*D44)*0.00694,"") -> 0 | O44: =IFERROR((B44*M44)/(VLOOKUP(N44,$Y$15:$AB$33,2,FALSE)),"") | P44: =IFERROR(VLOOKUP(N44,$Y$15:$AB$33,4,FALSE)*(O44/(VLOOKUP(N44,$Y$15:$AB$33,3,FALSE))),"") | Q44: =IFERROR((P44*$Z$11)/B44,"") | S44: =IFERROR(L44+Q44+($Z$8/$B$100)+($Z$9/$B$100)+($Z$3/$B$100)+($Z$2/$B$100)+($Z$4/$B$100)+($Z$5/$B$100)+($Z$6/$B$100),"") | T44: =IFERROR(ROUND(S44*'Quote Info'!$O$4+R44,2),"") | U44: =IFERROR(S44*B44,"") | V44: =IFERROR(T44*B44,"") | W44: =IFERROR(S44/((VLOOKUP(N44,'FB Data'!$A$2:$E$150,3,FALSE))*'FB Laser'!M44),"") | AC44: =IFERROR((AA44/12)*(AB44/12)*Z44,"") -> 0 | AD44: =IFERROR(IF($Z$7="JWMCD",VLOOKUP(Y44,'FB Data'!$A$2:$E$151,3,FALSE)*VLOOKUP(Y44,'FB Data'!$A$2:$E$151,5,FALSE)*AC44,IF($Z$7="Customer Supplied",0,"Need Input")),"")
G45: =IFERROR(((E45/60)*$Z$10)/B45,"") | H45: =IF(Forming!G45>0,Forming!G45,0) -> 0 | I45: =IF('Hardware Install'!E45>0,'Hardware Install'!E45,0) -> 0 | J45: =IFERROR(VLOOKUP('FB Laser'!A45,Machining!A45:G135,7,FALSE),"") | K45: =IFERROR(IF(Finishing!G45>0,VLOOKUP('FB Laser'!A45,Finishing!A45:G135,7,FALSE),""),"") | L45: =IFERROR(SUM((H45*$Z$12),G45,I45,J45,K45,'FB Data'!AM44),"") -> 0 | M45: =IFERROR((C45*D45)*0.00694,"") -> 0 | O45: =IFERROR((B45*M45)/(VLOOKUP(N45,$Y$15:$AB$33,2,FALSE)),"") | P45: =IFERROR(VLOOKUP(N45,$Y$15:$AB$33,4,FALSE)*(O45/(VLOOKUP(N45,$Y$15:$AB$33,3,FALSE))),"") | Q45: =IFERROR((P45*$Z$11)/B45,"") | S45: =IFERROR(L45+Q45+($Z$8/$B$100)+($Z$9/$B$100)+($Z$3/$B$100)+($Z$2/$B$100)+($Z$4/$B$100)+($Z$5/$B$100)+($Z$6/$B$100),"") | T45: =IFERROR(ROUND(S45*'Quote Info'!$O$4+R45,2),"") | U45: =IFERROR(S45*B45,"") | V45: =IFERROR(T45*B45,"") | W45: =IFERROR(S45/((VLOOKUP(N45,'FB Data'!$A$2:$E$150,3,FALSE))*'FB Laser'!M45),"") | AC45: =IFERROR((AA45/12)*(AB45/12)*Z45,"") -> 0 | AD45: =IFERROR(IF($Z$7="JWMCD",VLOOKUP(Y45,'FB Data'!$A$2:$E$151,3,FALSE)*VLOOKUP(Y45,'FB Data'!$A$2:$E$151,5,FALSE)*AC45,IF($Z$7="Customer Supplied",0,"Need Input")),"")
G46: =IFERROR(((E46/60)*$Z$10)/B46,"") | H46: =IF(Forming!G46>0,Forming!G46,0) -> 0 | I46: =IF('Hardware Install'!E46>0,'Hardware Install'!E46,0) -> 0 | J46: =IFERROR(VLOOKUP('FB Laser'!A46,Machining!A46:G136,7,FALSE),"") | K46: =IFERROR(IF(Finishing!G46>0,VLOOKUP('FB Laser'!A46,Finishing!A46:G136,7,FALSE),""),"") | L46: =IFERROR(SUM((H46*$Z$12),G46,I46,J46,K46,'FB Data'!AM45),"") -> 0 | M46: =IFERROR((C46*D46)*0.00694,"") -> 0 | O46: =IFERROR((B46*M46)/(VLOOKUP(N46,$Y$15:$AB$33,2,FALSE)),"") | P46: =IFERROR(VLOOKUP(N46,$Y$15:$AB$33,4,FALSE)*(O46/(VLOOKUP(N46,$Y$15:$AB$33,3,FALSE))),"") | Q46: =IFERROR((P46*$Z$11)/B46,"") | S46: =IFERROR(L46+Q46+($Z$8/$B$100)+($Z$9/$B$100)+($Z$3/$B$100)+($Z$2/$B$100)+($Z$4/$B$100)+($Z$5/$B$100)+($Z$6/$B$100),"") | T46: =IFERROR(ROUND(S46*'Quote Info'!$O$4+R46,2),"") | U46: =IFERROR(S46*B46,"") | V46: =IFERROR(T46*B46,"") | W46: =IFERROR(S46/((VLOOKUP(N46,'FB Data'!$A$2:$E$150,3,FALSE))*'FB Laser'!M46),"") | AC46: =IFERROR((AA46/12)*(AB46/12)*Z46,"") -> 0 | AD46: =IFERROR(IF($Z$7="JWMCD",VLOOKUP(Y46,'FB Data'!$A$2:$E$151,3,FALSE)*VLOOKUP(Y46,'FB Data'!$A$2:$E$151,5,FALSE)*AC46,IF($Z$7="Customer Supplied",0,"Need Input")),"")
...

Sheet Tube Laser
AC1: Notes
AA2: Outsource | AB2: 0
AA3: Programming Fee | AB3: 60
AA4: QC | AB4: 0
AA5: Welding | AB5: =IF(Welding!G10="Tube",Welding!E10+Welding!D6,IF(Welding!G10="Flat&Tube",(Welding!E10+Welding!D6)/2,0)) -> 0
AA6: Material Source | AB6: JWMCD | AD6: User Defined
AA7: Pallet Charge | AB7: =IF(AC7="Default",(ROUNDUP((AE25/1500),0)*30),IF(AC7="User Defined",AD7,"Need Input")) -> 0 | AC7: Default | AD7: 0
A8: dwg# | B8: Qty | C8: Length (in) | D8: Tube Laser Each (sec) | E8: Bevel | F8: Etch | G8: Tap Holes | H8: Seam | I8: Notes? | J8: Laser Cost (Each) | K8: Tube Bending (Each) | L8: Machining (Each) | M8: Finishing (Each) | N8: Labor (Each) | O8: linear ft (Each) | P8: Material ID | Q8: % Material Used | R8: Material Cost (LOT) | S8: Material PRICE (EACH) | T8: Adjustment | U8: Total Cost (Each) | V8: Total Price (Each) | W8: Lot Cost | X8: Lot Price | Y8: Cost/Lbs | AA8: Delivery Charge | AB8: =IF(AC8="Delivery",ROUNDUP((AE25/8000),0)*100,IF(AC8="Will-Call",0,"Need Input")) -> 0 | AC8: Delivery
J9: =IFERROR((((D9)/60)/60)*$AB$9,"") -> 0 | K9: ='Tube Bending'!E9 -> 0 | L9: =IFERROR(VLOOKUP('Tube Laser'!A9,Machining!A10:G100,7,FALSE),"") | M9: =IFERROR(IF(Finishing!G10>0,VLOOKUP('Tube Laser'!A9,Finishing!A10:G100,7,FALSE),0),"") -> 0 | N9: =SUM(J9,K9,L9,M9,'FB Data'!AR9) -> 0 | O9: =C9/12 -> 0 | Q9: =IFERROR((B9*O9)/(VLOOKUP(P9,$AA$14:$AD$24,2,FALSE)),"") | R9: =IFERROR(VLOOKUP(P9,$AA$14:$AD$24,4,FALSE)*(Q9/(VLOOKUP(P9,$AA$14:$AD$24,3,FALSE))),"") | S9: =IFERROR((R9*$AB$10)/B9,"") | U9: =IFERROR(N9+S9+'FB Data'!AE9+'FB Data'!AF9+'FB Data'!AG9+'FB Data'!AH9+($AB$7/$B$99)+($AB$8/$B$99)+($AB$3/$B$99)+($AB$2/$B$99)+($AB$4/$B$99)+($AB$5/$B$99),"") | V9: =IFERROR(ROUND(U9*'Quote Info'!$O$4+T9,2),"") | W9: =IFERROR(U9*B9,"") | X9: =IFERROR(V9*B9,"") | Y9: =IFERROR(U9/((VLOOKUP(P9,'TL Data'!$A$2:$E$1226,3,FALSE))*'Tube Laser'!O9),"") | AA9: Tube Laser/Hr (Cost) | AB9: 188.17 | AC9: =AB9*'Quote Info'!O4 -> 255.9112
J10: =IFERROR((((D10)/60)/60)*$AB$9,"") -> 0 | K10: ='Tube Bending'!E10 -> 0 | L10: =IFERROR(VLOOKUP('Tube Laser'!A10,Machining!A11:G101,7,FALSE),"") | M10: =IFERROR(IF(Finishing!G11>0,VLOOKUP('Tube Laser'!A10,Finishing!A11:G101,7,FALSE),0),"") -> 0 | N10: =SUM(J10,K10,L10,M10,'FB Data'!AR10) -> 0 | O10: =C10/12 -> 0 | Q10: =IFERROR((B10*O10)/(VLOOKUP(P10,$AA$14:$AD$24,2,FALSE)),"") | R10: =IFERROR(VLOOKUP(P10,$AA$14:$AD$24,4,FALSE)*(Q10/(VLOOKUP(P10,$AA$14:$AD$24,3,FALSE))),"") | S10: =IFERROR((R10*$AB$10)/B10,"") | U10: =IFERROR(N10+S10+'FB Data'!AE10+'FB Data'!AF10+'FB Data'!AG10+'FB Data'!AH10+($AB$7/$B$99)+($AB$8/$B$99)+($AB$3/$B$99)+($AB$2/$B$99)+($AB$4/$B$99)+($AB$5/$B$99),"") | V10: =IFERROR(ROUND(U10*'Quote Info'!$O$4+T10,2),"") | W10: =IFERROR(U10*B10,"") | X10: =IFERROR(V10*B10,"") | Y10: =IFERROR(U10/((VLOOKUP(P10,'TL Data'!$A$2:$E$1226,3,FALSE))*'Tube Laser'!O10),"") | AA10: Material Mark-Up | AB10: 1
J11: =IFERROR((((D11)/60)/60)*$AB$9,"") -> 0 | K11: ='Tube Bending'!E11 -> 0 | L11: =IFERROR(VLOOKUP('Tube Laser'!A11,Machining!A12:G102,7,FALSE),"") | M11: =IFERROR(IF(Finishing!G12>0,VLOOKUP('Tube Laser'!A11,Finishing!A12:G102,7,FALSE),0),"") -> 0 | N11: =SUM(J11,K11,L11,M11,'FB Data'!AR11) -> 0 | O11: =C11/12 -> 0 | Q11: =IFERROR((B11*O11)/(VLOOKUP(P11,$AA$14:$AD$24,2,FALSE)),"") | R11: =IFERROR(VLOOKUP(P11,$AA$14:$AD$24,4,FALSE)*(Q11/(VLOOKUP(P11,$AA$14:$AD$24,3,FALSE))),"") | S11: =IFERROR((R11*$AB$10)/B11,"") | U11: =IFERROR(N11+S11+'FB Data'!AE11+'FB Data'!AF11+'FB Data'!AG11+'FB Data'!AH11+($AB$7/$B$99)+($AB$8/$B$99)+($AB$3/$B$99)+($AB$2/$B$99)+($AB$4/$B$99)+($AB$5/$B$99),"") | V11: =IFERROR(ROUND(U11*'Quote Info'!$O$4+T11,2),"") | W11: =IFERROR(U11*B11,"") | X11: =IFERROR(V11*B11,"") | Y11: =IFERROR(U11/((VLOOKUP(P11,'TL Data'!$A$2:$E$1226,3,FALSE))*'Tube Laser'!O11),"")
J12: =IFERROR((((D12)/60)/60)*$AB$9,"") -> 0 | K12: ='Tube Bending'!E12 -> 0 | L12: =IFERROR(VLOOKUP('Tube Laser'!A12,Machining!A13:G103,7,FALSE),"") | M12: =IFERROR(IF(Finishing!G13>0,VLOOKUP('Tube Laser'!A12,Finishing!A13:G103,7,FALSE),0),"") -> 0 | N12: =SUM(J12,K12,L12,M12,'FB Data'!AR12) -> 0 | O12: =C12/12 -> 0 | Q12: =IFERROR((B12*O12)/(VLOOKUP(P12,$AA$14:$AD$24,2,FALSE)),"") | R12: =IFERROR(VLOOKUP(P12,$AA$14:$AD$24,4,FALSE)*(Q12/(VLOOKUP(P12,$AA$14:$AD$24,3,FALSE))),"") | S12: =IFERROR((R12*$AB$10)/B12,"") | U12: =IFERROR(N12+S12+'FB Data'!AE12+'FB Data'!AF12+'FB Data'!AG12+'FB Data'!AH12+($AB$7/$B$99)+($AB$8/$B$99)+($AB$3/$B$99)+($AB$2/$B$99)+($AB$4/$B$99)+($AB$5/$B$99),"") | V12: =IFERROR(ROUND(U12*'Quote Info'!$O$4+T12,2),"") | W12: =IFERROR(U12*B12,"") | X12: =IFERROR(V12*B12,"") | Y12: =IFERROR(U12/((VLOOKUP(P12,'TL Data'!$A$2:$E$1226,3,FALSE))*'Tube Laser'!O12),"")
J13: =IFERROR((((D13)/60)/60)*$AB$9,"") -> 0 | K13: ='Tube Bending'!E13 -> 0 | L13: =IFERROR(VLOOKUP('Tube Laser'!A13,Machining!A14:G104,7,FALSE),"") | M13: =IFERROR(IF(Finishing!G14>0,VLOOKUP('Tube Laser'!A13,Finishing!A14:G104,7,FALSE),0),"") -> 0 | N13: =SUM(J13,K13,L13,M13,'FB Data'!AR13) -> 0 | O13: =C13/12 -> 0 | Q13: =IFERROR((B13*O13)/(VLOOKUP(P13,$AA$14:$AD$24,2,FALSE)),"") | R13: =IFERROR(VLOOKUP(P13,$AA$14:$AD$24,4,FALSE)*(Q13/(VLOOKUP(P13,$AA$14:$AD$24,3,FALSE))),"") | S13: =IFERROR((R13*$AB$10)/B13,"") | U13: =IFERROR(N13+S13+'FB Data'!AE13+'FB Data'!AF13+'FB Data'!AG13+'FB Data'!AH13+($AB$7/$B$99)+($AB$8/$B$99)+($AB$3/$B$99)+($AB$2/$B$99)+($AB$4/$B$99)+($AB$5/$B$99),"") | V13: =IFERROR(ROUND(U13*'Quote Info'!$O$4+T13,2),"") | W13: =IFERROR(U13*B13,"") | X13: =IFERROR(V13*B13,"") | Y13: =IFERROR(U13/((VLOOKUP(P13,'TL Data'!$A$2:$E$1226,3,FALSE))*'Tube Laser'!O13),"") | AA13: Material ID | AB13: Total Linear ft | AC13: Yield % | AD13: Total Cost | AE13: Total Weight (lbs)
J14: =IFERROR((((D14)/60)/60)*$AB$9,"") -> 0 | K14: ='Tube Bending'!E14 -> 0 | L14: =IFERROR(VLOOKUP('Tube Laser'!A14,Machining!A15:G105,7,FALSE),"") | M14: =IFERROR(IF(Finishing!G15>0,VLOOKUP('Tube Laser'!A14,Finishing!A15:G105,7,FALSE),0),"") -> 0 | N14: =SUM(J14,K14,L14,M14,'FB Data'!AR14) -> 0 | O14: =C14/12 -> 0 | Q14: =IFERROR((B14*O14)/(VLOOKUP(P14,$AA$14:$AD$24,2,FALSE)),"") | R14: =IFERROR(VLOOKUP(P14,$AA$14:$AD$24,4,FALSE)*(Q14/(VLOOKUP(P14,$AA$14:$AD$24,3,FALSE))),"") | S14: =IFERROR((R14*$AB$10)/B14,"") | U14: =IFERROR(N14+S14+'FB Data'!AE14+'FB Data'!AF14+'FB Data'!AG14+'FB Data'!AH14+($AB$7/$B$99)+($AB$8/$B$99)+($AB$3/$B$99)+($AB$2/$B$99)+($AB$4/$B$99)+($AB$5/$B$99),"") | V14: =IFERROR(ROUND(U14*'Quote Info'!$O$4+T14,2),"") | W14: =IFERROR(U14*B14,"") | X14: =IFERROR(V14*B14,"") | Y14: =IFERROR(U14/((VLOOKUP(P14,'TL Data'!$A$2:$E$1226,3,FALSE))*'Tube Laser'!O14),"") | AA14: {=IFERROR(INDEX($AA$30:$AA$56, MATCH(0,IF(ISBLANK($AA$30:$AA$56),1,COUNTIF($AA$13:AA13, $AA$30:$AA$56)), 0)),"")} | AB14: =SUMIF($AA$30:$AA$56,AA14,$AD$30:$AD$56) -> 0 | AC14: =SUMIF($P$9:$P$98,AA14,$Q$9:$Q$98) -> 0 | AD14: =SUMIF($AA$30:$AA$56,AA14,$AE$30:$AE$56) -> 0 | AE14: =IFERROR(AB14*AC14*VLOOKUP(AA14,'TL Data'!$A$2:$E$1226,3,FALSE),"")
J15: =IFERROR((((D15)/60)/60)*$AB$9,"") -> 0 | K15: ='Tube Bending'!E15 -> 0 | L15: =IFERROR(VLOOKUP('Tube Laser'!A15,Machining!A16:G106,7,FALSE),"") | M15: =IFERROR(IF(Finishing!G16>0,VLOOKUP('Tube Laser'!A15,Finishing!A16:G106,7,FALSE),0),"") -> 0 | N15: =SUM(J15,K15,L15,M15,'FB Data'!AR15) -> 0 | O15: =C15/12 -> 0 | Q15: =IFERROR((B15*O15)/(VLOOKUP(P15,$AA$14:$AD$24,2,FALSE)),"") | R15: =IFERROR(VLOOKUP(P15,$AA$14:$AD$24,4,FALSE)*(Q15/(VLOOKUP(P15,$AA$14:$AD$24,3,FALSE))),"") | S15: =IFERROR((R15*$AB$10)/B15,"") | U15: =IFERROR(N15+S15+'FB Data'!AE15+'FB Data'!AF15+'FB Data'!AG15+'FB Data'!AH15+($AB$7/$B$99)+($AB$8/$B$99)+($AB$3/$B$99)+($AB$2/$B$99)+($AB$4/$B$99)+($AB$5/$B$99),"") | V15: =IFERROR(ROUND(U15*'Quote Info'!$O$4+T15,2),"") | W15: =IFERROR(U15*B15,"") | X15: =IFERROR(V15*B15,"") | Y15: =IFERROR(U15/((VLOOKUP(P15,'TL Data'!$A$2:$E$1226,3,FALSE))*'Tube Laser'!O15),"") | AA15: {=IFERROR(INDEX($AA$30:$AA$56, MATCH(0,IF(ISBLANK($AA$30:$AA$56),1,COUNTIF($AA$13:AA14, $AA$30:$AA$56)), 0)),"")} | AB15: =SUMIF($AA$30:$AA$56,AA15,$AD$30:$AD$56) -> 0 | AC15: =SUMIF($P$9:$P$98,AA15,$Q$9:$Q$98) -> 0 | AD15: =SUMIF($AA$30:$AA$56,AA15,$AE$30:$AE$56) -> 0 | AE15: =IFERROR(AB15*AC15*VLOOKUP(AA15,'TL Data'!$A$2:$E$1226,3,FALSE),"")
J16: =IFERROR((((D16)/60)/60)*$AB$9,"") -> 0 | K16: ='Tube Bending'!E16 -> 0 | L16: =IFERROR(VLOOKUP('Tube Laser'!A16,Machining!A17:G107,7,FALSE),"") | M16: =IFERROR(IF(Finishing!G17>0,VLOOKUP('Tube Laser'!A16,Finishing!A17:G107,7,FALSE),0),"") -> 0 | N16: =SUM(J16,K16,L16,M16,'FB Data'!AR16) -> 0 | O16: =C16/12 -> 0 | Q16: =IFERROR((B16*O16)/(VLOOKUP(P16,$AA$14:$AD$24,2,FALSE)),"") | R16: =IFERROR(VLOOKUP(P16,$AA$14:$AD$24,4,FALSE)*(Q16/(VLOOKUP(P16,$AA$14:$AD$24,3,FALSE))),"") | S16: =IFERROR((R16*$AB$10)/B16,"") | U16: =IFERROR(N16+S16+'FB Data'!AE16+'FB Data'!AF16+'FB Data'!AG16+'FB Data'!AH16+($AB$7/$B$99)+($AB$8/$B$99)+($AB$3/$B$99)+($AB$2/$B$99)+($AB$4/$B$99)+($AB$5/$B$99),"") | V16: =IFERROR(ROUND(U16*'Quote Info'!$O$4+T16,2),"") | W16: =IFERROR(U16*B16,"") | X16: =IFERROR(V16*B16,"") | Y16: =IFERROR(U16/((VLOOKUP(P16,'TL Data'!$A$2:$E$1226,3,FALSE))*'Tube Laser'!O16),"") | AA16: {=IFERROR(INDEX($AA$30:$AA$56, MATCH(0,IF(ISBLANK($AA$30:$AA$56),1,COUNTIF($AA$13:AA15, $AA$30:$AA$56)), 0)),"")} | AB16: =SUMIF($AA$30:$AA$56,AA16,$AD$30:$AD$56) -> 0 | AC16: =SUMIF($P$9:$P$98,AA16,$Q$9:$Q$98) -> 0 | AD16: =SUMIF($AA$30:$AA$56,AA16,$AE$30:$AE$56) -> 0 | AE16: =IFERROR(AB16*AC16*VLOOKUP(AA16,'TL Data'!$A$2:$E$1226,3,FALSE),"")
J17: =IFERROR((((D17)/60)/60)*$AB$9,"") -> 0 | K17: ='Tube Bending'!E17 -> 0 | L17: =IFERROR(VLOOKUP('Tube Laser'!A17,Machining!A18:G108,7,FALSE),"") | M17: =IFERROR(IF(Finishing!G18>0,VLOOKUP('Tube Laser'!A17,Finishing!A18:G108,7,FALSE),0),"") -> 0 | N17: =SUM(J17,K17,L17,M17,'FB Data'!AR17) -> 0 | O17: =C17/12 -> 0 | Q17: =IFERROR((B17*O17)/(VLOOKUP(P17,$AA$14:$AD$24,2,FALSE)),"") | R17: =IFERROR(VLOOKUP(P17,$AA$14:$AD$24,4,FALSE)*(Q17/(VLOOKUP(P17,$AA$14:$AD$24,3,FALSE))),"") | S17: =IFERROR((R17*$AB$10)/B17,"") | U17: =IFERROR(N17+S17+'FB Data'!AE17+'FB Data'!AF17+'FB Data'!AG17+'FB Data'!AH17+($AB$7/$B$99)+($AB$8/$B$99)+($AB$3/$B$99)+($AB$2/$B$99)+($AB$4/$B$99)+($AB$5/$B$99),"") | V17: =IFERROR(ROUND(U17*'Quote Info'!$O$4+T17,2),"") | W17: =IFERROR(U17*B17,"") | X17: =IFERROR(V17*B17,"") | Y17: =IFERROR(U17/((VLOOKUP(P17,'TL Data'!$A$2:$E$1226,3,FALSE))*'Tube Laser'!O17),"") | AA17: {=IFERROR(INDEX($AA$30:$AA$56, MATCH(0,IF(ISBLANK($AA$30:$AA$56),1,COUNTIF($AA$13:AA16, $AA$30:$AA$56)), 0)),"")} | AB17: =SUMIF($AA$30:$AA$56,AA17,$AD$30:$AD$56) -> 0 | AC17: =SUMIF($P$9:$P$98,AA17,$Q$9:$Q$98) -> 0 | AD17: =SUMIF($AA$30:$AA$56,AA17,$AE$30:$AE$56) -> 0 | AE17: =IFERROR(AB17*AC17*VLOOKUP(AA17,'TL Data'!$A$2:$E$1226,3,FALSE),"")
J18: =IFERROR((((D18)/60)/60)*$AB$9,"") -> 0 | K18: ='Tube Bending'!E18 -> 0 | L18: =IFERROR(VLOOKUP('Tube Laser'!A18,Machining!A19:G109,7,FALSE),"") | M18: =IFERROR(IF(Finishing!G19>0,VLOOKUP('Tube Laser'!A18,Finishing!A19:G109,7,FALSE),0),"") -> 0 | N18: =SUM(J18,K18,L18,M18,'FB Data'!AR18) -> 0 | O18: =C18/12 -> 0 | Q18: =IFERROR((B18*O18)/(VLOOKUP(P18,$AA$14:$AD$24,2,FALSE)),"") | R18: =IFERROR(VLOOKUP(P18,$AA$14:$AD$24,4,FALSE)*(Q18/(VLOOKUP(P18,$AA$14:$AD$24,3,FALSE))),"") | S18: =IFERROR((R18*$AB$10)/B18,"") | U18: =IFERROR(N18+S18+'FB Data'!AE18+'FB Data'!AF18+'FB Data'!AG18+'FB Data'!AH18+($AB$7/$B$99)+($AB$8/$B$99)+($AB$3/$B$99)+($AB$2/$B$99)+($AB$4/$B$99)+($AB$5/$B$99),"") | V18: =IFERROR(ROUND(U18*'Quote Info'!$O$4+T18,2),"") | W18: =IFERROR(U18*B18,"") | X18: =IFERROR(V18*B18,"") | Y18: =IFERROR(U18/((VLOOKUP(P18,'TL Data'!$A$2:$E$1226,3,FALSE))*'Tube Laser'!O18),"") | AA18: {=IFERROR(INDEX($AA$30:$AA$56, MATCH(0,IF(ISBLANK($AA$30:$AA$56),1,COUNTIF($AA$13:AA17, $AA$30:$AA$56)), 0)),"")} | AB18: =SUMIF($AA$30:$AA$56,AA18,$AD$30:$AD$56) -> 0 | AC18: =SUMIF($P$9:$P$98,AA18,$Q$9:$Q$98) -> 0 | AD18: =SUMIF($AA$30:$AA$56,AA18,$AE$30:$AE$56) -> 0 | AE18: =IFERROR(AB18*AC18*VLOOKUP(AA18,'TL Data'!$A$2:$E$1226,3,FALSE),"")
J19: =IFERROR((((D19)/60)/60)*$AB$9,"") -> 0 | K19: ='Tube Bending'!E19 -> 0 | L19: =IFERROR(VLOOKUP('Tube Laser'!A19,Machining!A20:G110,7,FALSE),"") | M19: =IFERROR(IF(Finishing!G20>0,VLOOKUP('Tube Laser'!A19,Finishing!A20:G110,7,FALSE),0),"") -> 0 | N19: =SUM(J19,K19,L19,M19,'FB Data'!AR19) -> 0 | O19: =C19/12 -> 0 | Q19: =IFERROR((B19*O19)/(VLOOKUP(P19,$AA$14:$AD$24,2,FALSE)),"") | R19: =IFERROR(VLOOKUP(P19,$AA$14:$AD$24,4,FALSE)*(Q19/(VLOOKUP(P19,$AA$14:$AD$24,3,FALSE))),"") | S19: =IFERROR((R19*$AB$10)/B19,"") | U19: =IFERROR(N19+S19+'FB Data'!AE19+'FB Data'!AF19+'FB Data'!AG19+'FB Data'!AH19+($AB$7/$B$99)+($AB$8/$B$99)+($AB$3/$B$99)+($AB$2/$B$99)+($AB$4/$B$99)+($AB$5/$B$99),"") | V19: =IFERROR(ROUND(U19*'Quote Info'!$O$4+T19,2),"") | W19: =IFERROR(U19*B19,"") | X19: =IFERROR(V19*B19,"") | Y19: =IFERROR(U19/((VLOOKUP(P19,'TL Data'!$A$2:$E$1226,3,FALSE))*'Tube Laser'!O19),"") | AA19: {=IFERROR(INDEX($AA$30:$AA$56, MATCH(0,IF(ISBLANK($AA$30:$AA$56),1,COUNTIF($AA$13:AA18, $AA$30:$AA$56)), 0)),"")} | AB19: =SUMIF($AA$30:$AA$56,AA19,$AD$30:$AD$56) -> 0 | AC19: =SUMIF($P$9:$P$98,AA19,$Q$9:$Q$98) -> 0 | AD19: =SUMIF($AA$30:$AA$56,AA19,$AE$30:$AE$56) -> 0 | AE19: =IFERROR(AB19*AC19*VLOOKUP(AA19,'TL Data'!$A$2:$E$1226,3,FALSE),"")
J20: =IFERROR((((D20)/60)/60)*$AB$9,"") -> 0 | K20: ='Tube Bending'!E20 -> 0 | L20: =IFERROR(VLOOKUP('Tube Laser'!A20,Machining!A21:G111,7,FALSE),"") | M20: =IFERROR(IF(Finishing!G21>0,VLOOKUP('Tube Laser'!A20,Finishing!A21:G111,7,FALSE),0),"") -> 0 | N20: =SUM(J20,K20,L20,M20,'FB Data'!AR20) -> 0 | O20: =C20/12 -> 0 | Q20: =IFERROR((B20*O20)/(VLOOKUP(P20,$AA$14:$AD$24,2,FALSE)),"") | R20: =IFERROR(VLOOKUP(P20,$AA$14:$AD$24,4,FALSE)*(Q20/(VLOOKUP(P20,$AA$14:$AD$24,3,FALSE))),"") | S20: =IFERROR((R20*$AB$10)/B20,"") | U20: =IFERROR(N20+S20+'FB Data'!AE20+'FB Data'!AF20+'FB Data'!AG20+'FB Data'!AH20+($AB$7/$B$99)+($AB$8/$B$99)+($AB$3/$B$99)+($AB$2/$B$99)+($AB$4/$B$99)+($AB$5/$B$99),"") | V20: =IFERROR(ROUND(U20*'Quote Info'!$O$4+T20,2),"") | W20: =IFERROR(U20*B20,"") | X20: =IFERROR(V20*B20,"") | Y20: =IFERROR(U20/((VLOOKUP(P20,'TL Data'!$A$2:$E$1226,3,FALSE))*'Tube Laser'!O20),"") | AA20: {=IFERROR(INDEX($AA$30:$AA$56, MATCH(0,IF(ISBLANK($AA$30:$AA$56),1,COUNTIF($AA$13:AA19, $AA$30:$AA$56)), 0)),"")} | AB20: =SUMIF($AA$30:$AA$56,AA20,$AD$30:$AD$56) -> 0 | AC20: =SUMIF($P$9:$P$98,AA20,$Q$9:$Q$98) -> 0 | AD20: =SUMIF($AA$30:$AA$56,AA20,$AE$30:$AE$56) -> 0 | AE20: =IFERROR(AB20*AC20*VLOOKUP(AA20,'TL Data'!$A$2:$E$1226,3,FALSE),"")
J21: =IFERROR((((D21)/60)/60)*$AB$9,"") -> 0 | K21: ='Tube Bending'!E21 -> 0 | L21: =IFERROR(VLOOKUP('Tube Laser'!A21,Machining!A22:G112,7,FALSE),"") | M21: =IFERROR(IF(Finishing!G22>0,VLOOKUP('Tube Laser'!A21,Finishing!A22:G112,7,FALSE),0),"") -> 0 | N21: =SUM(J21,K21,L21,M21,'FB Data'!AR21) -> 0 | O21: =C21/12 -> 0 | Q21: =IFERROR((B21*O21)/(VLOOKUP(P21,$AA$14:$AD$24,2,FALSE)),"") | R21: =IFERROR(VLOOKUP(P21,$AA$14:$AD$24,4,FALSE)*(Q21/(VLOOKUP(P21,$AA$14:$AD$24,3,FALSE))),"") | S21: =IFERROR((R21*$AB$10)/B21,"") | U21: =IFERROR(N21+S21+'FB Data'!AE21+'FB Data'!AF21+'FB Data'!AG21+'FB Data'!AH21+($AB$7/$B$99)+($AB$8/$B$99)+($AB$3/$B$99)+($AB$2/$B$99)+($AB$4/$B$99)+($AB$5/$B$99),"") | V21: =IFERROR(ROUND(U21*'Quote Info'!$O$4+T21,2),"") | W21: =IFERROR(U21*B21,"") | X21: =IFERROR(V21*B21,"") | Y21: =IFERROR(U21/((VLOOKUP(P21,'TL Data'!$A$2:$E$1226,3,FALSE))*'Tube Laser'!O21),"") | AA21: {=IFERROR(INDEX($AA$30:$AA$56, MATCH(0,IF(ISBLANK($AA$30:$AA$56),1,COUNTIF($AA$13:AA20, $AA$30:$AA$56)), 0)),"")} | AB21: =SUMIF($AA$30:$AA$56,AA21,$AD$30:$AD$56) -> 0 | AC21: =SUMIF($P$9:$P$98,AA21,$Q$9:$Q$98) -> 0 | AD21: =SUMIF($AA$30:$AA$56,AA21,$AE$30:$AE$56) -> 0 | AE21: =IFERROR(AB21*AC21*VLOOKUP(AA21,'TL Data'!$A$2:$E$1226,3,FALSE),"")
J22: =IFERROR((((D22)/60)/60)*$AB$9,"") -> 0 | K22: ='Tube Bending'!E22 -> 0 | L22: =IFERROR(VLOOKUP('Tube Laser'!A22,Machining!A23:G113,7,FALSE),"") | M22: =IFERROR(IF(Finishing!G23>0,VLOOKUP('Tube Laser'!A22,Finishing!A23:G113,7,FALSE),0),"") -> 0 | N22: =SUM(J22,K22,L22,M22,'FB Data'!AR22) -> 0 | O22: =C22/12 -> 0 | Q22: =IFERROR((B22*O22)/(VLOOKUP(P22,$AA$14:$AD$24,2,FALSE)),"") | R22: =IFERROR(VLOOKUP(P22,$AA$14:$AD$24,4,FALSE)*(Q22/(VLOOKUP(P22,$AA$14:$AD$24,3,FALSE))),"") | S22: =IFERROR((R22*$AB$10)/B22,"") | U22: =IFERROR(N22+S22+'FB Data'!AE22+'FB Data'!AF22+'FB Data'!AG22+'FB Data'!AH22+($AB$7/$B$99)+($AB$8/$B$99)+($AB$3/$B$99)+($AB$2/$B$99)+($AB$4/$B$99)+($AB$5/$B$99),"") | V22: =IFERROR(ROUND(U22*'Quote Info'!$O$4+T22,2),"") | W22: =IFERROR(U22*B22,"") | X22: =IFERROR(V22*B22,"") | Y22: =IFERROR(U22/((VLOOKUP(P22,'TL Data'!$A$2:$E$1226,3,FALSE))*'Tube Laser'!O22),"") | AA22: {=IFERROR(INDEX($AA$30:$AA$56, MATCH(0,IF(ISBLANK($AA$30:$AA$56),1,COUNTIF($AA$13:AA21, $AA$30:$AA$56)), 0)),"")} | AB22: =SUMIF($AA$30:$AA$56,AA22,$AD$30:$AD$56) -> 0 | AC22: =SUMIF($P$9:$P$98,AA22,$Q$9:$Q$98) -> 0 | AD22: =SUMIF($AA$30:$AA$56,AA22,$AE$30:$AE$56) -> 0 | AE22: =IFERROR(AB22*AC22*VLOOKUP(AA22,'TL Data'!$A$2:$E$1226,3,FALSE),"")
J23: =IFERROR((((D23)/60)/60)*$AB$9,"") -> 0 | K23: ='Tube Bending'!E23 -> 0 | L23: =IFERROR(VLOOKUP('Tube Laser'!A23,Machining!A24:G114,7,FALSE),"") | M23: =IFERROR(IF(Finishing!G24>0,VLOOKUP('Tube Laser'!A23,Finishing!A24:G114,7,FALSE),0),"") -> 0 | N23: =SUM(J23,K23,L23,M23,'FB Data'!AR23) -> 0 | O23: =C23/12 -> 0 | Q23: =IFERROR((B23*O23)/(VLOOKUP(P23,$AA$14:$AD$24,2,FALSE)),"") | R23: =IFERROR(VLOOKUP(P23,$AA$14:$AD$24,4,FALSE)*(Q23/(VLOOKUP(P23,$AA$14:$AD$24,3,FALSE))),"") | S23: =IFERROR((R23*$AB$10)/B23,"") | U23: =IFERROR(N23+S23+'FB Data'!AE23+'FB Data'!AF23+'FB Data'!AG23+'FB Data'!AH23+($AB$7/$B$99)+($AB$8/$B$99)+($AB$3/$B$99)+($AB$2/$B$99)+($AB$4/$B$99)+($AB$5/$B$99),"") | V23: =IFERROR(ROUND(U23*'Quote Info'!$O$4+T23,2),"") | W23: =IFERROR(U23*B23,"") | X23: =IFERROR(V23*B23,"") | Y23: =IFERROR(U23/((VLOOKUP(P23,'TL Data'!$A$2:$E$1226,3,FALSE))*'Tube Laser'!O23),"") | AA23: {=IFERROR(INDEX($AA$30:$AA$56, MATCH(0,IF(ISBLANK($AA$30:$AA$56),1,COUNTIF($AA$13:AA22, $AA$30:$AA$56)), 0)),"")} | AB23: =SUMIF($AA$30:$AA$56,AA23,$AD$30:$AD$56) -> 0 | AC23: =SUMIF($P$9:$P$98,AA23,$Q$9:$Q$98) -> 0 | AD23: =SUMIF($AA$30:$AA$56,AA23,$AE$30:$AE$56) -> 0 | AE23: =IFERROR(AB23*AC23*VLOOKUP(AA23,'TL Data'!$A$2:$E$1226,3,FALSE),"")
J24: =IFERROR((((D24)/60)/60)*$AB$9,"") -> 0 | K24: ='Tube Bending'!E24 -> 0 | L24: =IFERROR(VLOOKUP('Tube Laser'!A24,Machining!A25:G115,7,FALSE),"") | M24: =IFERROR(IF(Finishing!G25>0,VLOOKUP('Tube Laser'!A24,Finishing!A25:G115,7,FALSE),0),"") -> 0 | N24: =SUM(J24,K24,L24,M24,'FB Data'!AR24) -> 0 | O24: =C24/12 -> 0 | Q24: =IFERROR((B24*O24)/(VLOOKUP(P24,$AA$14:$AD$24,2,FALSE)),"") | R24: =IFERROR(VLOOKUP(P24,$AA$14:$AD$24,4,FALSE)*(Q24/(VLOOKUP(P24,$AA$14:$AD$24,3,FALSE))),"") | S24: =IFERROR((R24*$AB$10)/B24,"") | U24: =IFERROR(N24+S24+'FB Data'!AE24+'FB Data'!AF24+'FB Data'!AG24+'FB Data'!AH24+($AB$7/$B$99)+($AB$8/$B$99)+($AB$3/$B$99)+($AB$2/$B$99)+($AB$4/$B$99)+($AB$5/$B$99),"") | V24: =IFERROR(ROUND(U24*'Quote Info'!$O$4+T24,2),"") | W24: =IFERROR(U24*B24,"") | X24: =IFERROR(V24*B24,"") | Y24: =IFERROR(U24/((VLOOKUP(P24,'TL Data'!$A$2:$E$1226,3,FALSE))*'Tube Laser'!O24),"") | AA24: {=IFERROR(INDEX($AA$30:$AA$56, MATCH(0,IF(ISBLANK($AA$30:$AA$56),1,COUNTIF($AA$13:AA23, $AA$30:$AA$56)), 0)),"")} | AB24: =SUMIF($AA$30:$AA$56,AA24,$AD$30:$AD$56) -> 0 | AC24: =SUMIF($P$9:$P$98,AA24,$Q$9:$Q$98) -> 0 | AD24: =SUMIF($AA$30:$AA$56,AA24,$AE$30:$AE$56) -> 0 | AE24: =IFERROR(AB24*AC24*VLOOKUP(AA24,'TL Data'!$A$2:$E$1226,3,FALSE),"")
J25: =IFERROR((((D25)/60)/60)*$AB$9,"") -> 0 | K25: ='Tube Bending'!E25 -> 0 | L25: =IFERROR(VLOOKUP('Tube Laser'!A25,Machining!A26:G116,7,FALSE),"") | M25: =IFERROR(IF(Finishing!G26>0,VLOOKUP('Tube Laser'!A25,Finishing!A26:G116,7,FALSE),0),"") -> 0 | N25: =SUM(J25,K25,L25,M25,'FB Data'!AR25) -> 0 | O25: =C25/12 -> 0 | Q25: =IFERROR((B25*O25)/(VLOOKUP(P25,$AA$14:$AD$24,2,FALSE)),"") | R25: =IFERROR(VLOOKUP(P25,$AA$14:$AD$24,4,FALSE)*(Q25/(VLOOKUP(P25,$AA$14:$AD$24,3,FALSE))),"") | S25: =IFERROR((R25*$AB$10)/B25,"") | U25: =IFERROR(N25+S25+'FB Data'!AE25+'FB Data'!AF25+'FB Data'!AG25+'FB Data'!AH25+($AB$7/$B$99)+($AB$8/$B$99)+($AB$3/$B$99)+($AB$2/$B$99)+($AB$4/$B$99)+($AB$5/$B$99),"") | V25: =IFERROR(ROUND(U25*'Quote Info'!$O$4+T25,2),"") | W25: =IFERROR(U25*B25,"") | X25: =IFERROR(V25*B25,"") | Y25: =IFERROR(U25/((VLOOKUP(P25,'TL Data'!$A$2:$E$1226,3,FALSE))*'Tube Laser'!O25),"") | AE25: =SUMIF(AE14:AE24,"<>#N/A") -> 0
J26: =IFERROR((((D26)/60)/60)*$AB$9,"") -> 0 | K26: ='Tube Bending'!E26 -> 0 | L26: =IFERROR(VLOOKUP('Tube Laser'!A26,Machining!A27:G117,7,FALSE),"") | M26: =IFERROR(IF(Finishing!G27>0,VLOOKUP('Tube Laser'!A26,Finishing!A27:G117,7,FALSE),0),"") -> 0 | N26: =SUM(J26,K26,L26,M26,'FB Data'!AR26) -> 0 | O26: =C26/12 -> 0 | Q26: =IFERROR((B26*O26)/(VLOOKUP(P26,$AA$14:$AD$24,2,FALSE)),"") | R26: =IFERROR(VLOOKUP(P26,$AA$14:$AD$24,4,FALSE)*(Q26/(VLOOKUP(P26,$AA$14:$AD$24,3,FALSE))),"") | S26: =IFERROR((R26*$AB$10)/B26,"") | U26: =IFERROR(N26+S26+'FB Data'!AE26+'FB Data'!AF26+'FB Data'!AG26+'FB Data'!AH26+($AB$7/$B$99)+($AB$8/$B$99)+($AB$3/$B$99)+($AB$2/$B$99)+($AB$4/$B$99)+($AB$5/$B$99),"") | V26: =IFERROR(ROUND(U26*'Quote Info'!$O$4+T26,2),"") | W26: =IFERROR(U26*B26,"") | X26: =IFERROR(V26*B26,"") | Y26: =IFERROR(U26/((VLOOKUP(P26,'TL Data'!$A$2:$E$1226,3,FALSE))*'Tube Laser'!O26),"")
J27: =IFERROR((((D27)/60)/60)*$AB$9,"") -> 0 | K27: ='Tube Bending'!E27 -> 0 | L27: =IFERROR(VLOOKUP('Tube Laser'!A27,Machining!A28:G118,7,FALSE),"") | M27: =IFERROR(IF(Finishing!G28>0,VLOOKUP('Tube Laser'!A27,Finishing!A28:G118,7,FALSE),0),"") -> 0 | N27: =SUM(J27,K27,L27,M27,'FB Data'!AR27) -> 0 | O27: =C27/12 -> 0 | Q27: =IFERROR((B27*O27)/(VLOOKUP(P27,$AA$14:$AD$24,2,FALSE)),"") | R27: =IFERROR(VLOOKUP(P27,$AA$14:$AD$24,4,FALSE)*(Q27/(VLOOKUP(P27,$AA$14:$AD$24,3,FALSE))),"") | S27: =IFERROR((R27*$AB$10)/B27,"") | U27: =IFERROR(N27+S27+'FB Data'!AE27+'FB Data'!AF27+'FB Data'!AG27+'FB Data'!AH27+($AB$7/$B$99)+($AB$8/$B$99)+($AB$3/$B$99)+($AB$2/$B$99)+($AB$4/$B$99)+($AB$5/$B$99),"") | V27: =IFERROR(ROUND(U27*'Quote Info'!$O$4+T27,2),"") | W27: =IFERROR(U27*B27,"") | X27: =IFERROR(V27*B27,"") | Y27: =IFERROR(U27/((VLOOKUP(P27,'TL Data'!$A$2:$E$1226,3,FALSE))*'Tube Laser'!O27),"")
